Workbook

Sheet Résumé
A1: Récapitulatif des charges — Compte BRED EJ 2026
A2: Période couverte : 02/01/2026 au 10/07/2026 — 889 opérations
A4: Total encaissements | B4: =SUMIF(Détail!F:F,"Encaissement*",Détail!E:E) -> 643902.63
A5: Total charges (hors encaissements, hors chèques/saisie à vérifier) | B5: =SUMIFS(Détail!E:E,Détail!F:F,"<>Encaissement (hors périmètre charges)",Détail!F:F,"<>Paiement par chèque (à vérifier)",Détail!F:F,"<>Saisie administrative") -> -636709.75
A6: Solde net (encaissements + charges + à vérifier) | B6: =SUMIF(Détail!F:F,"<>",Détail!E:E) -> 5217.88
A8: Détail par catégorie de charge
A9: Catégorie | B9: Nb opérations | C9: Montant total (€) | D9: % du total charges
A10: Fournisseurs matières premières & emballage (France) | B10: =COUNTIF(Détail!F:F,A10) -> 24 | C10: =SUMIF(Détail!F:F,A10,Détail!E:E) -> -244170.98 | D10: =C10/$B$5 -> 0.38348868
A11: Usine de conditionnement et macération | B11: =COUNTIF(Détail!F:F,A11) -> 12 | C11: =SUMIF(Détail!F:F,A11,Détail!E:E) -> -136758.73 | D11: =C11/$B$5 -> 0.21478975
A12: Fournisseurs internationaux (Chine/Import) | B12: =COUNTIF(Détail!F:F,A12) -> 13 | C12: =SUMIF(Détail!F:F,A12,Détail!E:E) -> -57342.97 | D12: =C12/$B$5 -> 0.090061398
A13: Transport / livraison (colis, courrier) | B13: =COUNTIF(Détail!F:F,A13) -> 48 | C13: =SUMIF(Détail!F:F,A13,Détail!E:E) -> -42914.9 | D13: =C13/$B$5 -> 0.067401041
A14: Salaires (salariés) | B14: =COUNTIF(Détail!F:F,A14) -> 25 | C14: =SUMIF(Détail!F:F,A14,Détail!E:E) -> -33658.99 | D14: =C14/$B$5 -> 0.052863946
A15: Charges sociales & cotisations | B15: =COUNTIF(Détail!F:F,A15) -> 24 | C15: =SUMIF(Détail!F:F,A15,Détail!E:E) -> -25681.14 | D15: =C15/$B$5 -> 0.04033414
A16: Rémunération gérant | B16: =COUNTIF(Détail!F:F,A16) -> 11 | C16: =SUMIF(Détail!F:F,A16,Détail!E:E) -> -24300 | D16: =C16/$B$5 -> 0.038164957
A17: Carburant, péages, parking, leasing | B17: =COUNTIF(Détail!F:F,A17) -> 197 | C17: =SUMIF(Détail!F:F,A17,Détail!E:E) -> -13245.95 | D17: =C17/$B$5 -> 0.020803749
A18: Frais professionnels divers | B18: =COUNTIF(Détail!F:F,A18) -> 55 | C18: =SUMIF(Détail!F:F,A18,Détail!E:E) -> -12908.5 | D18: =C18/$B$5 -> 0.020273759
A19: Voyages / déplacements | B19: =COUNTIF(Détail!F:F,A19) -> 44 | C19: =SUMIF(Détail!F:F,A19,Détail!E:E) -> -10275.06 | D19: =C19/$B$5 -> 0.016137746
A20: Téléphone / Internet / Logiciels | B20: =COUNTIF(Détail!F:F,A20) -> 99 | C20: =SUMIF(Détail!F:F,A20,Détail!E:E) -> -7501.73 | D20: =C20/$B$5 -> 0.011782025
A21: Électricité / Gaz | B21: =COUNTIF(Détail!F:F,A21) -> 13 | C21: =SUMIF(Détail!F:F,A21,Détail!E:E) -> -5559.55 | D21: =C21/$B$5 -> 0.0087316866
... A31: Restauration | B31: =COUNTIF(Détail!F:F,A31) -> 18 | C31: =SUMIF(Détail!F:F,A31,Détail!E:E) -> -410.79 | D31: =C31/$B$5 -> 0.00064517624
A32: TOTAL | B32: =SUM(B10:B31) -> 820 | C32: =SUM(C10:C31) -> -638684.75

Sheet Revenus
A1: Revenus — Compte BRED EJ 2026
A2: Période couverte : 02/01/2026 au 08/07/2026 — 69 encaissements
A4: Total encaissements | B4: =SUM('Détail Revenus'!E:E) -> 643902.63
A6: Détail par source de revenu
A7: Source | B7: Nb opérations | C7: Montant total (€) | D7: % du total
A8: NB Evolution FZCO (factures NB...) | B8: =COUNTIF('Détail Revenus'!F:F,A8) -> 16 | C8: =SUMIF('Détail Revenus'!F:F,A8,'Détail Revenus'!E:E) -> 395976.38 | D8: =C8/$B$4 -> 0.61496314
A9: Usine Algérie (Jade Création — sans marge) | B9: =COUNTIF('Détail Revenus'!F:F,A9) -> 5 | C9: =SUMIF('Détail Revenus'!F:F,A9,'Détail Revenus'!E:E) -> 101673.36 | D9: =C9/$B$4 -> 0.15790176
A10: Al Muftah | B10: =COUNTIF('Détail Revenus'!F:F,A10) -> 3 | C10: =SUMIF('Détail Revenus'!F:F,A10,'Détail Revenus'!E:E) -> 71936.54 | D10: =C10/$B$4 -> 0.11171959
A11: Autres clients (probables, non confirmés) | B11: =COUNTIF('Détail Revenus'!F:F,A11) -> 0 | C11: =SUMIF('Détail Revenus'!F:F,A11,'Détail Revenus'!E:E) -> 0 | D11: =C11/$B$4 -> 0
A12: Encaissements non identifiés | B12: =COUNTIF('Détail Revenus'!F:F,A12) -> 0 | C12: =SUMIF('Détail Revenus'!F:F,A12,'Détail Revenus'!E:E) -> 0 | D12: =C12/$B$4 -> 0
A13: Arzum Group Mmc | B13: =COUNTIF('Détail Revenus'!F:F,A13) -> 1 | C13: =SUMIF('Détail Revenus'!F:F,A13,'Détail Revenus'!E:E) -> 10142 | D13: =C13/$B$4 -> 0.015750829
A14: Passion Parfum | B14: =COUNTIF('Détail Revenus'!F:F,A14) -> 7 | C14: =SUMIF('Détail Revenus'!F:F,A14,'Détail Revenus'!E:E) -> 37140 | D14: =C14/$B$4 -> 0.057679528
A15: Mb Tressoria | B15: =COUNTIF('Détail Revenus'!F:F,A15) -> 3 | C15: =SUMIF('Détail Revenus'!F:F,A15,'Détail Revenus'!E:E) -> 13067 | D15: =C15/$B$4 -> 0.020293441
A16: Stf Perfumeria | B16: =COUNTIF('Détail Revenus'!F:F,A16) -> 2 | C16: =SUMIF('Détail Revenus'!F:F,A16,'Détail Revenus'!E:E) -> 2777 | D16: =C16/$B$4 -> 0.0043127639
A17: Alfa Group Srls | B17: =COUNTIF('Détail Revenus'!F:F,A17) -> 1 | C17: =SUMIF('Détail Revenus'!F:F,A17,'Détail Revenus'!E:E) -> 2394 | D17: =C17/$B$4 -> 0.0037179534
A18: Ventes en ligne (boutique Shopify) | B18: =COUNTIF('Détail Revenus'!F:F,A18) -> 28 | C18: =SUMIF('Détail Revenus'!F:F,A18,'Détail Revenus'!E:E) -> 1638.75 | D18: =C18/$B$4 -> 0.0025450277
A19: Firm Rheds | B19: =COUNTIF('Détail Revenus'!F:F,A19) -> 1 | C19: =SUMIF('Détail Revenus'!F:F,A19,'Détail Revenus'!E:E) -> 624 | D19: =C19/$B$4 -> 0.00096909062
... A21: Frais de dossier facturés (client) | B21: =COUNTIF('Détail Revenus'!F:F,A21) -> 1 | C21: =SUMIF('Détail Revenus'!F:F,A21,'Détail Revenus'!E:E) -> 303.6 | D21: =C21/$B$4 -> 0.00047149986
A22: TOTAL | B22: =SUM(B8:B21) -> 69 | C22: =SUM(C8:C21) -> 643902.63
A24: 🟠 En orange : sources pas encore confirmées avec Mounir

Sheet Revenus détail
A1: Revenus — détail par source et par mois (2026)
A3: NB Evolution FZCO (factures NB...) | C3: =SUMIF('Détail Revenus'!$F:$F,"NB Evolution FZCO (factures NB...)",'Détail Revenus'!$E:$E) -> 395976.38
A4: Mois | B4: Montant
A5: Janvier 2026 | B5: =SUMIFS('Détail Revenus'!$E:$E,'Détail Revenus'!$F:$F,"NB Evolution FZCO (factures NB...)",'Détail Revenus'!$A:$A,">="&DATE(2026,1,1),'Détail Revenus'!$A:$A,"<"&EDATE(DATE(2026,1,1),1)) -> 45807.68
A6: Février 2026 | B6: =SUMIFS('Détail Revenus'!$E:$E,'Détail Revenus'!$F:$F,"NB Evolution FZCO (factures NB...)",'Détail Revenus'!$A:$A,">="&DATE(2026,2,1),'Détail Revenus'!$A:$A,"<"&EDATE(DATE(2026,2,1),1)) -> 55968.7
A7: Mars 2026 | B7: =SUMIFS('Détail Revenus'!$E:$E,'Détail Revenus'!$F:$F,"NB Evolution FZCO (factures NB...)",'Détail Revenus'!$A:$A,">="&DATE(2026,3,1),'Détail Revenus'!$A:$A,"<"&EDATE(DATE(2026,3,1),1)) -> 48000
A8: Avril 2026 | B8: =SUMIFS('Détail Revenus'!$E:$E,'Détail Revenus'!$F:$F,"NB Evolution FZCO (factures NB...)",'Détail Revenus'!$A:$A,">="&DATE(2026,4,1),'Détail Revenus'!$A:$A,"<"&EDATE(DATE(2026,4,1),1)) -> 72200
A9: Mai 2026 | B9: =SUMIFS('Détail Revenus'!$E:$E,'Détail Revenus'!$F:$F,"NB Evolution FZCO (factures NB...)",'Détail Revenus'!$A:$A,">="&DATE(2026,5,1),'Détail Revenus'!$A:$A,"<"&EDATE(DATE(2026,5,1),1)) -> 59200
A10: Juin 2026 | B10: =SUMIFS('Détail Revenus'!$E:$E,'Détail Revenus'!$F:$F,"NB Evolution FZCO (factures NB...)",'Détail Revenus'!$A:$A,">="&DATE(2026,6,1),'Détail Revenus'!$A:$A,"<"&EDATE(DATE(2026,6,1),1)) -> 94800
A11: Juillet 2026 | B11: =SUMIFS('Détail Revenus'!$E:$E,'Détail Revenus'!$F:$F,"NB Evolution FZCO (factures NB...)",'Détail Revenus'!$A:$A,">="&DATE(2026,7,1),'Détail Revenus'!$A:$A,"<"&EDATE(DATE(2026,7,1),1)) -> 20000
A14: Usine Algérie (Jade Création — sans marge) | C14: =SUMIF('Détail Revenus'!$F:$F,"Usine Algérie (Jade Création — sans marge)",'Détail Revenus'!$E:$E) -> 101673.36
A15: Noms bancaires d'origine : | B15: SARL JADE CREATION SALGDZALXXX, JADE CREATION SARL
A16: Mois | B16: Montant
A17: Janvier 2026 | B17: =SUMIFS('Détail Revenus'!$E:$E,'Détail Revenus'!$F:$F,"Usine Algérie (Jade Création — sans marge)",'Détail Revenus'!$A:$A,">="&DATE(2026,1,1),'Détail Revenus'!$A:$A,"<"&EDATE(DATE(2026,1,1),1)) -> 5284.36
A18: Février 2026 | B18: =SUMIFS('Détail Revenus'!$E:$E,'Détail Revenus'!$F:$F,"Usine Algérie (Jade Création — sans marge)",'Détail Revenus'!$A:$A,">="&DATE(2026,2,1),'Détail Revenus'!$A:$A,"<"&EDATE(DATE(2026,2,1),1)) -> 0
A19: Mars 2026 | B19: =SUMIFS('Détail Revenus'!$E:$E,'Détail Revenus'!$F:$F,"Usine Algérie (Jade Création — sans marge)",'Détail Revenus'!$A:$A,">="&DATE(2026,3,1),'Détail Revenus'!$A:$A,"<"&EDATE(DATE(2026,3,1),1)) -> 0
A20: Avril 2026 | B20: =SUMIFS('Détail Revenus'!$E:$E,'Détail Revenus'!$F:$F,"Usine Algérie (Jade Création — sans marge)",'Détail Revenus'!$A:$A,">="&DATE(2026,4,1),'Détail Revenus'!$A:$A,"<"&EDATE(DATE(2026,4,1),1)) -> 0
A21: Mai 2026 | B21: =SUMIFS('Détail Revenus'!$E:$E,'Détail Revenus'!$F:$F,"Usine Algérie (Jade Création — sans marge)",'Détail Revenus'!$A:$A,">="&DATE(2026,5,1),'Détail Revenus'!$A:$A,"<"&EDATE(DATE(2026,5,1),1)) -> 46714
A22: Juin 2026 | B22: =SUMIFS('Détail Revenus'!$E:$E,'Détail Revenus'!$F:$F,"Usine Algérie (Jade Création — sans marge)",'Détail Revenus'!$A:$A,">="&DATE(2026,6,1),'Détail Revenus'!$A:$A,"<"&EDATE(DATE(2026,6,1),1)) -> 49675
A23: Juillet 2026 | B23: =SUMIFS('Détail Revenus'!$E:$E,'Détail Revenus'!$F:$F,"Usine Algérie (Jade Création — sans marge)",'Détail Revenus'!$A:$A,">="&DATE(2026,7,1),'Détail Revenus'!$A:$A,"<"&EDATE(DATE(2026,7,1),1)) -> 0
A26: Al Muftah | C26: =SUMIF('Détail Revenus'!$F:$F,"Al Muftah",'Détail Revenus'!$E:$E) -> 71936.54
A27: Noms bancaires d'origine : | B27: ALMUFTAH MARKETING, ALMUFTAH TRADING AND CONT CO.
A28: Mois | B28: Montant
A29: Janvier 2026 | B29: =SUMIFS('Détail Revenus'!$E:$E,'Détail Revenus'!$F:$F,"Al Muftah",'Détail Revenus'!$A:$A,">="&DATE(2026,1,1),'Détail Revenus'!$A:$A,"<"&EDATE(DATE(2026,1,1),1)) -> 21555.14
A30: Février 2026 | B30: =SUMIFS('Détail Revenus'!$E:$E,'Détail Revenus'!$F:$F,"Al Muftah",'Détail Revenus'!$A:$A,">="&DATE(2026,2,1),'Détail Revenus'!$A:$A,"<"&EDATE(DATE(2026,2,1),1)) -> 0
A31: Mars 2026 | B31: =SUMIFS('Détail Revenus'!$E:$E,'Détail Revenus'!$F:$F,"Al Muftah",'Détail Revenus'!$A:$A,">="&DATE(2026,3,1),'Détail Revenus'!$A:$A,"<"&EDATE(DATE(2026,3,1),1)) -> 0
A32: Avril 2026 | B32: =SUMIFS('Détail Revenus'!$E:$E,'Détail Revenus'!$F:$F,"Al Muftah",'Détail Revenus'!$A:$A,">="&DATE(2026,4,1),'Détail Revenus'!$A:$A,"<"&EDATE(DATE(2026,4,1),1)) -> 25223
A33: Mai 2026 | B33: =SUMIFS('Détail Revenus'!$E:$E,'Détail Revenus'!$F:$F,"Al Muftah",'Détail Revenus'!$A:$A,">="&DATE(2026,5,1),'Détail Revenus'!$A:$A,"<"&EDATE(DATE(2026,5,1),1)) -> 0
A34: Juin 2026 | B34: =SUMIFS('Détail Revenus'!$E:$E,'Détail Revenus'!$F:$F,"Al Muftah",'Détail Revenus'!$A:$A,">="&DATE(2026,6,1),'Détail Revenus'!$A:$A,"<"&EDATE(DATE(2026,6,1),1)) -> 25158.4
A35: Juillet 2026 | B35: =SUMIFS('Détail Revenus'!$E:$E,'Détail Revenus'!$F:$F,"Al Muftah",'Détail Revenus'!$A:$A,">="&DATE(2026,7,1),'Détail Revenus'!$A:$A,"<"&EDATE(DATE(2026,7,1),1)) -> 0
A38: Autres clients (probables, non confirmés) | C38: =SUMIF('Détail Revenus'!$F:$F,"Autres clients (probables, non confirmés)",'Détail Revenus'!$E:$E) -> 0
A39: Noms bancaires d'origine : | B39: FLASHCONNECT, GLOBAL AUTO 94
A40: Mois | B40: Montant
A41: Janvier 2026 | B41: =SUMIFS('Détail Revenus'!$E:$E,'Détail Revenus'!$F:$F,"Autres clients (probables, non confirmés)",'Détail Revenus'!$A:$A,">="&DATE(2026,1,1),'Détail Revenus'!$A:$A,"<"&EDATE(DATE(2026,1,1),1)) -> 0
A42: Février 2026 | B42: =SUMIFS('Détail Revenus'!$E:$E,'Détail Revenus'!$F:$F,"Autres clients (probables, non confirmés)",'Détail Revenus'!$A:$A,">="&DATE(2026,2,1),'Détail Revenus'!$A:$A,"<"&EDATE(DATE(2026,2,1),1)) -> 0
A43: Mars 2026 | B43: =SUMIFS('Détail Revenus'!$E:$E,'Détail Revenus'!$F:$F,"Autres clients (probables, non confirmés)",'Détail Revenus'!$A:$A,">="&DATE(2026,3,1),'Détail Revenus'!$A:$A,"<"&EDATE(DATE(2026,3,1),1)) -> 0
A44: Avril 2026 | B44: =SUMIFS('Détail Revenus'!$E:$E,'Détail Revenus'!$F:$F,"Autres clients (probables, non confirmés)",'Détail Revenus'!$A:$A,">="&DATE(2026,4,1),'Détail Revenus'!$A:$A,"<"&EDATE(DATE(2026,4,1),1)) -> 0
A45: Mai 2026 | B45: =SUMIFS('Détail Revenus'!$E:$E,'Détail Revenus'!$F:$F,"Autres clients (probables, non confirmés)",'Détail Revenus'!$A:$A,">="&DATE(2026,5,1),'Détail Revenus'!$A:$A,"<"&EDATE(DATE(2026,5,1),1)) -> 0
A46: Juin 2026 | B46: =SUMIFS('Détail Revenus'!$E:$E,'Détail Revenus'!$F:$F,"Autres clients (probables, non confirmés)",'Détail Revenus'!$A:$A,">="&DATE(2026,6,1),'Détail Revenus'!$A:$A,"<"&EDATE(DATE(2026,6,1),1)) -> 0
A47: Juillet 2026 | B47: =SUMIFS('Détail Revenus'!$E:$E,'Détail Revenus'!$F:$F,"Autres clients (probables, non confirmés)",'Détail Revenus'!$A:$A,">="&DATE(2026,7,1),'Détail Revenus'!$A:$A,"<"&EDATE(DATE(2026,7,1),1)) -> 0
...

Sheet Salaires détail
A1: Salaires & rémunération gérant — détail par personne (2026)
A3: Mr Boudjada Said (Gérant — rémunération libre) | C3: =SUMIF(Détail!$D:$D,"MR BOUDJADA SAID",Détail!$E:$E) -> -24300
A4: Mois | B4: Montant
A5: Janvier 2026 | B5: =SUMIFS(Détail!$E:$E,Détail!$D:$D,"MR BOUDJADA SAID",Détail!$A:$A,">="&DATE(2026,1,1),Détail!$A:$A,"<"&EDATE(DATE(2026,1,1),1)) -> -4700
A6: Février 2026 | B6: =SUMIFS(Détail!$E:$E,Détail!$D:$D,"MR BOUDJADA SAID",Détail!$A:$A,">="&DATE(2026,2,1),Détail!$A:$A,"<"&EDATE(DATE(2026,2,1),1)) -> -3600
A7: Mars 2026 | B7: =SUMIFS(Détail!$E:$E,Détail!$D:$D,"MR BOUDJADA SAID",Détail!$A:$A,">="&DATE(2026,3,1),Détail!$A:$A,"<"&EDATE(DATE(2026,3,1),1)) -> 0
A8: Avril 2026 | B8: =SUMIFS(Détail!$E:$E,Détail!$D:$D,"MR BOUDJADA SAID",Détail!$A:$A,">="&DATE(2026,4,1),Détail!$A:$A,"<"&EDATE(DATE(2026,4,1),1)) -> -7000
A9: Mai 2026 | B9: =SUMIFS(Détail!$E:$E,Détail!$D:$D,"MR BOUDJADA SAID",Détail!$A:$A,">="&DATE(2026,5,1),Détail!$A:$A,"<"&EDATE(DATE(2026,5,1),1)) -> -5000
A10: Juin 2026 | B10: =SUMIFS(Détail!$E:$E,Détail!$D:$D,"MR BOUDJADA SAID",Détail!$A:$A,">="&DATE(2026,6,1),Détail!$A:$A,"<"&EDATE(DATE(2026,6,1),1)) -> 0
A11: Juillet 2026 | B11: =SUMIFS(Détail!$E:$E,Détail!$D:$D,"MR BOUDJADA SAID",Détail!$A:$A,">="&DATE(2026,7,1),Détail!$A:$A,"<"&EDATE(DATE(2026,7,1),1)) -> -4000
A14: Mr Boudaja Nassim (Salarié) | C14: =SUMIF(Détail!$D:$D,"MR BOUDAJA NASSIM",Détail!$E:$E) -> -14792.28
A15: Mois | B15: Montant
A16: Janvier 2026 | B16: =SUMIFS(Détail!$E:$E,Détail!$D:$D,"MR BOUDAJA NASSIM",Détail!$A:$A,">="&DATE(2026,1,1),Détail!$A:$A,"<"&EDATE(DATE(2026,1,1),1)) -> -2465.38
A17: Février 2026 | B17: =SUMIFS(Détail!$E:$E,Détail!$D:$D,"MR BOUDAJA NASSIM",Détail!$A:$A,">="&DATE(2026,2,1),Détail!$A:$A,"<"&EDATE(DATE(2026,2,1),1)) -> -2465.38
A18: Mars 2026 | B18: =SUMIFS(Détail!$E:$E,Détail!$D:$D,"MR BOUDAJA NASSIM",Détail!$A:$A,">="&DATE(2026,3,1),Détail!$A:$A,"<"&EDATE(DATE(2026,3,1),1)) -> -2465.38
A19: Avril 2026 | B19: =SUMIFS(Détail!$E:$E,Détail!$D:$D,"MR BOUDAJA NASSIM",Détail!$A:$A,">="&DATE(2026,4,1),Détail!$A:$A,"<"&EDATE(DATE(2026,4,1),1)) -> -2465.38
A20: Mai 2026 | B20: =SUMIFS(Détail!$E:$E,Détail!$D:$D,"MR BOUDAJA NASSIM",Détail!$A:$A,">="&DATE(2026,5,1),Détail!$A:$A,"<"&EDATE(DATE(2026,5,1),1)) -> -2465.38
A21: Juin 2026 | B21: =SUMIFS(Détail!$E:$E,Détail!$D:$D,"MR BOUDAJA NASSIM",Détail!$A:$A,">="&DATE(2026,6,1),Détail!$A:$A,"<"&EDATE(DATE(2026,6,1),1)) -> -2465.38
A22: Juillet 2026 | B22: =SUMIFS(Détail!$E:$E,Détail!$D:$D,"MR BOUDAJA NASSIM",Détail!$A:$A,">="&DATE(2026,7,1),Détail!$A:$A,"<"&EDATE(DATE(2026,7,1),1)) -> 0
A25: Mme Machado Natali (Salarié) | C25: =SUMIF(Détail!$D:$D,"MME MACHADO NATALI",Détail!$E:$E) -> -8456.58
A26: Mois | B26: Montant
A27: Janvier 2026 | B27: =SUMIFS(Détail!$E:$E,Détail!$D:$D,"MME MACHADO NATALI",Détail!$A:$A,">="&DATE(2026,1,1),Détail!$A:$A,"<"&EDATE(DATE(2026,1,1),1)) -> -1287.51
A28: Février 2026 | B28: =SUMIFS(Détail!$E:$E,Détail!$D:$D,"MME MACHADO NATALI",Détail!$A:$A,">="&DATE(2026,2,1),Détail!$A:$A,"<"&EDATE(DATE(2026,2,1),1)) -> -1284.87
A29: Mars 2026 | B29: =SUMIFS(Détail!$E:$E,Détail!$D:$D,"MME MACHADO NATALI",Détail!$A:$A,">="&DATE(2026,3,1),Détail!$A:$A,"<"&EDATE(DATE(2026,3,1),1)) -> -1282.23
A30: Avril 2026 | B30: =SUMIFS(Détail!$E:$E,Détail!$D:$D,"MME MACHADO NATALI",Détail!$A:$A,">="&DATE(2026,4,1),Détail!$A:$A,"<"&EDATE(DATE(2026,4,1),1)) -> -1532.23
A31: Mai 2026 | B31: =SUMIFS(Détail!$E:$E,Détail!$D:$D,"MME MACHADO NATALI",Détail!$A:$A,">="&DATE(2026,5,1),Détail!$A:$A,"<"&EDATE(DATE(2026,5,1),1)) -> -1537.51
A32: Juin 2026 | B32: =SUMIFS(Détail!$E:$E,Détail!$D:$D,"MME MACHADO NATALI",Détail!$A:$A,">="&DATE(2026,6,1),Détail!$A:$A,"<"&EDATE(DATE(2026,6,1),1)) -> -1532.23
A33: Juillet 2026 | B33: =SUMIFS(Détail!$E:$E,Détail!$D:$D,"MME MACHADO NATALI",Détail!$A:$A,">="&DATE(2026,7,1),Détail!$A:$A,"<"&EDATE(DATE(2026,7,1),1)) -> 0
A36: Mr Boudjada Mounir (Salarié) | C36: =SUMIF(Détail!$D:$D,"MR BOUDJADA MOUNIR",Détail!$E:$E) -> -7740.99
A37: Mois | B37: Montant
A38: Janvier 2026 | B38: =SUMIFS(Détail!$E:$E,Détail!$D:$D,"MR BOUDJADA MOUNIR",Détail!$A:$A,">="&DATE(2026,1,1),Détail!$A:$A,"<"&EDATE(DATE(2026,1,1),1)) -> -1233.82
A39: Février 2026 | B39: =SUMIFS(Détail!$E:$E,Détail!$D:$D,"MR BOUDJADA MOUNIR",Détail!$A:$A,">="&DATE(2026,2,1),Détail!$A:$A,"<"&EDATE(DATE(2026,2,1),1)) -> -1233.82
A40: Mars 2026 | B40: =SUMIFS(Détail!$E:$E,Détail!$D:$D,"MR BOUDJADA MOUNIR",Détail!$A:$A,">="&DATE(2026,3,1),Détail!$A:$A,"<"&EDATE(DATE(2026,3,1),1)) -> -1233.82
A41: Avril 2026 | B41: =SUMIFS(Détail!$E:$E,Détail!$D:$D,"MR BOUDJADA MOUNIR",Détail!$A:$A,">="&DATE(2026,4,1),Détail!$A:$A,"<"&EDATE(DATE(2026,4,1),1)) -> -1233.82
A42: Mai 2026 | B42: =SUMIFS(Détail!$E:$E,Détail!$D:$D,"MR BOUDJADA MOUNIR",Détail!$A:$A,">="&DATE(2026,5,1),Détail!$A:$A,"<"&EDATE(DATE(2026,5,1),1)) -> -1829.82
A43: Juin 2026 | B43: =SUMIFS(Détail!$E:$E,Détail!$D:$D,"MR BOUDJADA MOUNIR",Détail!$A:$A,">="&DATE(2026,6,1),Détail!$A:$A,"<"&EDATE(DATE(2026,6,1),1)) -> -975.89
A44: Juillet 2026 | B44: =SUMIFS(Détail!$E:$E,Détail!$D:$D,"MR BOUDJADA MOUNIR",Détail!$A:$A,">="&DATE(2026,7,1),Détail!$A:$A,"<"&EDATE(DATE(2026,7,1),1)) -> 0
A47: Mme Sabrina Mahmoudi (Salarié) | C47: =SUMIF(Détail!$D:$D,"MME SABRINA MAHMOUDI",Détail!$E:$E) -> -2669.14
A48: Mois | B48: Montant
A49: Janvier 2026 | B49: =SUMIFS(Détail!$E:$E,Détail!$D:$D,"MME SABRINA MAHMOUDI",Détail!$A:$A,">="&DATE(2026,1,1),Détail!$A:$A,"<"&EDATE(DATE(2026,1,1),1)) -> 0
...

Sheet Fournisseurs France détail
A1: Fournisseurs matières premières & emballage (France) — détail par fournisseur (2026)
A3: Cpl Aromas France | C3: =SUMIF(Détail!$D:$D,"CPL AROMAS FRANCE",Détail!$E:$E) -> -105066.75
A4: Mois | B4: Montant
A5: Janvier 2026 | B5: =SUMIFS(Détail!$E:$E,Détail!$D:$D,"CPL AROMAS FRANCE",Détail!$A:$A,">="&DATE(2026,1,1),Détail!$A:$A,"<"&EDATE(DATE(2026,1,1),1)) -> -13893
A6: Février 2026 | B6: =SUMIFS(Détail!$E:$E,Détail!$D:$D,"CPL AROMAS FRANCE",Détail!$A:$A,">="&DATE(2026,2,1),Détail!$A:$A,"<"&EDATE(DATE(2026,2,1),1)) -> -4860
A7: Avril 2026 | B7: =SUMIFS(Détail!$E:$E,Détail!$D:$D,"CPL AROMAS FRANCE",Détail!$A:$A,">="&DATE(2026,4,1),Détail!$A:$A,"<"&EDATE(DATE(2026,4,1),1)) -> -25538.75
A8: Mai 2026 | B8: =SUMIFS(Détail!$E:$E,Détail!$D:$D,"CPL AROMAS FRANCE",Détail!$A:$A,">="&DATE(2026,5,1),Détail!$A:$A,"<"&EDATE(DATE(2026,5,1),1)) -> -34580
A9: Juin 2026 | B9: =SUMIFS(Détail!$E:$E,Détail!$D:$D,"CPL AROMAS FRANCE",Détail!$A:$A,">="&DATE(2026,6,1),Détail!$A:$A,"<"&EDATE(DATE(2026,6,1),1)) -> -26195
A10: Juillet 2026 | B10: =SUMIFS(Détail!$E:$E,Détail!$D:$D,"CPL AROMAS FRANCE",Détail!$A:$A,">="&DATE(2026,7,1),Détail!$A:$A,"<"&EDATE(DATE(2026,7,1),1)) -> 0
A13: Aromascent | C13: =SUMIF(Détail!$D:$D,"AROMASCENT",Détail!$E:$E) -> -85707
A14: Mois | B14: Montant
A15: Janvier 2026 | B15: =SUMIFS(Détail!$E:$E,Détail!$D:$D,"AROMASCENT",Détail!$A:$A,">="&DATE(2026,1,1),Détail!$A:$A,"<"&EDATE(DATE(2026,1,1),1)) -> -5222
A16: Février 2026 | B16: =SUMIFS(Détail!$E:$E,Détail!$D:$D,"AROMASCENT",Détail!$A:$A,">="&DATE(2026,2,1),Détail!$A:$A,"<"&EDATE(DATE(2026,2,1),1)) -> -13638
A17: Avril 2026 | B17: =SUMIFS(Détail!$E:$E,Détail!$D:$D,"AROMASCENT",Détail!$A:$A,">="&DATE(2026,4,1),Détail!$A:$A,"<"&EDATE(DATE(2026,4,1),1)) -> -13484
A18: Mai 2026 | B18: =SUMIFS(Détail!$E:$E,Détail!$D:$D,"AROMASCENT",Détail!$A:$A,">="&DATE(2026,5,1),Détail!$A:$A,"<"&EDATE(DATE(2026,5,1),1)) -> 0
A19: Juin 2026 | B19: =SUMIFS(Détail!$E:$E,Détail!$D:$D,"AROMASCENT",Détail!$A:$A,">="&DATE(2026,6,1),Détail!$A:$A,"<"&EDATE(DATE(2026,6,1),1)) -> -53363
A20: Juillet 2026 | B20: =SUMIFS(Détail!$E:$E,Détail!$D:$D,"AROMASCENT",Détail!$A:$A,">="&DATE(2026,7,1),Détail!$A:$A,"<"&EDATE(DATE(2026,7,1),1)) -> 0
A23: Firmenich | C23: =SUMIF(Détail!$D:$D,"FIRMENICH",Détail!$E:$E) -> -19500.6
A24: Mois | B24: Montant
A25: Janvier 2026 | B25: =SUMIFS(Détail!$E:$E,Détail!$D:$D,"FIRMENICH",Détail!$A:$A,">="&DATE(2026,1,1),Détail!$A:$A,"<"&EDATE(DATE(2026,1,1),1)) -> 0
A26: Février 2026 | B26: =SUMIFS(Détail!$E:$E,Détail!$D:$D,"FIRMENICH",Détail!$A:$A,">="&DATE(2026,2,1),Détail!$A:$A,"<"&EDATE(DATE(2026,2,1),1)) -> 0
A27: Avril 2026 | B27: =SUMIFS(Détail!$E:$E,Détail!$D:$D,"FIRMENICH",Détail!$A:$A,">="&DATE(2026,4,1),Détail!$A:$A,"<"&EDATE(DATE(2026,4,1),1)) -> 0
A28: Mai 2026 | B28: =SUMIFS(Détail!$E:$E,Détail!$D:$D,"FIRMENICH",Détail!$A:$A,">="&DATE(2026,5,1),Détail!$A:$A,"<"&EDATE(DATE(2026,5,1),1)) -> -19500.6
A29: Juin 2026 | B29: =SUMIFS(Détail!$E:$E,Détail!$D:$D,"FIRMENICH",Détail!$A:$A,">="&DATE(2026,6,1),Détail!$A:$A,"<"&EDATE(DATE(2026,6,1),1)) -> 0
A30: Juillet 2026 | B30: =SUMIFS(Détail!$E:$E,Détail!$D:$D,"FIRMENICH",Détail!$A:$A,">="&DATE(2026,7,1),Détail!$A:$A,"<"&EDATE(DATE(2026,7,1),1)) -> 0
A33: Cartonnages Du Val D Orge | C33: =SUMIF(Détail!$D:$D,"CARTONNAGES DU VAL D ORGE",Détail!$E:$E) -> -7922.52
A34: Mois | B34: Montant
A35: Janvier 2026 | B35: =SUMIFS(Détail!$E:$E,Détail!$D:$D,"CARTONNAGES DU VAL D ORGE",Détail!$A:$A,">="&DATE(2026,1,1),Détail!$A:$A,"<"&EDATE(DATE(2026,1,1),1)) -> -1828.8
A36: Février 2026 | B36: =SUMIFS(Détail!$E:$E,Détail!$D:$D,"CARTONNAGES DU VAL D ORGE",Détail!$A:$A,">="&DATE(2026,2,1),Détail!$A:$A,"<"&EDATE(DATE(2026,2,1),1)) -> 0
A37: Avril 2026 | B37: =SUMIFS(Détail!$E:$E,Détail!$D:$D,"CARTONNAGES DU VAL D ORGE",Détail!$A:$A,">="&DATE(2026,4,1),Détail!$A:$A,"<"&EDATE(DATE(2026,4,1),1)) -> 0
A38: Mai 2026 | B38: =SUMIFS(Détail!$E:$E,Détail!$D:$D,"CARTONNAGES DU VAL D ORGE",Détail!$A:$A,">="&DATE(2026,5,1),Détail!$A:$A,"<"&EDATE(DATE(2026,5,1),1)) -> -6093.72
A39: Juin 2026 | B39: =SUMIFS(Détail!$E:$E,Détail!$D:$D,"CARTONNAGES DU VAL D ORGE",Détail!$A:$A,">="&DATE(2026,6,1),Détail!$A:$A,"<"&EDATE(DATE(2026,6,1),1)) -> 0
A40: Juillet 2026 | B40: =SUMIFS(Détail!$E:$E,Détail!$D:$D,"CARTONNAGES DU VAL D ORGE",Détail!$A:$A,">="&DATE(2026,7,1),Détail!$A:$A,"<"&EDATE(DATE(2026,7,1),1)) -> 0
A43: Sleeve Concept | C43: =SUMIF(Détail!$D:$D,"SLEEVE CONCEPT",Détail!$E:$E) -> -7707.85
A44: Mois | B44: Montant
A45: Janvier 2026 | B45: =SUMIFS(Détail!$E:$E,Détail!$D:$D,"SLEEVE CONCEPT",Détail!$A:$A,">="&DATE(2026,1,1),Détail!$A:$A,"<"&EDATE(DATE(2026,1,1),1)) -> -7707.85
A46: Février 2026 | B46: =SUMIFS(Détail!$E:$E,Détail!$D:$D,"SLEEVE CONCEPT",Détail!$A:$A,">="&DATE(2026,2,1),Détail!$A:$A,"<"&EDATE(DATE(2026,2,1),1)) -> 0
A47: Avril 2026 | B47: =SUMIFS(Détail!$E:$E,Détail!$D:$D,"SLEEVE CONCEPT",Détail!$A:$A,">="&DATE(2026,4,1),Détail!$A:$A,"<"&EDATE(DATE(2026,4,1),1)) -> 0
A48: Mai 2026 | B48: =SUMIFS(Détail!$E:$E,Détail!$D:$D,"SLEEVE CONCEPT",Détail!$A:$A,">="&DATE(2026,5,1),Détail!$A:$A,"<"&EDATE(DATE(2026,5,1),1)) -> 0
A49: Juin 2026 | B49: =SUMIFS(Détail!$E:$E,Détail!$D:$D,"SLEEVE CONCEPT",Détail!$A:$A,">="&DATE(2026,6,1),Détail!$A:$A,"<"&EDATE(DATE(2026,6,1),1)) -> 0
...

Sheet Usine conditionnement détail
A1: Usine de conditionnement et macération — détail (2026)
A3: France Conditionnement Parfum | C3: =SUMIF(Détail!$D:$D,"FRANCE CONDITIONNEMENT PARFUM",Détail!$E:$E) -> -136758.73
A4: Mois | B4: Montant
A5: Janvier 2026 | B5: =SUMIFS(Détail!$E:$E,Détail!$D:$D,"FRANCE CONDITIONNEMENT PARFUM",Détail!$A:$A,">="&DATE(2026,1,1),Détail!$A:$A,"<"&EDATE(DATE(2026,1,1),1)) -> -23997.81
A6: Février 2026 | B6: =SUMIFS(Détail!$E:$E,Détail!$D:$D,"FRANCE CONDITIONNEMENT PARFUM",Détail!$A:$A,">="&DATE(2026,2,1),Détail!$A:$A,"<"&EDATE(DATE(2026,2,1),1)) -> -5639.86
A7: Avril 2026 | B7: =SUMIFS(Détail!$E:$E,Détail!$D:$D,"FRANCE CONDITIONNEMENT PARFUM",Détail!$A:$A,">="&DATE(2026,4,1),Détail!$A:$A,"<"&EDATE(DATE(2026,4,1),1)) -> -24999.66
A8: Mai 2026 | B8: =SUMIFS(Détail!$E:$E,Détail!$D:$D,"FRANCE CONDITIONNEMENT PARFUM",Détail!$A:$A,">="&DATE(2026,5,1),Détail!$A:$A,"<"&EDATE(DATE(2026,5,1),1)) -> -26556.5
A9: Juin 2026 | B9: =SUMIFS(Détail!$E:$E,Détail!$D:$D,"FRANCE CONDITIONNEMENT PARFUM",Détail!$A:$A,">="&DATE(2026,6,1),Détail!$A:$A,"<"&EDATE(DATE(2026,6,1),1)) -> -55564.9

Sheet Fournisseurs intl détail
A1: Fournisseurs internationaux (Chine/Import) — détail par fournisseur (2026)
A3: Gold Rock Company Limited | C3: =SUMIF(Détail!$D:$D,"GOLD ROCK COMPANY LIMITED",Détail!$E:$E) -> -21026.95
A4: Mois | B4: Montant
A5: Janvier 2026 | B5: =SUMIFS(Détail!$E:$E,Détail!$D:$D,"GOLD ROCK COMPANY LIMITED",Détail!$A:$A,">="&DATE(2026,1,1),Détail!$A:$A,"<"&EDATE(DATE(2026,1,1),1)) -> 0
A6: Février 2026 | B6: =SUMIFS(Détail!$E:$E,Détail!$D:$D,"GOLD ROCK COMPANY LIMITED",Détail!$A:$A,">="&DATE(2026,2,1),Détail!$A:$A,"<"&EDATE(DATE(2026,2,1),1)) -> 0
A7: Mars 2026 | B7: =SUMIFS(Détail!$E:$E,Détail!$D:$D,"GOLD ROCK COMPANY LIMITED",Détail!$A:$A,">="&DATE(2026,3,1),Détail!$A:$A,"<"&EDATE(DATE(2026,3,1),1)) -> -21026.95
A8: Avril 2026 | B8: =SUMIFS(Détail!$E:$E,Détail!$D:$D,"GOLD ROCK COMPANY LIMITED",Détail!$A:$A,">="&DATE(2026,4,1),Détail!$A:$A,"<"&EDATE(DATE(2026,4,1),1)) -> 0
A9: Mai 2026 | B9: =SUMIFS(Détail!$E:$E,Détail!$D:$D,"GOLD ROCK COMPANY LIMITED",Détail!$A:$A,">="&DATE(2026,5,1),Détail!$A:$A,"<"&EDATE(DATE(2026,5,1),1)) -> 0
A10: Juin 2026 | B10: =SUMIFS(Détail!$E:$E,Détail!$D:$D,"GOLD ROCK COMPANY LIMITED",Détail!$A:$A,">="&DATE(2026,6,1),Détail!$A:$A,"<"&EDATE(DATE(2026,6,1),1)) -> 0
A13: Leaders Hardware Plastic Co Limited | C13: =SUMIF(Détail!$D:$D,"LEADERS HARDWARE PLASTIC CO LIMITED",Détail!$E:$E) -> -15497.84
A14: Mois | B14: Montant
A15: Janvier 2026 | B15: =SUMIFS(Détail!$E:$E,Détail!$D:$D,"LEADERS HARDWARE PLASTIC CO LIMITED",Détail!$A:$A,">="&DATE(2026,1,1),Détail!$A:$A,"<"&EDATE(DATE(2026,1,1),1)) -> 0
A16: Février 2026 | B16: =SUMIFS(Détail!$E:$E,Détail!$D:$D,"LEADERS HARDWARE PLASTIC CO LIMITED",Détail!$A:$A,">="&DATE(2026,2,1),Détail!$A:$A,"<"&EDATE(DATE(2026,2,1),1)) -> 0
A17: Mars 2026 | B17: =SUMIFS(Détail!$E:$E,Détail!$D:$D,"LEADERS HARDWARE PLASTIC CO LIMITED",Détail!$A:$A,">="&DATE(2026,3,1),Détail!$A:$A,"<"&EDATE(DATE(2026,3,1),1)) -> -3489.28
A18: Avril 2026 | B18: =SUMIFS(Détail!$E:$E,Détail!$D:$D,"LEADERS HARDWARE PLASTIC CO LIMITED",Détail!$A:$A,">="&DATE(2026,4,1),Détail!$A:$A,"<"&EDATE(DATE(2026,4,1),1)) -> -4373.08
A19: Mai 2026 | B19: =SUMIFS(Détail!$E:$E,Détail!$D:$D,"LEADERS HARDWARE PLASTIC CO LIMITED",Détail!$A:$A,">="&DATE(2026,5,1),Détail!$A:$A,"<"&EDATE(DATE(2026,5,1),1)) -> -3057.38
A20: Juin 2026 | B20: =SUMIFS(Détail!$E:$E,Détail!$D:$D,"LEADERS HARDWARE PLASTIC CO LIMITED",Détail!$A:$A,">="&DATE(2026,6,1),Détail!$A:$A,"<"&EDATE(DATE(2026,6,1),1)) -> -4578.1
A23: Fu Hui Paper Product Limited | C23: =SUMIF(Détail!$D:$D,"FU HUI PAPER PRODUCT LIMITED",Détail!$E:$E) -> -13613.22
A24: Mois | B24: Montant
A25: Janvier 2026 | B25: =SUMIFS(Détail!$E:$E,Détail!$D:$D,"FU HUI PAPER PRODUCT LIMITED",Détail!$A:$A,">="&DATE(2026,1,1),Détail!$A:$A,"<"&EDATE(DATE(2026,1,1),1)) -> -8573.6
A26: Février 2026 | B26: =SUMIFS(Détail!$E:$E,Détail!$D:$D,"FU HUI PAPER PRODUCT LIMITED",Détail!$A:$A,">="&DATE(2026,2,1),Détail!$A:$A,"<"&EDATE(DATE(2026,2,1),1)) -> -5039.62
A27: Mars 2026 | B27: =SUMIFS(Détail!$E:$E,Détail!$D:$D,"FU HUI PAPER PRODUCT LIMITED",Détail!$A:$A,">="&DATE(2026,3,1),Détail!$A:$A,"<"&EDATE(DATE(2026,3,1),1)) -> 0
A28: Avril 2026 | B28: =SUMIFS(Détail!$E:$E,Détail!$D:$D,"FU HUI PAPER PRODUCT LIMITED",Détail!$A:$A,">="&DATE(2026,4,1),Détail!$A:$A,"<"&EDATE(DATE(2026,4,1),1)) -> 0
A29: Mai 2026 | B29: =SUMIFS(Détail!$E:$E,Détail!$D:$D,"FU HUI PAPER PRODUCT LIMITED",Détail!$A:$A,">="&DATE(2026,5,1),Détail!$A:$A,"<"&EDATE(DATE(2026,5,1),1)) -> 0
A30: Juin 2026 | B30: =SUMIFS(Détail!$E:$E,Détail!$D:$D,"FU HUI PAPER PRODUCT LIMITED",Détail!$A:$A,">="&DATE(2026,6,1),Détail!$A:$A,"<"&EDATE(DATE(2026,6,1),1)) -> 0
A33: Leaders Hardware Plastic Co Limit | C33: =SUMIF(Détail!$D:$D,"LEADERS HARDWARE PLASTIC CO LIMIT",Détail!$E:$E) -> -6224.84
A34: Mois | B34: Montant
A35: Janvier 2026 | B35: =SUMIFS(Détail!$E:$E,Détail!$D:$D,"LEADERS HARDWARE PLASTIC CO LIMIT",Détail!$A:$A,">="&DATE(2026,1,1),Détail!$A:$A,"<"&EDATE(DATE(2026,1,1),1)) -> -6224.84
A36: Février 2026 | B36: =SUMIFS(Détail!$E:$E,Détail!$D:$D,"LEADERS HARDWARE PLASTIC CO LIMIT",Détail!$A:$A,">="&DATE(2026,2,1),Détail!$A:$A,"<"&EDATE(DATE(2026,2,1),1)) -> 0
A37: Mars 2026 | B37: =SUMIFS(Détail!$E:$E,Détail!$D:$D,"LEADERS HARDWARE PLASTIC CO LIMIT",Détail!$A:$A,">="&DATE(2026,3,1),Détail!$A:$A,"<"&EDATE(DATE(2026,3,1),1)) -> 0
A38: Avril 2026 | B38: =SUMIFS(Détail!$E:$E,Détail!$D:$D,"LEADERS HARDWARE PLASTIC CO LIMIT",Détail!$A:$A,">="&DATE(2026,4,1),Détail!$A:$A,"<"&EDATE(DATE(2026,4,1),1)) -> 0
A39: Mai 2026 | B39: =SUMIFS(Détail!$E:$E,Détail!$D:$D,"LEADERS HARDWARE PLASTIC CO LIMIT",Détail!$A:$A,">="&DATE(2026,5,1),Détail!$A:$A,"<"&EDATE(DATE(2026,5,1),1)) -> 0
A40: Juin 2026 | B40: =SUMIFS(Détail!$E:$E,Détail!$D:$D,"LEADERS HARDWARE PLASTIC CO LIMIT",Détail!$A:$A,">="&DATE(2026,6,1),Détail!$A:$A,"<"&EDATE(DATE(2026,6,1),1)) -> 0
A43: Zhejiang Bi Industrial Co Ltd | C43: =SUMIF(Détail!$D:$D,"ZHEJIANG BI INDUSTRIAL CO LTD",Détail!$E:$E) -> -980.12
A44: Mois | B44: Montant
A45: Janvier 2026 | B45: =SUMIFS(Détail!$E:$E,Détail!$D:$D,"ZHEJIANG BI INDUSTRIAL CO LTD",Détail!$A:$A,">="&DATE(2026,1,1),Détail!$A:$A,"<"&EDATE(DATE(2026,1,1),1)) -> 0
A46: Février 2026 | B46: =SUMIFS(Détail!$E:$E,Détail!$D:$D,"ZHEJIANG BI INDUSTRIAL CO LTD",Détail!$A:$A,">="&DATE(2026,2,1),Détail!$A:$A,"<"&EDATE(DATE(2026,2,1),1)) -> -715.69
A47: Mars 2026 | B47: =SUMIFS(Détail!$E:$E,Détail!$D:$D,"ZHEJIANG BI INDUSTRIAL CO LTD",Détail!$A:$A,">="&DATE(2026,3,1),Détail!$A:$A,"<"&EDATE(DATE(2026,3,1),1)) -> -264.43
A48: Avril 2026 | B48: =SUMIFS(Détail!$E:$E,Détail!$D:$D,"ZHEJIANG BI INDUSTRIAL CO LTD",Détail!$A:$A,">="&DATE(2026,4,1),Détail!$A:$A,"<"&EDATE(DATE(2026,4,1),1)) -> 0
A49: Mai 2026 | B49: =SUMIFS(Détail!$E:$E,Détail!$D:$D,"ZHEJIANG BI INDUSTRIAL CO LTD",Détail!$A:$A,">="&DATE(2026,5,1),Détail!$A:$A,"<"&EDATE(DATE(2026,5,1),1)) -> 0
...

Sheet Charges sociales détail
A1: Charges sociales & cotisations — détail par organisme (2026)
A3: Urssaf D'Ile De France | C3: =SUMIF(Détail!$D:$D,"URSSAF D'ILE DE FRANCE",Détail!$E:$E) -> -20330
A4: Mois | B4: Montant
A5: Janvier 2026 | B5: =SUMIFS(Détail!$E:$E,Détail!$D:$D,"URSSAF D'ILE DE FRANCE",Détail!$A:$A,">="&DATE(2026,1,1),Détail!$A:$A,"<"&EDATE(DATE(2026,1,1),1)) -> -5040
A6: Février 2026 | B6: =SUMIFS(Détail!$E:$E,Détail!$D:$D,"URSSAF D'ILE DE FRANCE",Détail!$A:$A,">="&DATE(2026,2,1),Détail!$A:$A,"<"&EDATE(DATE(2026,2,1),1)) -> -2961
A7: Mars 2026 | B7: =SUMIFS(Détail!$E:$E,Détail!$D:$D,"URSSAF D'ILE DE FRANCE",Détail!$A:$A,">="&DATE(2026,3,1),Détail!$A:$A,"<"&EDATE(DATE(2026,3,1),1)) -> -2958
A8: Avril 2026 | B8: =SUMIFS(Détail!$E:$E,Détail!$D:$D,"URSSAF D'ILE DE FRANCE",Détail!$A:$A,">="&DATE(2026,4,1),Détail!$A:$A,"<"&EDATE(DATE(2026,4,1),1)) -> -2955
A9: Mai 2026 | B9: =SUMIFS(Détail!$E:$E,Détail!$D:$D,"URSSAF D'ILE DE FRANCE",Détail!$A:$A,">="&DATE(2026,5,1),Détail!$A:$A,"<"&EDATE(DATE(2026,5,1),1)) -> -3038
A10: Juin 2026 | B10: =SUMIFS(Détail!$E:$E,Détail!$D:$D,"URSSAF D'ILE DE FRANCE",Détail!$A:$A,">="&DATE(2026,6,1),Détail!$A:$A,"<"&EDATE(DATE(2026,6,1),1)) -> -3378
A13: Ag2R Reunica | C13: =SUMIF(Détail!$D:$D,"AG2R REUNICA",Détail!$E:$E) -> -3934.14
A14: Mois | B14: Montant
A15: Janvier 2026 | B15: =SUMIFS(Détail!$E:$E,Détail!$D:$D,"AG2R REUNICA",Détail!$A:$A,">="&DATE(2026,1,1),Détail!$A:$A,"<"&EDATE(DATE(2026,1,1),1)) -> -1107.3
A16: Février 2026 | B16: =SUMIFS(Détail!$E:$E,Détail!$D:$D,"AG2R REUNICA",Détail!$A:$A,">="&DATE(2026,2,1),Détail!$A:$A,"<"&EDATE(DATE(2026,2,1),1)) -> -552.44
A17: Mars 2026 | B17: =SUMIFS(Détail!$E:$E,Détail!$D:$D,"AG2R REUNICA",Détail!$A:$A,">="&DATE(2026,3,1),Détail!$A:$A,"<"&EDATE(DATE(2026,3,1),1)) -> -551.83
A18: Avril 2026 | B18: =SUMIFS(Détail!$E:$E,Détail!$D:$D,"AG2R REUNICA",Détail!$A:$A,">="&DATE(2026,4,1),Détail!$A:$A,"<"&EDATE(DATE(2026,4,1),1)) -> -551.36
A19: Mai 2026 | B19: =SUMIFS(Détail!$E:$E,Détail!$D:$D,"AG2R REUNICA",Détail!$A:$A,">="&DATE(2026,5,1),Détail!$A:$A,"<"&EDATE(DATE(2026,5,1),1)) -> -551.35
A20: Juin 2026 | B20: =SUMIFS(Détail!$E:$E,Détail!$D:$D,"AG2R REUNICA",Détail!$A:$A,">="&DATE(2026,6,1),Détail!$A:$A,"<"&EDATE(DATE(2026,6,1),1)) -> -619.86
A23: Direction Generale Des Finances Publiques (Dgfip) | C23: =SUMIF(Détail!$D:$D,"DIRECTION GENERALE DES FINANCES PUBLIQUES (DGFIP)",Détail!$E:$E) -> -1417
A24: Mois | B24: Montant
A25: Janvier 2026 | B25: =SUMIFS(Détail!$E:$E,Détail!$D:$D,"DIRECTION GENERALE DES FINANCES PUBLIQUES (DGFIP)",Détail!$A:$A,">="&DATE(2026,1,1),Détail!$A:$A,"<"&EDATE(DATE(2026,1,1),1)) -> -237
A26: Février 2026 | B26: =SUMIFS(Détail!$E:$E,Détail!$D:$D,"DIRECTION GENERALE DES FINANCES PUBLIQUES (DGFIP)",Détail!$A:$A,">="&DATE(2026,2,1),Détail!$A:$A,"<"&EDATE(DATE(2026,2,1),1)) -> -236
A27: Mars 2026 | B27: =SUMIFS(Détail!$E:$E,Détail!$D:$D,"DIRECTION GENERALE DES FINANCES PUBLIQUES (DGFIP)",Détail!$A:$A,">="&DATE(2026,3,1),Détail!$A:$A,"<"&EDATE(DATE(2026,3,1),1)) -> -236
A28: Avril 2026 | B28: =SUMIFS(Détail!$E:$E,Détail!$D:$D,"DIRECTION GENERALE DES FINANCES PUBLIQUES (DGFIP)",Détail!$A:$A,">="&DATE(2026,4,1),Détail!$A:$A,"<"&EDATE(DATE(2026,4,1),1)) -> -236
A29: Mai 2026 | B29: =SUMIFS(Détail!$E:$E,Détail!$D:$D,"DIRECTION GENERALE DES FINANCES PUBLIQUES (DGFIP)",Détail!$A:$A,">="&DATE(2026,5,1),Détail!$A:$A,"<"&EDATE(DATE(2026,5,1),1)) -> -236
A30: Juin 2026 | B30: =SUMIFS(Détail!$E:$E,Détail!$D:$D,"DIRECTION GENERALE DES FINANCES PUBLIQUES (DGFIP)",Détail!$A:$A,">="&DATE(2026,6,1),Détail!$A:$A,"<"&EDATE(DATE(2026,6,1),1)) -> -236

Sheet Voyages détail
A1: Voyages / déplacements — détail par prestataire (2026)
A3: Emirates | C3: =SUMIF(Détail!$D:$D,"EMIRATES",Détail!$E:$E) -> -3743.41
A4: Mois | B4: Montant
A5: Janvier 2026 | B5: =SUMIFS(Détail!$E:$E,Détail!$D:$D,"EMIRATES",Détail!$A:$A,">="&DATE(2026,1,1),Détail!$A:$A,"<"&EDATE(DATE(2026,1,1),1)) -> -202
A6: Mars 2026 | B6: =SUMIFS(Détail!$E:$E,Détail!$D:$D,"EMIRATES",Détail!$A:$A,">="&DATE(2026,3,1),Détail!$A:$A,"<"&EDATE(DATE(2026,3,1),1)) -> 0
A7: Avril 2026 | B7: =SUMIFS(Détail!$E:$E,Détail!$D:$D,"EMIRATES",Détail!$A:$A,">="&DATE(2026,4,1),Détail!$A:$A,"<"&EDATE(DATE(2026,4,1),1)) -> -1011.86
A8: Mai 2026 | B8: =SUMIFS(Détail!$E:$E,Détail!$D:$D,"EMIRATES",Détail!$A:$A,">="&DATE(2026,5,1),Détail!$A:$A,"<"&EDATE(DATE(2026,5,1),1)) -> -590.91
A9: Juin 2026 | B9: =SUMIFS(Détail!$E:$E,Détail!$D:$D,"EMIRATES",Détail!$A:$A,">="&DATE(2026,6,1),Détail!$A:$A,"<"&EDATE(DATE(2026,6,1),1)) -> -757.12
A10: Juillet 2026 | B10: =SUMIFS(Détail!$E:$E,Détail!$D:$D,"EMIRATES",Détail!$A:$A,">="&DATE(2026,7,1),Détail!$A:$A,"<"&EDATE(DATE(2026,7,1),1)) -> -1181.52
A13: Five Luxe Hotel | C13: =SUMIF(Détail!$D:$D,"FIVE LUXE HOTEL",Détail!$E:$E) -> -1859.74
A14: Mois | B14: Montant
A15: Janvier 2026 | B15: =SUMIFS(Détail!$E:$E,Détail!$D:$D,"FIVE LUXE HOTEL",Détail!$A:$A,">="&DATE(2026,1,1),Détail!$A:$A,"<"&EDATE(DATE(2026,1,1),1)) -> 0
A16: Mars 2026 | B16: =SUMIFS(Détail!$E:$E,Détail!$D:$D,"FIVE LUXE HOTEL",Détail!$A:$A,">="&DATE(2026,3,1),Détail!$A:$A,"<"&EDATE(DATE(2026,3,1),1)) -> 0
A17: Avril 2026 | B17: =SUMIFS(Détail!$E:$E,Détail!$D:$D,"FIVE LUXE HOTEL",Détail!$A:$A,">="&DATE(2026,4,1),Détail!$A:$A,"<"&EDATE(DATE(2026,4,1),1)) -> 0
A18: Mai 2026 | B18: =SUMIFS(Détail!$E:$E,Détail!$D:$D,"FIVE LUXE HOTEL",Détail!$A:$A,">="&DATE(2026,5,1),Détail!$A:$A,"<"&EDATE(DATE(2026,5,1),1)) -> 0
A19: Juin 2026 | B19: =SUMIFS(Détail!$E:$E,Détail!$D:$D,"FIVE LUXE HOTEL",Détail!$A:$A,">="&DATE(2026,6,1),Détail!$A:$A,"<"&EDATE(DATE(2026,6,1),1)) -> -1860.01
A20: Juillet 2026 | B20: =SUMIFS(Détail!$E:$E,Détail!$D:$D,"FIVE LUXE HOTEL",Détail!$A:$A,">="&DATE(2026,7,1),Détail!$A:$A,"<"&EDATE(DATE(2026,7,1),1)) -> 0.27
A23: Air France | C23: =SUMIF(Détail!$D:$D,"AIR FRANCE",Détail!$E:$E) -> -1460.32
A24: Mois | B24: Montant
A25: Janvier 2026 | B25: =SUMIFS(Détail!$E:$E,Détail!$D:$D,"AIR FRANCE",Détail!$A:$A,">="&DATE(2026,1,1),Détail!$A:$A,"<"&EDATE(DATE(2026,1,1),1)) -> 0
A26: Mars 2026 | B26: =SUMIFS(Détail!$E:$E,Détail!$D:$D,"AIR FRANCE",Détail!$A:$A,">="&DATE(2026,3,1),Détail!$A:$A,"<"&EDATE(DATE(2026,3,1),1)) -> -440.58
A27: Avril 2026 | B27: =SUMIFS(Détail!$E:$E,Détail!$D:$D,"AIR FRANCE",Détail!$A:$A,">="&DATE(2026,4,1),Détail!$A:$A,"<"&EDATE(DATE(2026,4,1),1)) -> 0
A28: Mai 2026 | B28: =SUMIFS(Détail!$E:$E,Détail!$D:$D,"AIR FRANCE",Détail!$A:$A,">="&DATE(2026,5,1),Détail!$A:$A,"<"&EDATE(DATE(2026,5,1),1)) -> 0
A29: Juin 2026 | B29: =SUMIFS(Détail!$E:$E,Détail!$D:$D,"AIR FRANCE",Détail!$A:$A,">="&DATE(2026,6,1),Détail!$A:$A,"<"&EDATE(DATE(2026,6,1),1)) -> -995.74
A30: Juillet 2026 | B30: =SUMIFS(Détail!$E:$E,Détail!$D:$D,"AIR FRANCE",Détail!$A:$A,">="&DATE(2026,7,1),Détail!$A:$A,"<"&EDATE(DATE(2026,7,1),1)) -> -24
A33: Airbnb | C33: =SUMIF(Détail!$D:$D,"AIRBNB",Détail!$E:$E) -> -1207.64
A34: Mois | B34: Montant
A35: Janvier 2026 | B35: =SUMIFS(Détail!$E:$E,Détail!$D:$D,"AIRBNB",Détail!$A:$A,">="&DATE(2026,1,1),Détail!$A:$A,"<"&EDATE(DATE(2026,1,1),1)) -> 0
A36: Mars 2026 | B36: =SUMIFS(Détail!$E:$E,Détail!$D:$D,"AIRBNB",Détail!$A:$A,">="&DATE(2026,3,1),Détail!$A:$A,"<"&EDATE(DATE(2026,3,1),1)) -> 0
A37: Avril 2026 | B37: =SUMIFS(Détail!$E:$E,Détail!$D:$D,"AIRBNB",Détail!$A:$A,">="&DATE(2026,4,1),Détail!$A:$A,"<"&EDATE(DATE(2026,4,1),1)) -> -1207.64
A38: Mai 2026 | B38: =SUMIFS(Détail!$E:$E,Détail!$D:$D,"AIRBNB",Détail!$A:$A,">="&DATE(2026,5,1),Détail!$A:$A,"<"&EDATE(DATE(2026,5,1),1)) -> 0
A39: Juin 2026 | B39: =SUMIFS(Détail!$E:$E,Détail!$D:$D,"AIRBNB",Détail!$A:$A,">="&DATE(2026,6,1),Détail!$A:$A,"<"&EDATE(DATE(2026,6,1),1)) -> 0
A40: Juillet 2026 | B40: =SUMIFS(Détail!$E:$E,Détail!$D:$D,"AIRBNB",Détail!$A:$A,">="&DATE(2026,7,1),Détail!$A:$A,"<"&EDATE(DATE(2026,7,1),1)) -> 0
A43: Hotel Le Royal | C43: =SUMIF(Détail!$D:$D,"HOTEL LE ROYAL",Détail!$E:$E) -> -757
A44: Mois | B44: Montant
A45: Janvier 2026 | B45: =SUMIFS(Détail!$E:$E,Détail!$D:$D,"HOTEL LE ROYAL",Détail!$A:$A,">="&DATE(2026,1,1),Détail!$A:$A,"<"&EDATE(DATE(2026,1,1),1)) -> 0
A46: Mars 2026 | B46: =SUMIFS(Détail!$E:$E,Détail!$D:$D,"HOTEL LE ROYAL",Détail!$A:$A,">="&DATE(2026,3,1),Détail!$A:$A,"<"&EDATE(DATE(2026,3,1),1)) -> 0
A47: Avril 2026 | B47: =SUMIFS(Détail!$E:$E,Détail!$D:$D,"HOTEL LE ROYAL",Détail!$A:$A,">="&DATE(2026,4,1),Détail!$A:$A,"<"&EDATE(DATE(2026,4,1),1)) -> -757
A48: Mai 2026 | B48: =SUMIFS(Détail!$E:$E,Détail!$D:$D,"HOTEL LE ROYAL",Détail!$A:$A,">="&DATE(2026,5,1),Détail!$A:$A,"<"&EDATE(DATE(2026,5,1),1)) -> 0
A49: Juin 2026 | B49: =SUMIFS(Détail!$E:$E,Détail!$D:$D,"HOTEL LE ROYAL",Détail!$A:$A,">="&DATE(2026,6,1),Détail!$A:$A,"<"&EDATE(DATE(2026,6,1),1)) -> 0
...

Sheet Téléphone-Internet détail
A1: Téléphone / Internet / Logiciels — détail par prestataire (2026)
A3: Orange Sa | C3: =SUMIF(Détail!$D:$D,"ORANGE SA",Détail!$E:$E) -> -3596.25
A4: Mois | B4: Montant
A5: Janvier 2026 | B5: =SUMIFS(Détail!$E:$E,Détail!$D:$D,"ORANGE SA",Détail!$A:$A,">="&DATE(2026,1,1),Détail!$A:$A,"<"&EDATE(DATE(2026,1,1),1)) -> -670.88
A6: Février 2026 | B6: =SUMIFS(Détail!$E:$E,Détail!$D:$D,"ORANGE SA",Détail!$A:$A,">="&DATE(2026,2,1),Détail!$A:$A,"<"&EDATE(DATE(2026,2,1),1)) -> -703.49
A7: Mars 2026 | B7: =SUMIFS(Détail!$E:$E,Détail!$D:$D,"ORANGE SA",Détail!$A:$A,">="&DATE(2026,3,1),Détail!$A:$A,"<"&EDATE(DATE(2026,3,1),1)) -> -518
A8: Avril 2026 | B8: =SUMIFS(Détail!$E:$E,Détail!$D:$D,"ORANGE SA",Détail!$A:$A,">="&DATE(2026,4,1),Détail!$A:$A,"<"&EDATE(DATE(2026,4,1),1)) -> -527.32
A9: Mai 2026 | B9: =SUMIFS(Détail!$E:$E,Détail!$D:$D,"ORANGE SA",Détail!$A:$A,">="&DATE(2026,5,1),Détail!$A:$A,"<"&EDATE(DATE(2026,5,1),1)) -> -642.82
A10: Juin 2026 | B10: =SUMIFS(Détail!$E:$E,Détail!$D:$D,"ORANGE SA",Détail!$A:$A,">="&DATE(2026,6,1),Détail!$A:$A,"<"&EDATE(DATE(2026,6,1),1)) -> -533.74
A11: Juillet 2026 | B11: =SUMIFS(Détail!$E:$E,Détail!$D:$D,"ORANGE SA",Détail!$A:$A,">="&DATE(2026,7,1),Détail!$A:$A,"<"&EDATE(DATE(2026,7,1),1)) -> 0
A14: Apple | C14: =SUMIF(Détail!$D:$D,"APPLE",Détail!$E:$E) -> -1914.69
A15: Mois | B15: Montant
A16: Janvier 2026 | B16: =SUMIFS(Détail!$E:$E,Détail!$D:$D,"APPLE",Détail!$A:$A,">="&DATE(2026,1,1),Détail!$A:$A,"<"&EDATE(DATE(2026,1,1),1)) -> -38.95
A17: Février 2026 | B17: =SUMIFS(Détail!$E:$E,Détail!$D:$D,"APPLE",Détail!$A:$A,">="&DATE(2026,2,1),Détail!$A:$A,"<"&EDATE(DATE(2026,2,1),1)) -> -137.95
A18: Mars 2026 | B18: =SUMIFS(Détail!$E:$E,Détail!$D:$D,"APPLE",Détail!$A:$A,">="&DATE(2026,3,1),Détail!$A:$A,"<"&EDATE(DATE(2026,3,1),1)) -> -38.95
A19: Avril 2026 | B19: =SUMIFS(Détail!$E:$E,Détail!$D:$D,"APPLE",Détail!$A:$A,">="&DATE(2026,4,1),Détail!$A:$A,"<"&EDATE(DATE(2026,4,1),1)) -> -56.93
A20: Mai 2026 | B20: =SUMIFS(Détail!$E:$E,Détail!$D:$D,"APPLE",Détail!$A:$A,">="&DATE(2026,5,1),Détail!$A:$A,"<"&EDATE(DATE(2026,5,1),1)) -> -721.94
A21: Juin 2026 | B21: =SUMIFS(Détail!$E:$E,Détail!$D:$D,"APPLE",Détail!$A:$A,">="&DATE(2026,6,1),Détail!$A:$A,"<"&EDATE(DATE(2026,6,1),1)) -> -905.98
A22: Juillet 2026 | B22: =SUMIFS(Détail!$E:$E,Détail!$D:$D,"APPLE",Détail!$A:$A,">="&DATE(2026,7,1),Détail!$A:$A,"<"&EDATE(DATE(2026,7,1),1)) -> -13.99
A25: Google Workspace | C25: =SUMIF(Détail!$D:$D,"GOOGLE WORKSPACE",Détail!$E:$E) -> -1036.58
A26: Mois | B26: Montant
A27: Janvier 2026 | B27: =SUMIFS(Détail!$E:$E,Détail!$D:$D,"GOOGLE WORKSPACE",Détail!$A:$A,">="&DATE(2026,1,1),Détail!$A:$A,"<"&EDATE(DATE(2026,1,1),1)) -> -145.8
A28: Février 2026 | B28: =SUMIFS(Détail!$E:$E,Détail!$D:$D,"GOOGLE WORKSPACE",Détail!$A:$A,">="&DATE(2026,2,1),Détail!$A:$A,"<"&EDATE(DATE(2026,2,1),1)) -> -145.8
A29: Mars 2026 | B29: =SUMIFS(Détail!$E:$E,Détail!$D:$D,"GOOGLE WORKSPACE",Détail!$A:$A,">="&DATE(2026,3,1),Détail!$A:$A,"<"&EDATE(DATE(2026,3,1),1)) -> -145.8
A30: Avril 2026 | B30: =SUMIFS(Détail!$E:$E,Détail!$D:$D,"GOOGLE WORKSPACE",Détail!$A:$A,">="&DATE(2026,4,1),Détail!$A:$A,"<"&EDATE(DATE(2026,4,1),1)) -> -145.8
A31: Mai 2026 | B31: =SUMIFS(Détail!$E:$E,Détail!$D:$D,"GOOGLE WORKSPACE",Détail!$A:$A,">="&DATE(2026,5,1),Détail!$A:$A,"<"&EDATE(DATE(2026,5,1),1)) -> -145.8
A32: Juin 2026 | B32: =SUMIFS(Détail!$E:$E,Détail!$D:$D,"GOOGLE WORKSPACE",Détail!$A:$A,">="&DATE(2026,6,1),Détail!$A:$A,"<"&EDATE(DATE(2026,6,1),1)) -> -152.06
A33: Juillet 2026 | B33: =SUMIFS(Détail!$E:$E,Détail!$D:$D,"GOOGLE WORKSPACE",Détail!$A:$A,">="&DATE(2026,7,1),Détail!$A:$A,"<"&EDATE(DATE(2026,7,1),1)) -> -155.52
A36: Adobe | C36: =SUMIF(Détail!$D:$D,"ADOBE",Détail!$E:$E) -> -393.24
A37: Mois | B37: Montant
A38: Janvier 2026 | B38: =SUMIFS(Détail!$E:$E,Détail!$D:$D,"ADOBE",Détail!$A:$A,">="&DATE(2026,1,1),Détail!$A:$A,"<"&EDATE(DATE(2026,1,1),1)) -> -65.54
A39: Février 2026 | B39: =SUMIFS(Détail!$E:$E,Détail!$D:$D,"ADOBE",Détail!$A:$A,">="&DATE(2026,2,1),Détail!$A:$A,"<"&EDATE(DATE(2026,2,1),1)) -> 0
A40: Mars 2026 | B40: =SUMIFS(Détail!$E:$E,Détail!$D:$D,"ADOBE",Détail!$A:$A,">="&DATE(2026,3,1),Détail!$A:$A,"<"&EDATE(DATE(2026,3,1),1)) -> -131.08
A41: Avril 2026 | B41: =SUMIFS(Détail!$E:$E,Détail!$D:$D,"ADOBE",Détail!$A:$A,">="&DATE(2026,4,1),Détail!$A:$A,"<"&EDATE(DATE(2026,4,1),1)) -> -65.54
A42: Mai 2026 | B42: =SUMIFS(Détail!$E:$E,Détail!$D:$D,"ADOBE",Détail!$A:$A,">="&DATE(2026,5,1),Détail!$A:$A,"<"&EDATE(DATE(2026,5,1),1)) -> -65.54
A43: Juin 2026 | B43: =SUMIFS(Détail!$E:$E,Détail!$D:$D,"ADOBE",Détail!$A:$A,">="&DATE(2026,6,1),Détail!$A:$A,"<"&EDATE(DATE(2026,6,1),1)) -> -65.54
A44: Juillet 2026 | B44: =SUMIFS(Détail!$E:$E,Détail!$D:$D,"ADOBE",Détail!$A:$A,">="&DATE(2026,7,1),Détail!$A:$A,"<"&EDATE(DATE(2026,7,1),1)) -> 0
A47: Shopify | C47: =SUMIF(Détail!$D:$D,"SHOPIFY",Détail!$E:$E) -> -239.02
A48: Mois | B48: Montant
A49: Janvier 2026 | B49: =SUMIFS(Détail!$E:$E,Détail!$D:$D,"SHOPIFY",Détail!$A:$A,">="&DATE(2026,1,1),Détail!$A:$A,"<"&EDATE(DATE(2026,1,1),1)) -> -33.92
...

Sheet Frais pro divers détail
A1: Frais professionnels divers — détail par prestataire (2026)
A3: Eaton Technologies Gmbh | C3: =SUMIF(Détail!$D:$D,"EATON TECHNOLOGIES GMBH",Détail!$E:$E) -> -3990
A4: Mois | B4: Montant
A5: Janvier 2026 | B5: =SUMIFS(Détail!$E:$E,Détail!$D:$D,"EATON TECHNOLOGIES GMBH",Détail!$A:$A,">="&DATE(2026,1,1),Détail!$A:$A,"<"&EDATE(DATE(2026,1,1),1)) -> -3990
A6: Février 2026 | B6: =SUMIFS(Détail!$E:$E,Détail!$D:$D,"EATON TECHNOLOGIES GMBH",Détail!$A:$A,">="&DATE(2026,2,1),Détail!$A:$A,"<"&EDATE(DATE(2026,2,1),1)) -> 0
A7: Mars 2026 | B7: =SUMIFS(Détail!$E:$E,Détail!$D:$D,"EATON TECHNOLOGIES GMBH",Détail!$A:$A,">="&DATE(2026,3,1),Détail!$A:$A,"<"&EDATE(DATE(2026,3,1),1)) -> 0
A8: Avril 2026 | B8: =SUMIFS(Détail!$E:$E,Détail!$D:$D,"EATON TECHNOLOGIES GMBH",Détail!$A:$A,">="&DATE(2026,4,1),Détail!$A:$A,"<"&EDATE(DATE(2026,4,1),1)) -> 0
A9: Mai 2026 | B9: =SUMIFS(Détail!$E:$E,Détail!$D:$D,"EATON TECHNOLOGIES GMBH",Détail!$A:$A,">="&DATE(2026,5,1),Détail!$A:$A,"<"&EDATE(DATE(2026,5,1),1)) -> 0
A10: Juin 2026 | B10: =SUMIFS(Détail!$E:$E,Détail!$D:$D,"EATON TECHNOLOGIES GMBH",Détail!$A:$A,">="&DATE(2026,6,1),Détail!$A:$A,"<"&EDATE(DATE(2026,6,1),1)) -> 0
A11: Juillet 2026 | B11: =SUMIFS(Détail!$E:$E,Détail!$D:$D,"EATON TECHNOLOGIES GMBH",Détail!$A:$A,">="&DATE(2026,7,1),Détail!$A:$A,"<"&EDATE(DATE(2026,7,1),1)) -> 0
A14: Sumup *Ultime | C14: =SUMIF(Détail!$D:$D,"SUMUP *ULTIME",Détail!$E:$E) -> -2529
A15: Mois | B15: Montant
A16: Janvier 2026 | B16: =SUMIFS(Détail!$E:$E,Détail!$D:$D,"SUMUP *ULTIME",Détail!$A:$A,">="&DATE(2026,1,1),Détail!$A:$A,"<"&EDATE(DATE(2026,1,1),1)) -> 0
A17: Février 2026 | B17: =SUMIFS(Détail!$E:$E,Détail!$D:$D,"SUMUP *ULTIME",Détail!$A:$A,">="&DATE(2026,2,1),Détail!$A:$A,"<"&EDATE(DATE(2026,2,1),1)) -> 0
A18: Mars 2026 | B18: =SUMIFS(Détail!$E:$E,Détail!$D:$D,"SUMUP *ULTIME",Détail!$A:$A,">="&DATE(2026,3,1),Détail!$A:$A,"<"&EDATE(DATE(2026,3,1),1)) -> 0
A19: Avril 2026 | B19: =SUMIFS(Détail!$E:$E,Détail!$D:$D,"SUMUP *ULTIME",Détail!$A:$A,">="&DATE(2026,4,1),Détail!$A:$A,"<"&EDATE(DATE(2026,4,1),1)) -> 0
A20: Mai 2026 | B20: =SUMIFS(Détail!$E:$E,Détail!$D:$D,"SUMUP *ULTIME",Détail!$A:$A,">="&DATE(2026,5,1),Détail!$A:$A,"<"&EDATE(DATE(2026,5,1),1)) -> -2529
A21: Juin 2026 | B21: =SUMIFS(Détail!$E:$E,Détail!$D:$D,"SUMUP *ULTIME",Détail!$A:$A,">="&DATE(2026,6,1),Détail!$A:$A,"<"&EDATE(DATE(2026,6,1),1)) -> 0
A22: Juillet 2026 | B22: =SUMIFS(Détail!$E:$E,Détail!$D:$D,"SUMUP *ULTIME",Détail!$A:$A,">="&DATE(2026,7,1),Détail!$A:$A,"<"&EDATE(DATE(2026,7,1),1)) -> 0
A25: Tuv Rheinland France Sas | C25: =SUMIF(Détail!$D:$D,"TUV RHEINLAND FRANCE SAS",Détail!$E:$E) -> -1947.77
A26: Mois | B26: Montant
A27: Janvier 2026 | B27: =SUMIFS(Détail!$E:$E,Détail!$D:$D,"TUV RHEINLAND FRANCE SAS",Détail!$A:$A,">="&DATE(2026,1,1),Détail!$A:$A,"<"&EDATE(DATE(2026,1,1),1)) -> -827.87
A28: Février 2026 | B28: =SUMIFS(Détail!$E:$E,Détail!$D:$D,"TUV RHEINLAND FRANCE SAS",Détail!$A:$A,">="&DATE(2026,2,1),Détail!$A:$A,"<"&EDATE(DATE(2026,2,1),1)) -> -1119.9
A29: Mars 2026 | B29: =SUMIFS(Détail!$E:$E,Détail!$D:$D,"TUV RHEINLAND FRANCE SAS",Détail!$A:$A,">="&DATE(2026,3,1),Détail!$A:$A,"<"&EDATE(DATE(2026,3,1),1)) -> 0
A30: Avril 2026 | B30: =SUMIFS(Détail!$E:$E,Détail!$D:$D,"TUV RHEINLAND FRANCE SAS",Détail!$A:$A,">="&DATE(2026,4,1),Détail!$A:$A,"<"&EDATE(DATE(2026,4,1),1)) -> 0
A31: Mai 2026 | B31: =SUMIFS(Détail!$E:$E,Détail!$D:$D,"TUV RHEINLAND FRANCE SAS",Détail!$A:$A,">="&DATE(2026,5,1),Détail!$A:$A,"<"&EDATE(DATE(2026,5,1),1)) -> 0
A32: Juin 2026 | B32: =SUMIFS(Détail!$E:$E,Détail!$D:$D,"TUV RHEINLAND FRANCE SAS",Détail!$A:$A,">="&DATE(2026,6,1),Détail!$A:$A,"<"&EDATE(DATE(2026,6,1),1)) -> 0
A33: Juillet 2026 | B33: =SUMIFS(Détail!$E:$E,Détail!$D:$D,"TUV RHEINLAND FRANCE SAS",Détail!$A:$A,">="&DATE(2026,7,1),Détail!$A:$A,"<"&EDATE(DATE(2026,7,1),1)) -> 0
A36: Gs1 France | C36: =SUMIF(Détail!$D:$D,"GS1 FRANCE",Détail!$E:$E) -> -757.2
A37: Mois | B37: Montant
A38: Janvier 2026 | B38: =SUMIFS(Détail!$E:$E,Détail!$D:$D,"GS1 FRANCE",Détail!$A:$A,">="&DATE(2026,1,1),Détail!$A:$A,"<"&EDATE(DATE(2026,1,1),1)) -> -757.2
A39: Février 2026 | B39: =SUMIFS(Détail!$E:$E,Détail!$D:$D,"GS1 FRANCE",Détail!$A:$A,">="&DATE(2026,2,1),Détail!$A:$A,"<"&EDATE(DATE(2026,2,1),1)) -> 0
A40: Mars 2026 | B40: =SUMIFS(Détail!$E:$E,Détail!$D:$D,"GS1 FRANCE",Détail!$A:$A,">="&DATE(2026,3,1),Détail!$A:$A,"<"&EDATE(DATE(2026,3,1),1)) -> 0
A41: Avril 2026 | B41: =SUMIFS(Détail!$E:$E,Détail!$D:$D,"GS1 FRANCE",Détail!$A:$A,">="&DATE(2026,4,1),Détail!$A:$A,"<"&EDATE(DATE(2026,4,1),1)) -> 0
A42: Mai 2026 | B42: =SUMIFS(Détail!$E:$E,Détail!$D:$D,"GS1 FRANCE",Détail!$A:$A,">="&DATE(2026,5,1),Détail!$A:$A,"<"&EDATE(DATE(2026,5,1),1)) -> 0
A43: Juin 2026 | B43: =SUMIFS(Détail!$E:$E,Détail!$D:$D,"GS1 FRANCE",Détail!$A:$A,">="&DATE(2026,6,1),Détail!$A:$A,"<"&EDATE(DATE(2026,6,1),1)) -> 0
A44: Juillet 2026 | B44: =SUMIFS(Détail!$E:$E,Détail!$D:$D,"GS1 FRANCE",Détail!$A:$A,">="&DATE(2026,7,1),Détail!$A:$A,"<"&EDATE(DATE(2026,7,1),1)) -> 0
A47: Ccip Dfce Gefi | C47: =SUMIF(Détail!$D:$D,"CCIP DFCE GEFI",Détail!$E:$E) -> -716
A48: Mois | B48: Montant
A49: Janvier 2026 | B49: =SUMIFS(Détail!$E:$E,Détail!$D:$D,"CCIP DFCE GEFI",Détail!$A:$A,">="&DATE(2026,1,1),Détail!$A:$A,"<"&EDATE(DATE(2026,1,1),1)) -> -99
...

Sheet Électricité Gaz détail
A1: Électricité / Gaz — détail mensuel (2026)
A3: Totalenergies Electricite Et Gaz France | C3: =SUMIF(Détail!$D:$D,"TOTALENERGIES ELECTRICITE ET GAZ FRANCE",Détail!$E:$E) -> -5559.55
A4: Mois | B4: Montant
A5: Janvier 2026 | B5: =SUMIFS(Détail!$E:$E,Détail!$D:$D,"TOTALENERGIES ELECTRICITE ET GAZ FRANCE",Détail!$A:$A,">="&DATE(2026,1,1),Détail!$A:$A,"<"&EDATE(DATE(2026,1,1),1)) -> -174.83
A6: Février 2026 | B6: =SUMIFS(Détail!$E:$E,Détail!$D:$D,"TOTALENERGIES ELECTRICITE ET GAZ FRANCE",Détail!$A:$A,">="&DATE(2026,2,1),Détail!$A:$A,"<"&EDATE(DATE(2026,2,1),1)) -> -1320.6
A7: Mars 2026 | B7: =SUMIFS(Détail!$E:$E,Détail!$D:$D,"TOTALENERGIES ELECTRICITE ET GAZ FRANCE",Détail!$A:$A,">="&DATE(2026,3,1),Détail!$A:$A,"<"&EDATE(DATE(2026,3,1),1)) -> -2009.4
A8: Avril 2026 | B8: =SUMIFS(Détail!$E:$E,Détail!$D:$D,"TOTALENERGIES ELECTRICITE ET GAZ FRANCE",Détail!$A:$A,">="&DATE(2026,4,1),Détail!$A:$A,"<"&EDATE(DATE(2026,4,1),1)) -> -160.99
A9: Mai 2026 | B9: =SUMIFS(Détail!$E:$E,Détail!$D:$D,"TOTALENERGIES ELECTRICITE ET GAZ FRANCE",Détail!$A:$A,">="&DATE(2026,5,1),Détail!$A:$A,"<"&EDATE(DATE(2026,5,1),1)) -> -921.54
A10: Juin 2026 | B10: =SUMIFS(Détail!$E:$E,Détail!$D:$D,"TOTALENERGIES ELECTRICITE ET GAZ FRANCE",Détail!$A:$A,">="&DATE(2026,6,1),Détail!$A:$A,"<"&EDATE(DATE(2026,6,1),1)) -> -525.49
A11: Juillet 2026 | B11: =SUMIFS(Détail!$E:$E,Détail!$D:$D,"TOTALENERGIES ELECTRICITE ET GAZ FRANCE",Détail!$A:$A,">="&DATE(2026,7,1),Détail!$A:$A,"<"&EDATE(DATE(2026,7,1),1)) -> -446.7

Sheet Comptabilité détail
A1: Comptabilité / expert-comptable — détail (2026)
A3: Cabinet Sas Daran | C3: =SUMIF(Détail!$D:$D,"CABINET SAS DARAN",Détail!$E:$E) -> -3024
A4: Mois | B4: Montant
A5: Janvier 2026 | B5: =SUMIFS(Détail!$E:$E,Détail!$D:$D,"CABINET SAS DARAN",Détail!$A:$A,">="&DATE(2026,1,1),Détail!$A:$A,"<"&EDATE(DATE(2026,1,1),1)) -> -504
A6: Février 2026 | B6: =SUMIFS(Détail!$E:$E,Détail!$D:$D,"CABINET SAS DARAN",Détail!$A:$A,">="&DATE(2026,2,1),Détail!$A:$A,"<"&EDATE(DATE(2026,2,1),1)) -> -504
A7: Mars 2026 | B7: =SUMIFS(Détail!$E:$E,Détail!$D:$D,"CABINET SAS DARAN",Détail!$A:$A,">="&DATE(2026,3,1),Détail!$A:$A,"<"&EDATE(DATE(2026,3,1),1)) -> -504
A8: Avril 2026 | B8: =SUMIFS(Détail!$E:$E,Détail!$D:$D,"CABINET SAS DARAN",Détail!$A:$A,">="&DATE(2026,4,1),Détail!$A:$A,"<"&EDATE(DATE(2026,4,1),1)) -> -504
A9: Mai 2026 | B9: =SUMIFS(Détail!$E:$E,Détail!$D:$D,"CABINET SAS DARAN",Détail!$A:$A,">="&DATE(2026,5,1),Détail!$A:$A,"<"&EDATE(DATE(2026,5,1),1)) -> -504
A10: Juin 2026 | B10: =SUMIFS(Détail!$E:$E,Détail!$D:$D,"CABINET SAS DARAN",Détail!$A:$A,">="&DATE(2026,6,1),Détail!$A:$A,"<"&EDATE(DATE(2026,6,1),1)) -> -504
A13: Ebp France-E B P Informatique | C13: =SUMIF(Détail!$D:$D,"EBP FRANCE-E B P INFORMATIQUE",Détail!$E:$E) -> -660
A14: Mois | B14: Montant
A15: Janvier 2026 | B15: =SUMIFS(Détail!$E:$E,Détail!$D:$D,"EBP FRANCE-E B P INFORMATIQUE",Détail!$A:$A,">="&DATE(2026,1,1),Détail!$A:$A,"<"&EDATE(DATE(2026,1,1),1)) -> 0
A16: Février 2026 | B16: =SUMIFS(Détail!$E:$E,Détail!$D:$D,"EBP FRANCE-E B P INFORMATIQUE",Détail!$A:$A,">="&DATE(2026,2,1),Détail!$A:$A,"<"&EDATE(DATE(2026,2,1),1)) -> -660
A17: Mars 2026 | B17: =SUMIFS(Détail!$E:$E,Détail!$D:$D,"EBP FRANCE-E B P INFORMATIQUE",Détail!$A:$A,">="&DATE(2026,3,1),Détail!$A:$A,"<"&EDATE(DATE(2026,3,1),1)) -> 0
A18: Avril 2026 | B18: =SUMIFS(Détail!$E:$E,Détail!$D:$D,"EBP FRANCE-E B P INFORMATIQUE",Détail!$A:$A,">="&DATE(2026,4,1),Détail!$A:$A,"<"&EDATE(DATE(2026,4,1),1)) -> 0
A19: Mai 2026 | B19: =SUMIFS(Détail!$E:$E,Détail!$D:$D,"EBP FRANCE-E B P INFORMATIQUE",Détail!$A:$A,">="&DATE(2026,5,1),Détail!$A:$A,"<"&EDATE(DATE(2026,5,1),1)) -> 0
A20: Juin 2026 | B20: =SUMIFS(Détail!$E:$E,Détail!$D:$D,"EBP FRANCE-E B P INFORMATIQUE",Détail!$A:$A,">="&DATE(2026,6,1),Détail!$A:$A,"<"&EDATE(DATE(2026,6,1),1)) -> 0

Sheet Frais bancaires détail
A1: Frais bancaires & financiers — détail par type de frais (2026)
A2: Groupé par type d'opération bancaire (pas de nom de prestataire sur ces lignes).
A4: Interets | C4: =SUMIF(Détail!$C:$C,"INTERETS",Détail!$E:$E) -> -1274.97
A5: Mois | B5: Montant
A6: Janvier 2026 | B6: =SUMIFS(Détail!$E:$E,Détail!$C:$C,"INTERETS",Détail!$A:$A,">="&DATE(2026,1,1),Détail!$A:$A,"<"&EDATE(DATE(2026,1,1),1)) -> -519.86
A7: Février 2026 | B7: =SUMIFS(Détail!$E:$E,Détail!$C:$C,"INTERETS",Détail!$A:$A,">="&DATE(2026,2,1),Détail!$A:$A,"<"&EDATE(DATE(2026,2,1),1)) -> 0
A8: Mars 2026 | B8: =SUMIFS(Détail!$E:$E,Détail!$C:$C,"INTERETS",Détail!$A:$A,">="&DATE(2026,3,1),Détail!$A:$A,"<"&EDATE(DATE(2026,3,1),1)) -> 0
A9: Avril 2026 | B9: =SUMIFS(Détail!$E:$E,Détail!$C:$C,"INTERETS",Détail!$A:$A,">="&DATE(2026,4,1),Détail!$A:$A,"<"&EDATE(DATE(2026,4,1),1)) -> -246.8
A10: Mai 2026 | B10: =SUMIFS(Détail!$E:$E,Détail!$C:$C,"INTERETS",Détail!$A:$A,">="&DATE(2026,5,1),Détail!$A:$A,"<"&EDATE(DATE(2026,5,1),1)) -> 0
A11: Juin 2026 | B11: =SUMIFS(Détail!$E:$E,Détail!$C:$C,"INTERETS",Détail!$A:$A,">="&DATE(2026,6,1),Détail!$A:$A,"<"&EDATE(DATE(2026,6,1),1)) -> 0
A12: Juillet 2026 | B12: =SUMIFS(Détail!$E:$E,Détail!$C:$C,"INTERETS",Détail!$A:$A,">="&DATE(2026,7,1),Détail!$A:$A,"<"&EDATE(DATE(2026,7,1),1)) -> -508.31
A15: Frais De Gestion | C15: =SUMIF(Détail!$C:$C,"FRAIS DE GESTION",Détail!$E:$E) -> -375.49
A16: Mois | B16: Montant
A17: Janvier 2026 | B17: =SUMIFS(Détail!$E:$E,Détail!$C:$C,"FRAIS DE GESTION",Détail!$A:$A,">="&DATE(2026,1,1),Détail!$A:$A,"<"&EDATE(DATE(2026,1,1),1)) -> 0
A18: Février 2026 | B18: =SUMIFS(Détail!$E:$E,Détail!$C:$C,"FRAIS DE GESTION",Détail!$A:$A,">="&DATE(2026,2,1),Détail!$A:$A,"<"&EDATE(DATE(2026,2,1),1)) -> 0
A19: Mars 2026 | B19: =SUMIFS(Détail!$E:$E,Détail!$C:$C,"FRAIS DE GESTION",Détail!$A:$A,">="&DATE(2026,3,1),Détail!$A:$A,"<"&EDATE(DATE(2026,3,1),1)) -> -375.49
A20: Avril 2026 | B20: =SUMIFS(Détail!$E:$E,Détail!$C:$C,"FRAIS DE GESTION",Détail!$A:$A,">="&DATE(2026,4,1),Détail!$A:$A,"<"&EDATE(DATE(2026,4,1),1)) -> 0
A21: Mai 2026 | B21: =SUMIFS(Détail!$E:$E,Détail!$C:$C,"FRAIS DE GESTION",Détail!$A:$A,">="&DATE(2026,5,1),Détail!$A:$A,"<"&EDATE(DATE(2026,5,1),1)) -> 0
A22: Juin 2026 | B22: =SUMIFS(Détail!$E:$E,Détail!$C:$C,"FRAIS DE GESTION",Détail!$A:$A,">="&DATE(2026,6,1),Détail!$A:$A,"<"&EDATE(DATE(2026,6,1),1)) -> 0
A23: Juillet 2026 | B23: =SUMIFS(Détail!$E:$E,Détail!$C:$C,"FRAIS DE GESTION",Détail!$A:$A,">="&DATE(2026,7,1),Détail!$A:$A,"<"&EDATE(DATE(2026,7,1),1)) -> 0
A26: Frais Banque Etrangere | C26: =SUMIF(Détail!$C:$C,"FRAIS BANQUE ETRANGERE",Détail!$E:$E) -> -374.4
A27: Mois | B27: Montant
A28: Janvier 2026 | B28: =SUMIFS(Détail!$E:$E,Détail!$C:$C,"FRAIS BANQUE ETRANGERE",Détail!$A:$A,">="&DATE(2026,1,1),Détail!$A:$A,"<"&EDATE(DATE(2026,1,1),1)) -> -57.6
A29: Février 2026 | B29: =SUMIFS(Détail!$E:$E,Détail!$C:$C,"FRAIS BANQUE ETRANGERE",Détail!$A:$A,">="&DATE(2026,2,1),Détail!$A:$A,"<"&EDATE(DATE(2026,2,1),1)) -> -57.6
A30: Mars 2026 | B30: =SUMIFS(Détail!$E:$E,Détail!$C:$C,"FRAIS BANQUE ETRANGERE",Détail!$A:$A,">="&DATE(2026,3,1),Détail!$A:$A,"<"&EDATE(DATE(2026,3,1),1)) -> -144
A31: Avril 2026 | B31: =SUMIFS(Détail!$E:$E,Détail!$C:$C,"FRAIS BANQUE ETRANGERE",Détail!$A:$A,">="&DATE(2026,4,1),Détail!$A:$A,"<"&EDATE(DATE(2026,4,1),1)) -> -57.6
A32: Mai 2026 | B32: =SUMIFS(Détail!$E:$E,Détail!$C:$C,"FRAIS BANQUE ETRANGERE",Détail!$A:$A,">="&DATE(2026,5,1),Détail!$A:$A,"<"&EDATE(DATE(2026,5,1),1)) -> -28.8
A33: Juin 2026 | B33: =SUMIFS(Détail!$E:$E,Détail!$C:$C,"FRAIS BANQUE ETRANGERE",Détail!$A:$A,">="&DATE(2026,6,1),Détail!$A:$A,"<"&EDATE(DATE(2026,6,1),1)) -> -28.8
A34: Juillet 2026 | B34: =SUMIFS(Détail!$E:$E,Détail!$C:$C,"FRAIS BANQUE ETRANGERE",Détail!$A:$A,">="&DATE(2026,7,1),Détail!$A:$A,"<"&EDATE(DATE(2026,7,1),1)) -> 0
A37: Cotisation | C37: =SUMIF(Détail!$C:$C,"COTISATION",Détail!$E:$E) -> -296.1
A38: Mois | B38: Montant
A39: Janvier 2026 | B39: =SUMIFS(Détail!$E:$E,Détail!$C:$C,"COTISATION",Détail!$A:$A,">="&DATE(2026,1,1),Détail!$A:$A,"<"&EDATE(DATE(2026,1,1),1)) -> -49.35
A40: Février 2026 | B40: =SUMIFS(Détail!$E:$E,Détail!$C:$C,"COTISATION",Détail!$A:$A,">="&DATE(2026,2,1),Détail!$A:$A,"<"&EDATE(DATE(2026,2,1),1)) -> -49.35
A41: Mars 2026 | B41: =SUMIFS(Détail!$E:$E,Détail!$C:$C,"COTISATION",Détail!$A:$A,">="&DATE(2026,3,1),Détail!$A:$A,"<"&EDATE(DATE(2026,3,1),1)) -> -49.35
A42: Avril 2026 | B42: =SUMIFS(Détail!$E:$E,Détail!$C:$C,"COTISATION",Détail!$A:$A,">="&DATE(2026,4,1),Détail!$A:$A,"<"&EDATE(DATE(2026,4,1),1)) -> -49.35
A43: Mai 2026 | B43: =SUMIFS(Détail!$E:$E,Détail!$C:$C,"COTISATION",Détail!$A:$A,">="&DATE(2026,5,1),Détail!$A:$A,"<"&EDATE(DATE(2026,5,1),1)) -> -49.35
A44: Juin 2026 | B44: =SUMIFS(Détail!$E:$E,Détail!$C:$C,"COTISATION",Détail!$A:$A,">="&DATE(2026,6,1),Détail!$A:$A,"<"&EDATE(DATE(2026,6,1),1)) -> -49.35
A45: Juillet 2026 | B45: =SUMIFS(Détail!$E:$E,Détail!$C:$C,"COTISATION",Détail!$A:$A,">="&DATE(2026,7,1),Détail!$A:$A,"<"&EDATE(DATE(2026,7,1),1)) -> 0
A48: Frais De Change | C48: =SUMIF(Détail!$C:$C,"FRAIS DE CHANGE",Détail!$E:$E) -> -230
A49: Mois | B49: Montant
...

Sheet Mutuelle détail
A1: Mutuelle / prévoyance salariés — détail par organisme (2026)
A3: Macif Idf Production-Macif | C3: =SUMIF(Détail!$D:$D,"MACIF IDF PRODUCTION-MACIF",Détail!$E:$E) -> -1403.98
A4: Mois | B4: Montant
A5: Janvier 2026 | B5: =SUMIFS(Détail!$E:$E,Détail!$D:$D,"MACIF IDF PRODUCTION-MACIF",Détail!$A:$A,">="&DATE(2026,1,1),Détail!$A:$A,"<"&EDATE(DATE(2026,1,1),1)) -> -130.67
A6: Février 2026 | B6: =SUMIFS(Détail!$E:$E,Détail!$D:$D,"MACIF IDF PRODUCTION-MACIF",Détail!$A:$A,">="&DATE(2026,2,1),Détail!$A:$A,"<"&EDATE(DATE(2026,2,1),1)) -> -130.67
A7: Mars 2026 | B7: =SUMIFS(Détail!$E:$E,Détail!$D:$D,"MACIF IDF PRODUCTION-MACIF",Détail!$A:$A,">="&DATE(2026,3,1),Détail!$A:$A,"<"&EDATE(DATE(2026,3,1),1)) -> -130.67
A8: Avril 2026 | B8: =SUMIFS(Détail!$E:$E,Détail!$D:$D,"MACIF IDF PRODUCTION-MACIF",Détail!$A:$A,">="&DATE(2026,4,1),Détail!$A:$A,"<"&EDATE(DATE(2026,4,1),1)) -> -252.91
A9: Mai 2026 | B9: =SUMIFS(Détail!$E:$E,Détail!$D:$D,"MACIF IDF PRODUCTION-MACIF",Détail!$A:$A,">="&DATE(2026,5,1),Détail!$A:$A,"<"&EDATE(DATE(2026,5,1),1)) -> -253.02
A10: Juin 2026 | B10: =SUMIFS(Détail!$E:$E,Détail!$D:$D,"MACIF IDF PRODUCTION-MACIF",Détail!$A:$A,">="&DATE(2026,6,1),Détail!$A:$A,"<"&EDATE(DATE(2026,6,1),1)) -> -253.02
A11: Juillet 2026 | B11: =SUMIFS(Détail!$E:$E,Détail!$D:$D,"MACIF IDF PRODUCTION-MACIF",Détail!$A:$A,">="&DATE(2026,7,1),Détail!$A:$A,"<"&EDATE(DATE(2026,7,1),1)) -> -253.02
A14: Msp Cot Sante Des Entreprises-Macif Sante Prevoyance | C14: =SUMIF(Détail!$D:$D,"MSP COT SANTE DES ENTREPRISES-MACIF SANTE PREVOYANCE",Détail!$E:$E) -> -862
A15: Mois | B15: Montant
A16: Janvier 2026 | B16: =SUMIFS(Détail!$E:$E,Détail!$D:$D,"MSP COT SANTE DES ENTREPRISES-MACIF SANTE PREVOYANCE",Détail!$A:$A,">="&DATE(2026,1,1),Détail!$A:$A,"<"&EDATE(DATE(2026,1,1),1)) -> 0
