Workbook

Sheet Résumé
A1: Récapitulatif des charges — Compte BRED EJ 2025
A2: Période couverte : 02/01/2025 au 31/12/2025 — 1396 opérations (année complète)
A4: Total encaissements | B4: =SUMIF(Détail!F:F,"Encaissement*",Détail!E:E) -> 1518357.5
A5: Total charges (hors encaissements, hors chèques/non classé à vérifier) | B5: =SUMIFS(Détail!E:E,Détail!F:F,"<>Encaissement (hors périmètre charges)",Détail!F:F,"<>Paiement par chèque (à vérifier)",Détail!F:F,"<>Non classé / à vérifier",Détail!F:F,"<>Saisie administrative") -> -1498281.5
A6: Solde net (encaissements + charges + à vérifier) | B6: =SUMIF(Détail!F:F,"<>",Détail!E:E) -> 20075.96
A8: Détail par catégorie de charge
A9: Catégorie | B9: Nb opérations | C9: Montant total (€) | D9: % du total charges
A10: Fournisseurs matières premières & emballage (France) | B10: =COUNTIF(Détail!F:F,A10) -> 40 | C10: =SUMIF(Détail!F:F,A10,Détail!E:E) -> -509820.77 | D10: =C10/$B$5 -> 0.34027035
A11: Usine de conditionnement et macération | B11: =COUNTIF(Détail!F:F,A11) -> 26 | C11: =SUMIF(Détail!F:F,A11,Détail!E:E) -> -317174.39 | D11: =C11/$B$5 -> 0.21169212
A12: Fournisseurs internationaux (Chine/Import) | B12: =COUNTIF(Détail!F:F,A12) -> 24 | C12: =SUMIF(Détail!F:F,A12,Détail!E:E) -> -297383.41 | D12: =C12/$B$5 -> 0.198483
A13: Transport / livraison (colis, courrier) | B13: =COUNTIF(Détail!F:F,A13) -> 52 | C13: =SUMIF(Détail!F:F,A13,Détail!E:E) -> -81550.38 | D13: =C13/$B$5 -> 0.054429277
A14: Salaires (salariés) | B14: =COUNTIF(Détail!F:F,A14) -> 47 | C14: =SUMIF(Détail!F:F,A14,Détail!E:E) -> -74079.75 | D14: =C14/$B$5 -> 0.049443145
A15: Charges sociales & cotisations | B15: =COUNTIF(Détail!F:F,A15) -> 51 | C15: =SUMIF(Détail!F:F,A15,Détail!E:E) -> -44915.46 | D15: =C15/$B$5 -> 0.029977984
A16: Rémunération gérant | B16: =COUNTIF(Détail!F:F,A16) -> 13 | C16: =SUMIF(Détail!F:F,A16,Détail!E:E) -> -48500 | D16: =C16/$B$5 -> 0.032370419
A17: Frais professionnels divers | B17: =COUNTIF(Détail!F:F,A17) -> 88 | C17: =SUMIF(Détail!F:F,A17,Détail!E:E) -> -29712.26 | D17: =C17/$B$5 -> 0.019830893
A18: Voyages / déplacements | B18: =COUNTIF(Détail!F:F,A18) -> 67 | C18: =SUMIF(Détail!F:F,A18,Détail!E:E) -> -20990.53 | D18: =C18/$B$5 -> 0.014009737
A19: Carburant, péages, parking, leasing | B19: =COUNTIF(Détail!F:F,A19) -> 308 | C19: =SUMIF(Détail!F:F,A19,Détail!E:E) -> -20090.51 | D19: =C19/$B$5 -> 0.013409035
A20: Téléphone / Internet / Logiciels | B20: =COUNTIF(Détail!F:F,A20) -> 112 | C20: =SUMIF(Détail!F:F,A20,Détail!E:E) -> -11539.97 | D20: =C20/$B$5 -> 0.0077021373
A21: Commission vendeur | B21: =COUNTIF(Détail!F:F,A21) -> 1 | C21: =SUMIF(Détail!F:F,A21,Détail!E:E) -> -9359.1 | D21: =C21/$B$5 -> 0.0062465564
... A32: Prêt professionnel | B32: =COUNTIF(Détail!F:F,A32) -> 8 | C32: =SUMIF(Détail!F:F,A32,Détail!E:E) -> -230.88 | D32: =C32/$B$5 -> 0.00015409654
A33: TOTAL | B33: =SUM(B10:B32) -> 1307 | C33: =SUM(C10:C32) -> -1498281.5
A35: 🟠 En orange : catégories pas encore validées avec Mounir (à vérifier)

Sheet Revenus
A1: Revenus — Compte BRED EJ 2025
A2: Période couverte : 08/01/2025 au 30/12/2025 — 89 encaissements
A4: Total encaissements | B4: =SUM('Détail Revenus'!E:E) -> 1518357.5
A6: Détail par source de revenu
A7: Source | B7: Nb opérations | C7: Montant total (€) | D7: % du total
A8: NB Evolution FZCO (factures NB...) | B8: =COUNTIF('Détail Revenus'!F:F,A8) -> 24 | C8: =SUMIF('Détail Revenus'!F:F,A8,'Détail Revenus'!E:E) -> 741899.27 | D8: =C8/$B$4 -> 0.48861963
A9: Usine Algérie (Jade Création — sans marge) | B9: =COUNTIF('Détail Revenus'!F:F,A9) -> 5 | C9: =SUMIF('Détail Revenus'!F:F,A9,'Détail Revenus'!E:E) -> 350326.07 | D9: =C9/$B$4 -> 0.230727
A10: Encaissements non identifiés | B10: =COUNTIF('Détail Revenus'!F:F,A10) -> 0 | C10: =SUMIF('Détail Revenus'!F:F,A10,'Détail Revenus'!E:E) -> 0 | D10: =C10/$B$4 -> 0
A11: Arzum Group Mmc | B11: =COUNTIF('Détail Revenus'!F:F,A11) -> 6 | C11: =SUMIF('Détail Revenus'!F:F,A11,'Détail Revenus'!E:E) -> 88829 | D11: =C11/$B$4 -> 0.058503351
A12: Al Muftah | B12: =COUNTIF('Détail Revenus'!F:F,A12) -> 4 | C12: =SUMIF('Détail Revenus'!F:F,A12,'Détail Revenus'!E:E) -> 67324.2 | D12: =C12/$B$4 -> 0.044340151
A13: Al Fawanis Company | B13: =COUNTIF('Détail Revenus'!F:F,A13) -> 2 | C13: =SUMIF('Détail Revenus'!F:F,A13,'Détail Revenus'!E:E) -> 45195.4 | D13: =C13/$B$4 -> 0.029765981
A14: Chaloub Trading | B14: =COUNTIF('Détail Revenus'!F:F,A14) -> 4 | C14: =SUMIF('Détail Revenus'!F:F,A14,'Détail Revenus'!E:E) -> 21372 | D14: =C14/$B$4 -> 0.014075737
A15: Dv Menswear | B15: =COUNTIF('Détail Revenus'!F:F,A15) -> 3 | C15: =SUMIF('Détail Revenus'!F:F,A15,'Détail Revenus'!E:E) -> 14076.41 | D15: =C15/$B$4 -> 0.0092708141
A16: Khiyat Cospara | B16: =COUNTIF('Détail Revenus'!F:F,A16) -> 1 | C16: =SUMIF('Détail Revenus'!F:F,A16,'Détail Revenus'!E:E) -> 6460.8 | D16: =C16/$B$4 -> 0.0042551244
A17: Cielomed | B17: =COUNTIF('Détail Revenus'!F:F,A17) -> 1 | C17: =SUMIF('Détail Revenus'!F:F,A17,'Détail Revenus'!E:E) -> 6254 | D17: =C17/$B$4 -> 0.0041189246
A18: Passion Parfum | B18: =COUNTIF('Détail Revenus'!F:F,A18) -> 2 | C18: =SUMIF('Détail Revenus'!F:F,A18,'Détail Revenus'!E:E) -> 6224 | D18: =C18/$B$4 -> 0.0040991664
A19: Davidson Distributors Llc | B19: =COUNTIF('Détail Revenus'!F:F,A19) -> 2 | C19: =SUMIF('Détail Revenus'!F:F,A19,'Détail Revenus'!E:E) -> 3943 | D19: =C19/$B$4 -> 0.0025968852
... A28: Créance 2024 encaissée en 2025 (Usine Algérie) | B28: =COUNTIF('Détail Revenus'!F:F,A28) -> 1 | C28: =SUMIF('Détail Revenus'!F:F,A28,'Détail Revenus'!E:E) -> 95044 | D28: =C28/$B$4 -> 0.06259659
A29: TOTAL | B29: =SUM(B8:B28) -> 89 | C29: =SUM(C8:C28) -> 1518357.5
A31: 🟠 En orange : sources pas encore confirmées avec Mounir

Sheet Revenus détail
A1: Revenus — détail par source et par mois (2025)
A3: NB Evolution FZCO (factures NB...) | C3: =SUMIF('Détail Revenus'!$F:$F,"NB Evolution FZCO (factures NB...)",'Détail Revenus'!$E:$E) -> 741899.27
A4: Mois | B4: Montant
A5: Janvier 2025 | B5: =SUMIFS('Détail Revenus'!$E:$E,'Détail Revenus'!$F:$F,"NB Evolution FZCO (factures NB...)",'Détail Revenus'!$A:$A,">="&DATE(2025,1,1),'Détail Revenus'!$A:$A,"<"&EDATE(DATE(2025,1,1),1)) -> 44118.93
A6: Février 2025 | B6: =SUMIFS('Détail Revenus'!$E:$E,'Détail Revenus'!$F:$F,"NB Evolution FZCO (factures NB...)",'Détail Revenus'!$A:$A,">="&DATE(2025,2,1),'Détail Revenus'!$A:$A,"<"&EDATE(DATE(2025,2,1),1)) -> 35000
A7: Mars 2025 | B7: =SUMIFS('Détail Revenus'!$E:$E,'Détail Revenus'!$F:$F,"NB Evolution FZCO (factures NB...)",'Détail Revenus'!$A:$A,">="&DATE(2025,3,1),'Détail Revenus'!$A:$A,"<"&EDATE(DATE(2025,3,1),1)) -> 60000
A8: Avril 2025 | B8: =SUMIFS('Détail Revenus'!$E:$E,'Détail Revenus'!$F:$F,"NB Evolution FZCO (factures NB...)",'Détail Revenus'!$A:$A,">="&DATE(2025,4,1),'Détail Revenus'!$A:$A,"<"&EDATE(DATE(2025,4,1),1)) -> 88852
A9: Mai 2025 | B9: =SUMIFS('Détail Revenus'!$E:$E,'Détail Revenus'!$F:$F,"NB Evolution FZCO (factures NB...)",'Détail Revenus'!$A:$A,">="&DATE(2025,5,1),'Détail Revenus'!$A:$A,"<"&EDATE(DATE(2025,5,1),1)) -> 101000
A10: Juin 2025 | B10: =SUMIFS('Détail Revenus'!$E:$E,'Détail Revenus'!$F:$F,"NB Evolution FZCO (factures NB...)",'Détail Revenus'!$A:$A,">="&DATE(2025,6,1),'Détail Revenus'!$A:$A,"<"&EDATE(DATE(2025,6,1),1)) -> 89169.04
A11: Juillet 2025 | B11: =SUMIFS('Détail Revenus'!$E:$E,'Détail Revenus'!$F:$F,"NB Evolution FZCO (factures NB...)",'Détail Revenus'!$A:$A,">="&DATE(2025,7,1),'Détail Revenus'!$A:$A,"<"&EDATE(DATE(2025,7,1),1)) -> 98080
A12: Août 2025 | B12: =SUMIFS('Détail Revenus'!$E:$E,'Détail Revenus'!$F:$F,"NB Evolution FZCO (factures NB...)",'Détail Revenus'!$A:$A,">="&DATE(2025,8,1),'Détail Revenus'!$A:$A,"<"&EDATE(DATE(2025,8,1),1)) -> 0
A13: Septembre 2025 | B13: =SUMIFS('Détail Revenus'!$E:$E,'Détail Revenus'!$F:$F,"NB Evolution FZCO (factures NB...)",'Détail Revenus'!$A:$A,">="&DATE(2025,9,1),'Détail Revenus'!$A:$A,"<"&EDATE(DATE(2025,9,1),1)) -> 0
A14: Octobre 2025 | B14: =SUMIFS('Détail Revenus'!$E:$E,'Détail Revenus'!$F:$F,"NB Evolution FZCO (factures NB...)",'Détail Revenus'!$A:$A,">="&DATE(2025,10,1),'Détail Revenus'!$A:$A,"<"&EDATE(DATE(2025,10,1),1)) -> 76279.3
A15: Novembre 2025 | B15: =SUMIFS('Détail Revenus'!$E:$E,'Détail Revenus'!$F:$F,"NB Evolution FZCO (factures NB...)",'Détail Revenus'!$A:$A,">="&DATE(2025,11,1),'Détail Revenus'!$A:$A,"<"&EDATE(DATE(2025,11,1),1)) -> 0
A16: Décembre 2025 | B16: =SUMIFS('Détail Revenus'!$E:$E,'Détail Revenus'!$F:$F,"NB Evolution FZCO (factures NB...)",'Détail Revenus'!$A:$A,">="&DATE(2025,12,1),'Détail Revenus'!$A:$A,"<"&EDATE(DATE(2025,12,1),1)) -> 149400
A19: Usine Algérie (Jade Création — sans marge) | C19: =SUMIF('Détail Revenus'!$F:$F,"Usine Algérie (Jade Création — sans marge)",'Détail Revenus'!$E:$E) -> 350326.07
A20: Noms bancaires d'origine : | B20: SARL JADE CREATION SALGDZALXXX, SARL JADE CREATION SALGDZALXXX SALGDZALXXX
A21: Mois | B21: Montant
A22: Janvier 2025 | B22: =SUMIFS('Détail Revenus'!$E:$E,'Détail Revenus'!$F:$F,"Usine Algérie (Jade Création — sans marge)",'Détail Revenus'!$A:$A,">="&DATE(2025,1,1),'Détail Revenus'!$A:$A,"<"&EDATE(DATE(2025,1,1),1)) -> 0
A23: Février 2025 | B23: =SUMIFS('Détail Revenus'!$E:$E,'Détail Revenus'!$F:$F,"Usine Algérie (Jade Création — sans marge)",'Détail Revenus'!$A:$A,">="&DATE(2025,2,1),'Détail Revenus'!$A:$A,"<"&EDATE(DATE(2025,2,1),1)) -> 0
A24: Mars 2025 | B24: =SUMIFS('Détail Revenus'!$E:$E,'Détail Revenus'!$F:$F,"Usine Algérie (Jade Création — sans marge)",'Détail Revenus'!$A:$A,">="&DATE(2025,3,1),'Détail Revenus'!$A:$A,"<"&EDATE(DATE(2025,3,1),1)) -> 0
A25: Avril 2025 | B25: =SUMIFS('Détail Revenus'!$E:$E,'Détail Revenus'!$F:$F,"Usine Algérie (Jade Création — sans marge)",'Détail Revenus'!$A:$A,">="&DATE(2025,4,1),'Détail Revenus'!$A:$A,"<"&EDATE(DATE(2025,4,1),1)) -> 27129.32
A26: Mai 2025 | B26: =SUMIFS('Détail Revenus'!$E:$E,'Détail Revenus'!$F:$F,"Usine Algérie (Jade Création — sans marge)",'Détail Revenus'!$A:$A,">="&DATE(2025,5,1),'Détail Revenus'!$A:$A,"<"&EDATE(DATE(2025,5,1),1)) -> 0
A27: Juin 2025 | B27: =SUMIFS('Détail Revenus'!$E:$E,'Détail Revenus'!$F:$F,"Usine Algérie (Jade Création — sans marge)",'Détail Revenus'!$A:$A,">="&DATE(2025,6,1),'Détail Revenus'!$A:$A,"<"&EDATE(DATE(2025,6,1),1)) -> 0
A28: Juillet 2025 | B28: =SUMIFS('Détail Revenus'!$E:$E,'Détail Revenus'!$F:$F,"Usine Algérie (Jade Création — sans marge)",'Détail Revenus'!$A:$A,">="&DATE(2025,7,1),'Détail Revenus'!$A:$A,"<"&EDATE(DATE(2025,7,1),1)) -> 57046
A29: Août 2025 | B29: =SUMIFS('Détail Revenus'!$E:$E,'Détail Revenus'!$F:$F,"Usine Algérie (Jade Création — sans marge)",'Détail Revenus'!$A:$A,">="&DATE(2025,8,1),'Détail Revenus'!$A:$A,"<"&EDATE(DATE(2025,8,1),1)) -> 120449.68
A30: Septembre 2025 | B30: =SUMIFS('Détail Revenus'!$E:$E,'Détail Revenus'!$F:$F,"Usine Algérie (Jade Création — sans marge)",'Détail Revenus'!$A:$A,">="&DATE(2025,9,1),'Détail Revenus'!$A:$A,"<"&EDATE(DATE(2025,9,1),1)) -> 0
A31: Octobre 2025 | B31: =SUMIFS('Détail Revenus'!$E:$E,'Détail Revenus'!$F:$F,"Usine Algérie (Jade Création — sans marge)",'Détail Revenus'!$A:$A,">="&DATE(2025,10,1),'Détail Revenus'!$A:$A,"<"&EDATE(DATE(2025,10,1),1)) -> 132807.4
A32: Novembre 2025 | B32: =SUMIFS('Détail Revenus'!$E:$E,'Détail Revenus'!$F:$F,"Usine Algérie (Jade Création — sans marge)",'Détail Revenus'!$A:$A,">="&DATE(2025,11,1),'Détail Revenus'!$A:$A,"<"&EDATE(DATE(2025,11,1),1)) -> 12893.67
A33: Décembre 2025 | B33: =SUMIFS('Détail Revenus'!$E:$E,'Détail Revenus'!$F:$F,"Usine Algérie (Jade Création — sans marge)",'Détail Revenus'!$A:$A,">="&DATE(2025,12,1),'Détail Revenus'!$A:$A,"<"&EDATE(DATE(2025,12,1),1)) -> 0
A36: Encaissements non identifiés | C36: =SUMIF('Détail Revenus'!$F:$F,"Encaissements non identifiés",'Détail Revenus'!$E:$E) -> 0
A37: Noms bancaires d'origine : | B37: SIE MARNE ET BOIS, (sans libellé), PERFUMEPARADISE APS, ASOL ALDEAR CO, AKKONA SPOLKA Z OGRANICZONA ODPOWIEDZIALNOSCIA, SMART UK BRANDS LTD 167-169 5TH FLO, RAS TRANSPORT
A38: Mois | B38: Montant
A39: Janvier 2025 | B39: =SUMIFS('Détail Revenus'!$E:$E,'Détail Revenus'!$F:$F,"Encaissements non identifiés",'Détail Revenus'!$A:$A,">="&DATE(2025,1,1),'Détail Revenus'!$A:$A,"<"&EDATE(DATE(2025,1,1),1)) -> 0
A40: Février 2025 | B40: =SUMIFS('Détail Revenus'!$E:$E,'Détail Revenus'!$F:$F,"Encaissements non identifiés",'Détail Revenus'!$A:$A,">="&DATE(2025,2,1),'Détail Revenus'!$A:$A,"<"&EDATE(DATE(2025,2,1),1)) -> 0
A41: Mars 2025 | B41: =SUMIFS('Détail Revenus'!$E:$E,'Détail Revenus'!$F:$F,"Encaissements non identifiés",'Détail Revenus'!$A:$A,">="&DATE(2025,3,1),'Détail Revenus'!$A:$A,"<"&EDATE(DATE(2025,3,1),1)) -> 0
A42: Avril 2025 | B42: =SUMIFS('Détail Revenus'!$E:$E,'Détail Revenus'!$F:$F,"Encaissements non identifiés",'Détail Revenus'!$A:$A,">="&DATE(2025,4,1),'Détail Revenus'!$A:$A,"<"&EDATE(DATE(2025,4,1),1)) -> 0
A43: Mai 2025 | B43: =SUMIFS('Détail Revenus'!$E:$E,'Détail Revenus'!$F:$F,"Encaissements non identifiés",'Détail Revenus'!$A:$A,">="&DATE(2025,5,1),'Détail Revenus'!$A:$A,"<"&EDATE(DATE(2025,5,1),1)) -> 0
A44: Juin 2025 | B44: =SUMIFS('Détail Revenus'!$E:$E,'Détail Revenus'!$F:$F,"Encaissements non identifiés",'Détail Revenus'!$A:$A,">="&DATE(2025,6,1),'Détail Revenus'!$A:$A,"<"&EDATE(DATE(2025,6,1),1)) -> 0
A45: Juillet 2025 | B45: =SUMIFS('Détail Revenus'!$E:$E,'Détail Revenus'!$F:$F,"Encaissements non identifiés",'Détail Revenus'!$A:$A,">="&DATE(2025,7,1),'Détail Revenus'!$A:$A,"<"&EDATE(DATE(2025,7,1),1)) -> 0
...

Sheet Salaires détail
A1: Salaires & rémunération gérant — détail par personne (2025)
A3: Mr Boudjada Said (Gérant — rémunération libre) | C3: =SUMIF(Détail!$D:$D,"MR BOUDJADA SAID",Détail!$E:$E) -> -48500
A4: Mois | B4: Montant
A5: Janvier 2025 | B5: =SUMIFS(Détail!$E:$E,Détail!$D:$D,"MR BOUDJADA SAID",Détail!$A:$A,">="&DATE(2025,1,1),Détail!$A:$A,"<"&EDATE(DATE(2025,1,1),1)) -> -5000
A6: Février 2025 | B6: =SUMIFS(Détail!$E:$E,Détail!$D:$D,"MR BOUDJADA SAID",Détail!$A:$A,">="&DATE(2025,2,1),Détail!$A:$A,"<"&EDATE(DATE(2025,2,1),1)) -> -4000
A7: Mars 2025 | B7: =SUMIFS(Détail!$E:$E,Détail!$D:$D,"MR BOUDJADA SAID",Détail!$A:$A,">="&DATE(2025,3,1),Détail!$A:$A,"<"&EDATE(DATE(2025,3,1),1)) -> -6000
A8: Avril 2025 | B8: =SUMIFS(Détail!$E:$E,Détail!$D:$D,"MR BOUDJADA SAID",Détail!$A:$A,">="&DATE(2025,4,1),Détail!$A:$A,"<"&EDATE(DATE(2025,4,1),1)) -> -6000
A9: Mai 2025 | B9: =SUMIFS(Détail!$E:$E,Détail!$D:$D,"MR BOUDJADA SAID",Détail!$A:$A,">="&DATE(2025,5,1),Détail!$A:$A,"<"&EDATE(DATE(2025,5,1),1)) -> 0
A10: Juin 2025 | B10: =SUMIFS(Détail!$E:$E,Détail!$D:$D,"MR BOUDJADA SAID",Détail!$A:$A,">="&DATE(2025,6,1),Détail!$A:$A,"<"&EDATE(DATE(2025,6,1),1)) -> 0
A11: Juillet 2025 | B11: =SUMIFS(Détail!$E:$E,Détail!$D:$D,"MR BOUDJADA SAID",Détail!$A:$A,">="&DATE(2025,7,1),Détail!$A:$A,"<"&EDATE(DATE(2025,7,1),1)) -> -8500
A12: Août 2025 | B12: =SUMIFS(Détail!$E:$E,Détail!$D:$D,"MR BOUDJADA SAID",Détail!$A:$A,">="&DATE(2025,8,1),Détail!$A:$A,"<"&EDATE(DATE(2025,8,1),1)) -> -5000
A13: Septembre 2025 | B13: =SUMIFS(Détail!$E:$E,Détail!$D:$D,"MR BOUDJADA SAID",Détail!$A:$A,">="&DATE(2025,9,1),Détail!$A:$A,"<"&EDATE(DATE(2025,9,1),1)) -> -6000
A14: Octobre 2025 | B14: =SUMIFS(Détail!$E:$E,Détail!$D:$D,"MR BOUDJADA SAID",Détail!$A:$A,">="&DATE(2025,10,1),Détail!$A:$A,"<"&EDATE(DATE(2025,10,1),1)) -> -5000
A15: Novembre 2025 | B15: =SUMIFS(Détail!$E:$E,Détail!$D:$D,"MR BOUDJADA SAID",Détail!$A:$A,">="&DATE(2025,11,1),Détail!$A:$A,"<"&EDATE(DATE(2025,11,1),1)) -> -3000
A16: Décembre 2025 | B16: =SUMIFS(Détail!$E:$E,Détail!$D:$D,"MR BOUDJADA SAID",Détail!$A:$A,">="&DATE(2025,12,1),Détail!$A:$A,"<"&EDATE(DATE(2025,12,1),1)) -> 0
A19: Mr Boudaja Nassim (Salarié) | C19: =SUMIF(Détail!$D:$D,"MR BOUDAJA NASSIM",Détail!$E:$E) -> -29984.91
A20: Mois | B20: Montant
A21: Janvier 2025 | B21: =SUMIFS(Détail!$E:$E,Détail!$D:$D,"MR BOUDAJA NASSIM",Détail!$A:$A,">="&DATE(2025,1,1),Détail!$A:$A,"<"&EDATE(DATE(2025,1,1),1)) -> 0
A22: Février 2025 | B22: =SUMIFS(Détail!$E:$E,Détail!$D:$D,"MR BOUDAJA NASSIM",Détail!$A:$A,">="&DATE(2025,2,1),Détail!$A:$A,"<"&EDATE(DATE(2025,2,1),1)) -> -4720.82
A23: Mars 2025 | B23: =SUMIFS(Détail!$E:$E,Détail!$D:$D,"MR BOUDAJA NASSIM",Détail!$A:$A,">="&DATE(2025,3,1),Détail!$A:$A,"<"&EDATE(DATE(2025,3,1),1)) -> -1984.55
A24: Avril 2025 | B24: =SUMIFS(Détail!$E:$E,Détail!$D:$D,"MR BOUDAJA NASSIM",Détail!$A:$A,">="&DATE(2025,4,1),Détail!$A:$A,"<"&EDATE(DATE(2025,4,1),1)) -> -1984.55
A25: Mai 2025 | B25: =SUMIFS(Détail!$E:$E,Détail!$D:$D,"MR BOUDAJA NASSIM",Détail!$A:$A,">="&DATE(2025,5,1),Détail!$A:$A,"<"&EDATE(DATE(2025,5,1),1)) -> -1984.55
A26: Juin 2025 | B26: =SUMIFS(Détail!$E:$E,Détail!$D:$D,"MR BOUDAJA NASSIM",Détail!$A:$A,">="&DATE(2025,6,1),Détail!$A:$A,"<"&EDATE(DATE(2025,6,1),1)) -> -2484.55
A27: Juillet 2025 | B27: =SUMIFS(Détail!$E:$E,Détail!$D:$D,"MR BOUDAJA NASSIM",Détail!$A:$A,">="&DATE(2025,7,1),Détail!$A:$A,"<"&EDATE(DATE(2025,7,1),1)) -> -2466.15
A28: Août 2025 | B28: =SUMIFS(Détail!$E:$E,Détail!$D:$D,"MR BOUDAJA NASSIM",Détail!$A:$A,">="&DATE(2025,8,1),Détail!$A:$A,"<"&EDATE(DATE(2025,8,1),1)) -> -2481.8
A29: Septembre 2025 | B29: =SUMIFS(Détail!$E:$E,Détail!$D:$D,"MR BOUDAJA NASSIM",Détail!$A:$A,">="&DATE(2025,9,1),Détail!$A:$A,"<"&EDATE(DATE(2025,9,1),1)) -> -2481.8
A30: Octobre 2025 | B30: =SUMIFS(Détail!$E:$E,Détail!$D:$D,"MR BOUDAJA NASSIM",Détail!$A:$A,">="&DATE(2025,10,1),Détail!$A:$A,"<"&EDATE(DATE(2025,10,1),1)) -> -2465.38
A31: Novembre 2025 | B31: =SUMIFS(Détail!$E:$E,Détail!$D:$D,"MR BOUDAJA NASSIM",Détail!$A:$A,">="&DATE(2025,11,1),Détail!$A:$A,"<"&EDATE(DATE(2025,11,1),1)) -> -2465.38
A32: Décembre 2025 | B32: =SUMIFS(Détail!$E:$E,Détail!$D:$D,"MR BOUDAJA NASSIM",Détail!$A:$A,">="&DATE(2025,12,1),Détail!$A:$A,"<"&EDATE(DATE(2025,12,1),1)) -> -4465.38
A35: Mr Boudjada Mounir (Salarié) | C35: =SUMIF(Détail!$D:$D,"MR BOUDJADA MOUNIR",Détail!$E:$E) -> -20959.29
A36: Mois | B36: Montant
A37: Janvier 2025 | B37: =SUMIFS(Détail!$E:$E,Détail!$D:$D,"MR BOUDJADA MOUNIR",Détail!$A:$A,">="&DATE(2025,1,1),Détail!$A:$A,"<"&EDATE(DATE(2025,1,1),1)) -> -1449.27
A38: Février 2025 | B38: =SUMIFS(Détail!$E:$E,Détail!$D:$D,"MR BOUDJADA MOUNIR",Détail!$A:$A,">="&DATE(2025,2,1),Détail!$A:$A,"<"&EDATE(DATE(2025,2,1),1)) -> -1449.27
A39: Mars 2025 | B39: =SUMIFS(Détail!$E:$E,Détail!$D:$D,"MR BOUDJADA MOUNIR",Détail!$A:$A,">="&DATE(2025,3,1),Détail!$A:$A,"<"&EDATE(DATE(2025,3,1),1)) -> -1449.27
A40: Avril 2025 | B40: =SUMIFS(Détail!$E:$E,Détail!$D:$D,"MR BOUDJADA MOUNIR",Détail!$A:$A,">="&DATE(2025,4,1),Détail!$A:$A,"<"&EDATE(DATE(2025,4,1),1)) -> -1473.11
A41: Mai 2025 | B41: =SUMIFS(Détail!$E:$E,Détail!$D:$D,"MR BOUDJADA MOUNIR",Détail!$A:$A,">="&DATE(2025,5,1),Détail!$A:$A,"<"&EDATE(DATE(2025,5,1),1)) -> -4040.11
A42: Juin 2025 | B42: =SUMIFS(Détail!$E:$E,Détail!$D:$D,"MR BOUDJADA MOUNIR",Détail!$A:$A,">="&DATE(2025,6,1),Détail!$A:$A,"<"&EDATE(DATE(2025,6,1),1)) -> -1240.11
A43: Juillet 2025 | B43: =SUMIFS(Détail!$E:$E,Détail!$D:$D,"MR BOUDJADA MOUNIR",Détail!$A:$A,">="&DATE(2025,7,1),Détail!$A:$A,"<"&EDATE(DATE(2025,7,1),1)) -> -1228.51
A44: Août 2025 | B44: =SUMIFS(Détail!$E:$E,Détail!$D:$D,"MR BOUDJADA MOUNIR",Détail!$A:$A,">="&DATE(2025,8,1),Détail!$A:$A,"<"&EDATE(DATE(2025,8,1),1)) -> -1273.69
A45: Septembre 2025 | B45: =SUMIFS(Détail!$E:$E,Détail!$D:$D,"MR BOUDJADA MOUNIR",Détail!$A:$A,">="&DATE(2025,9,1),Détail!$A:$A,"<"&EDATE(DATE(2025,9,1),1)) -> -1218.1
...

Sheet Fournisseurs France détail
A1: Fournisseurs matières premières & emballage (France) — détail par fournisseur (2025)
A3: Firmenich | C3: =SUMIF(Détail!$D:$D,"FIRMENICH",Détail!$E:$E) -> -227485.55
A4: Mois | B4: Montant
A5: Janvier 2025 | B5: =SUMIFS(Détail!$E:$E,Détail!$D:$D,"FIRMENICH",Détail!$A:$A,">="&DATE(2025,1,1),Détail!$A:$A,"<"&EDATE(DATE(2025,1,1),1)) -> 0
A6: Février 2025 | B6: =SUMIFS(Détail!$E:$E,Détail!$D:$D,"FIRMENICH",Détail!$A:$A,">="&DATE(2025,2,1),Détail!$A:$A,"<"&EDATE(DATE(2025,2,1),1)) -> 0
A7: Mars 2025 | B7: =SUMIFS(Détail!$E:$E,Détail!$D:$D,"FIRMENICH",Détail!$A:$A,">="&DATE(2025,3,1),Détail!$A:$A,"<"&EDATE(DATE(2025,3,1),1)) -> -26530.22
A8: Avril 2025 | B8: =SUMIFS(Détail!$E:$E,Détail!$D:$D,"FIRMENICH",Détail!$A:$A,">="&DATE(2025,4,1),Détail!$A:$A,"<"&EDATE(DATE(2025,4,1),1)) -> 0
A9: Mai 2025 | B9: =SUMIFS(Détail!$E:$E,Détail!$D:$D,"FIRMENICH",Détail!$A:$A,">="&DATE(2025,5,1),Détail!$A:$A,"<"&EDATE(DATE(2025,5,1),1)) -> 0
A10: Juin 2025 | B10: =SUMIFS(Détail!$E:$E,Détail!$D:$D,"FIRMENICH",Détail!$A:$A,">="&DATE(2025,6,1),Détail!$A:$A,"<"&EDATE(DATE(2025,6,1),1)) -> 0
A11: Juillet 2025 | B11: =SUMIFS(Détail!$E:$E,Détail!$D:$D,"FIRMENICH",Détail!$A:$A,">="&DATE(2025,7,1),Détail!$A:$A,"<"&EDATE(DATE(2025,7,1),1)) -> -88850.73
A12: Août 2025 | B12: =SUMIFS(Détail!$E:$E,Détail!$D:$D,"FIRMENICH",Détail!$A:$A,">="&DATE(2025,8,1),Détail!$A:$A,"<"&EDATE(DATE(2025,8,1),1)) -> -101001.5
A13: Septembre 2025 | B13: =SUMIFS(Détail!$E:$E,Détail!$D:$D,"FIRMENICH",Détail!$A:$A,">="&DATE(2025,9,1),Détail!$A:$A,"<"&EDATE(DATE(2025,9,1),1)) -> 0
A14: Octobre 2025 | B14: =SUMIFS(Détail!$E:$E,Détail!$D:$D,"FIRMENICH",Détail!$A:$A,">="&DATE(2025,10,1),Détail!$A:$A,"<"&EDATE(DATE(2025,10,1),1)) -> 0
A15: Décembre 2025 | B15: =SUMIFS(Détail!$E:$E,Détail!$D:$D,"FIRMENICH",Détail!$A:$A,">="&DATE(2025,12,1),Détail!$A:$A,"<"&EDATE(DATE(2025,12,1),1)) -> -11103.1
A18: Aromascent | C18: =SUMIF(Détail!$D:$D,"AROMASCENT",Détail!$E:$E) -> -95058
A19: Mois | B19: Montant
A20: Janvier 2025 | B20: =SUMIFS(Détail!$E:$E,Détail!$D:$D,"AROMASCENT",Détail!$A:$A,">="&DATE(2025,1,1),Détail!$A:$A,"<"&EDATE(DATE(2025,1,1),1)) -> 0
A21: Février 2025 | B21: =SUMIFS(Détail!$E:$E,Détail!$D:$D,"AROMASCENT",Détail!$A:$A,">="&DATE(2025,2,1),Détail!$A:$A,"<"&EDATE(DATE(2025,2,1),1)) -> 0
A22: Mars 2025 | B22: =SUMIFS(Détail!$E:$E,Détail!$D:$D,"AROMASCENT",Détail!$A:$A,">="&DATE(2025,3,1),Détail!$A:$A,"<"&EDATE(DATE(2025,3,1),1)) -> -86184
A23: Avril 2025 | B23: =SUMIFS(Détail!$E:$E,Détail!$D:$D,"AROMASCENT",Détail!$A:$A,">="&DATE(2025,4,1),Détail!$A:$A,"<"&EDATE(DATE(2025,4,1),1)) -> 0
A24: Mai 2025 | B24: =SUMIFS(Détail!$E:$E,Détail!$D:$D,"AROMASCENT",Détail!$A:$A,">="&DATE(2025,5,1),Détail!$A:$A,"<"&EDATE(DATE(2025,5,1),1)) -> 0
A25: Juin 2025 | B25: =SUMIFS(Détail!$E:$E,Détail!$D:$D,"AROMASCENT",Détail!$A:$A,">="&DATE(2025,6,1),Détail!$A:$A,"<"&EDATE(DATE(2025,6,1),1)) -> 0
A26: Juillet 2025 | B26: =SUMIFS(Détail!$E:$E,Détail!$D:$D,"AROMASCENT",Détail!$A:$A,">="&DATE(2025,7,1),Détail!$A:$A,"<"&EDATE(DATE(2025,7,1),1)) -> 0
A27: Août 2025 | B27: =SUMIFS(Détail!$E:$E,Détail!$D:$D,"AROMASCENT",Détail!$A:$A,">="&DATE(2025,8,1),Détail!$A:$A,"<"&EDATE(DATE(2025,8,1),1)) -> 0
A28: Septembre 2025 | B28: =SUMIFS(Détail!$E:$E,Détail!$D:$D,"AROMASCENT",Détail!$A:$A,">="&DATE(2025,9,1),Détail!$A:$A,"<"&EDATE(DATE(2025,9,1),1)) -> 0
A29: Octobre 2025 | B29: =SUMIFS(Détail!$E:$E,Détail!$D:$D,"AROMASCENT",Détail!$A:$A,">="&DATE(2025,10,1),Détail!$A:$A,"<"&EDATE(DATE(2025,10,1),1)) -> -5916
A30: Décembre 2025 | B30: =SUMIFS(Détail!$E:$E,Détail!$D:$D,"AROMASCENT",Détail!$A:$A,">="&DATE(2025,12,1),Détail!$A:$A,"<"&EDATE(DATE(2025,12,1),1)) -> -2958
A33: Cpl Aromas France | C33: =SUMIF(Détail!$D:$D,"CPL AROMAS FRANCE",Détail!$E:$E) -> -75040
A34: Mois | B34: Montant
A35: Janvier 2025 | B35: =SUMIFS(Détail!$E:$E,Détail!$D:$D,"CPL AROMAS FRANCE",Détail!$A:$A,">="&DATE(2025,1,1),Détail!$A:$A,"<"&EDATE(DATE(2025,1,1),1)) -> -5075
A36: Février 2025 | B36: =SUMIFS(Détail!$E:$E,Détail!$D:$D,"CPL AROMAS FRANCE",Détail!$A:$A,">="&DATE(2025,2,1),Détail!$A:$A,"<"&EDATE(DATE(2025,2,1),1)) -> -13125
A37: Mars 2025 | B37: =SUMIFS(Détail!$E:$E,Détail!$D:$D,"CPL AROMAS FRANCE",Détail!$A:$A,">="&DATE(2025,3,1),Détail!$A:$A,"<"&EDATE(DATE(2025,3,1),1)) -> -18250
A38: Avril 2025 | B38: =SUMIFS(Détail!$E:$E,Détail!$D:$D,"CPL AROMAS FRANCE",Détail!$A:$A,">="&DATE(2025,4,1),Détail!$A:$A,"<"&EDATE(DATE(2025,4,1),1)) -> 0
A39: Mai 2025 | B39: =SUMIFS(Détail!$E:$E,Détail!$D:$D,"CPL AROMAS FRANCE",Détail!$A:$A,">="&DATE(2025,5,1),Détail!$A:$A,"<"&EDATE(DATE(2025,5,1),1)) -> -6686
A40: Juin 2025 | B40: =SUMIFS(Détail!$E:$E,Détail!$D:$D,"CPL AROMAS FRANCE",Détail!$A:$A,">="&DATE(2025,6,1),Détail!$A:$A,"<"&EDATE(DATE(2025,6,1),1)) -> 0
A41: Juillet 2025 | B41: =SUMIFS(Détail!$E:$E,Détail!$D:$D,"CPL AROMAS FRANCE",Détail!$A:$A,">="&DATE(2025,7,1),Détail!$A:$A,"<"&EDATE(DATE(2025,7,1),1)) -> 0
A42: Août 2025 | B42: =SUMIFS(Détail!$E:$E,Détail!$D:$D,"CPL AROMAS FRANCE",Détail!$A:$A,">="&DATE(2025,8,1),Détail!$A:$A,"<"&EDATE(DATE(2025,8,1),1)) -> 0
A43: Septembre 2025 | B43: =SUMIFS(Détail!$E:$E,Détail!$D:$D,"CPL AROMAS FRANCE",Détail!$A:$A,">="&DATE(2025,9,1),Détail!$A:$A,"<"&EDATE(DATE(2025,9,1),1)) -> -4670
A44: Octobre 2025 | B44: =SUMIFS(Détail!$E:$E,Détail!$D:$D,"CPL AROMAS FRANCE",Détail!$A:$A,">="&DATE(2025,10,1),Détail!$A:$A,"<"&EDATE(DATE(2025,10,1),1)) -> -26418
A45: Décembre 2025 | B45: =SUMIFS(Détail!$E:$E,Détail!$D:$D,"CPL AROMAS FRANCE",Détail!$A:$A,">="&DATE(2025,12,1),Détail!$A:$A,"<"&EDATE(DATE(2025,12,1),1)) -> -816
...

Sheet Usine conditionnement détail
A1: Usine de conditionnement et macération — détail (2025)
A3: France Conditionnement Parfum | C3: =SUMIF(Détail!$D:$D,"FRANCE CONDITIONNEMENT PARFUM",Détail!$E:$E) -> -282990.43
A4: Mois | B4: Montant
A5: Janvier 2025 | B5: =SUMIFS(Détail!$E:$E,Détail!$D:$D,"FRANCE CONDITIONNEMENT PARFUM",Détail!$A:$A,">="&DATE(2025,1,1),Détail!$A:$A,"<"&EDATE(DATE(2025,1,1),1)) -> -33630.81
A6: Mars 2025 | B6: =SUMIFS(Détail!$E:$E,Détail!$D:$D,"FRANCE CONDITIONNEMENT PARFUM",Détail!$A:$A,">="&DATE(2025,3,1),Détail!$A:$A,"<"&EDATE(DATE(2025,3,1),1)) -> -9896.52
A7: Avril 2025 | B7: =SUMIFS(Détail!$E:$E,Détail!$D:$D,"FRANCE CONDITIONNEMENT PARFUM",Détail!$A:$A,">="&DATE(2025,4,1),Détail!$A:$A,"<"&EDATE(DATE(2025,4,1),1)) -> -21066.05
A8: Mai 2025 | B8: =SUMIFS(Détail!$E:$E,Détail!$D:$D,"FRANCE CONDITIONNEMENT PARFUM",Détail!$A:$A,">="&DATE(2025,5,1),Détail!$A:$A,"<"&EDATE(DATE(2025,5,1),1)) -> -48375.39
A9: Juin 2025 | B9: =SUMIFS(Détail!$E:$E,Détail!$D:$D,"FRANCE CONDITIONNEMENT PARFUM",Détail!$A:$A,">="&DATE(2025,6,1),Détail!$A:$A,"<"&EDATE(DATE(2025,6,1),1)) -> -3496.58
A10: Juillet 2025 | B10: =SUMIFS(Détail!$E:$E,Détail!$D:$D,"FRANCE CONDITIONNEMENT PARFUM",Détail!$A:$A,">="&DATE(2025,7,1),Détail!$A:$A,"<"&EDATE(DATE(2025,7,1),1)) -> -57951.62
A11: Septembre 2025 | B11: =SUMIFS(Détail!$E:$E,Détail!$D:$D,"FRANCE CONDITIONNEMENT PARFUM",Détail!$A:$A,">="&DATE(2025,9,1),Détail!$A:$A,"<"&EDATE(DATE(2025,9,1),1)) -> -12593.08
A12: Octobre 2025 | B12: =SUMIFS(Détail!$E:$E,Détail!$D:$D,"FRANCE CONDITIONNEMENT PARFUM",Détail!$A:$A,">="&DATE(2025,10,1),Détail!$A:$A,"<"&EDATE(DATE(2025,10,1),1)) -> -73181.32
A13: Novembre 2025 | B13: =SUMIFS(Détail!$E:$E,Détail!$D:$D,"FRANCE CONDITIONNEMENT PARFUM",Détail!$A:$A,">="&DATE(2025,11,1),Détail!$A:$A,"<"&EDATE(DATE(2025,11,1),1)) -> -11848.95
A14: Décembre 2025 | B14: =SUMIFS(Détail!$E:$E,Détail!$D:$D,"FRANCE CONDITIONNEMENT PARFUM",Détail!$A:$A,">="&DATE(2025,12,1),Détail!$A:$A,"<"&EDATE(DATE(2025,12,1),1)) -> -10916.11
A17: Amival | C17: =SUMIF(Détail!$D:$D,"AMIVAL",Détail!$E:$E) -> -34183.96
A18: Mois | B18: Montant
A19: Janvier 2025 | B19: =SUMIFS(Détail!$E:$E,Détail!$D:$D,"AMIVAL",Détail!$A:$A,">="&DATE(2025,1,1),Détail!$A:$A,"<"&EDATE(DATE(2025,1,1),1)) -> 0
A20: Mars 2025 | B20: =SUMIFS(Détail!$E:$E,Détail!$D:$D,"AMIVAL",Détail!$A:$A,">="&DATE(2025,3,1),Détail!$A:$A,"<"&EDATE(DATE(2025,3,1),1)) -> 0
A21: Avril 2025 | B21: =SUMIFS(Détail!$E:$E,Détail!$D:$D,"AMIVAL",Détail!$A:$A,">="&DATE(2025,4,1),Détail!$A:$A,"<"&EDATE(DATE(2025,4,1),1)) -> 0
A22: Mai 2025 | B22: =SUMIFS(Détail!$E:$E,Détail!$D:$D,"AMIVAL",Détail!$A:$A,">="&DATE(2025,5,1),Détail!$A:$A,"<"&EDATE(DATE(2025,5,1),1)) -> 0
A23: Juin 2025 | B23: =SUMIFS(Détail!$E:$E,Détail!$D:$D,"AMIVAL",Détail!$A:$A,">="&DATE(2025,6,1),Détail!$A:$A,"<"&EDATE(DATE(2025,6,1),1)) -> -10000
A24: Juillet 2025 | B24: =SUMIFS(Détail!$E:$E,Détail!$D:$D,"AMIVAL",Détail!$A:$A,">="&DATE(2025,7,1),Détail!$A:$A,"<"&EDATE(DATE(2025,7,1),1)) -> -24183.96
A25: Septembre 2025 | B25: =SUMIFS(Détail!$E:$E,Détail!$D:$D,"AMIVAL",Détail!$A:$A,">="&DATE(2025,9,1),Détail!$A:$A,"<"&EDATE(DATE(2025,9,1),1)) -> 0
A26: Octobre 2025 | B26: =SUMIFS(Détail!$E:$E,Détail!$D:$D,"AMIVAL",Détail!$A:$A,">="&DATE(2025,10,1),Détail!$A:$A,"<"&EDATE(DATE(2025,10,1),1)) -> 0
A27: Novembre 2025 | B27: =SUMIFS(Détail!$E:$E,Détail!$D:$D,"AMIVAL",Détail!$A:$A,">="&DATE(2025,11,1),Détail!$A:$A,"<"&EDATE(DATE(2025,11,1),1)) -> 0
A28: Décembre 2025 | B28: =SUMIFS(Détail!$E:$E,Détail!$D:$D,"AMIVAL",Détail!$A:$A,">="&DATE(2025,12,1),Détail!$A:$A,"<"&EDATE(DATE(2025,12,1),1)) -> 0

Sheet Fournisseurs intl détail
A1: Fournisseurs internationaux (Chine/Import) — détail par fournisseur (2025)
A3: Zhejiang Bi Industrial Co Ltd | C3: =SUMIF(Détail!$D:$D,"ZHEJIANG BI INDUSTRIAL CO LTD",Détail!$E:$E) -> -245581.16
A4: Mois | B4: Montant
A5: Janvier 2025 | B5: =SUMIFS(Détail!$E:$E,Détail!$D:$D,"ZHEJIANG BI INDUSTRIAL CO LTD",Détail!$A:$A,">="&DATE(2025,1,1),Détail!$A:$A,"<"&EDATE(DATE(2025,1,1),1)) -> 0
A6: Mars 2025 | B6: =SUMIFS(Détail!$E:$E,Détail!$D:$D,"ZHEJIANG BI INDUSTRIAL CO LTD",Détail!$A:$A,">="&DATE(2025,3,1),Détail!$A:$A,"<"&EDATE(DATE(2025,3,1),1)) -> -25738.1
A7: Avril 2025 | B7: =SUMIFS(Détail!$E:$E,Détail!$D:$D,"ZHEJIANG BI INDUSTRIAL CO LTD",Détail!$A:$A,">="&DATE(2025,4,1),Détail!$A:$A,"<"&EDATE(DATE(2025,4,1),1)) -> 0
A8: Mai 2025 | B8: =SUMIFS(Détail!$E:$E,Détail!$D:$D,"ZHEJIANG BI INDUSTRIAL CO LTD",Détail!$A:$A,">="&DATE(2025,5,1),Détail!$A:$A,"<"&EDATE(DATE(2025,5,1),1)) -> -11187.07
A9: Juin 2025 | B9: =SUMIFS(Détail!$E:$E,Détail!$D:$D,"ZHEJIANG BI INDUSTRIAL CO LTD",Détail!$A:$A,">="&DATE(2025,6,1),Détail!$A:$A,"<"&EDATE(DATE(2025,6,1),1)) -> -74407.99
A10: Septembre 2025 | B10: =SUMIFS(Détail!$E:$E,Détail!$D:$D,"ZHEJIANG BI INDUSTRIAL CO LTD",Détail!$A:$A,">="&DATE(2025,9,1),Détail!$A:$A,"<"&EDATE(DATE(2025,9,1),1)) -> 0
A11: Octobre 2025 | B11: =SUMIFS(Détail!$E:$E,Détail!$D:$D,"ZHEJIANG BI INDUSTRIAL CO LTD",Détail!$A:$A,">="&DATE(2025,10,1),Détail!$A:$A,"<"&EDATE(DATE(2025,10,1),1)) -> 0
A12: Novembre 2025 | B12: =SUMIFS(Détail!$E:$E,Détail!$D:$D,"ZHEJIANG BI INDUSTRIAL CO LTD",Détail!$A:$A,">="&DATE(2025,11,1),Détail!$A:$A,"<"&EDATE(DATE(2025,11,1),1)) -> -7264.03
A13: Décembre 2025 | B13: =SUMIFS(Détail!$E:$E,Détail!$D:$D,"ZHEJIANG BI INDUSTRIAL CO LTD",Détail!$A:$A,">="&DATE(2025,12,1),Détail!$A:$A,"<"&EDATE(DATE(2025,12,1),1)) -> -126983.97
A16: Leaders Hardware Plastic Co Limited | C16: =SUMIF(Détail!$D:$D,"LEADERS HARDWARE PLASTIC CO LIMITED",Détail!$E:$E) -> -19669.88
A17: Mois | B17: Montant
A18: Janvier 2025 | B18: =SUMIFS(Détail!$E:$E,Détail!$D:$D,"LEADERS HARDWARE PLASTIC CO LIMITED",Détail!$A:$A,">="&DATE(2025,1,1),Détail!$A:$A,"<"&EDATE(DATE(2025,1,1),1)) -> -5727.66
A19: Mars 2025 | B19: =SUMIFS(Détail!$E:$E,Détail!$D:$D,"LEADERS HARDWARE PLASTIC CO LIMITED",Détail!$A:$A,">="&DATE(2025,3,1),Détail!$A:$A,"<"&EDATE(DATE(2025,3,1),1)) -> 0
A20: Avril 2025 | B20: =SUMIFS(Détail!$E:$E,Détail!$D:$D,"LEADERS HARDWARE PLASTIC CO LIMITED",Détail!$A:$A,">="&DATE(2025,4,1),Détail!$A:$A,"<"&EDATE(DATE(2025,4,1),1)) -> -5189
A21: Mai 2025 | B21: =SUMIFS(Détail!$E:$E,Détail!$D:$D,"LEADERS HARDWARE PLASTIC CO LIMITED",Détail!$A:$A,">="&DATE(2025,5,1),Détail!$A:$A,"<"&EDATE(DATE(2025,5,1),1)) -> -1752.85
A22: Juin 2025 | B22: =SUMIFS(Détail!$E:$E,Détail!$D:$D,"LEADERS HARDWARE PLASTIC CO LIMITED",Détail!$A:$A,">="&DATE(2025,6,1),Détail!$A:$A,"<"&EDATE(DATE(2025,6,1),1)) -> -3332.97
A23: Septembre 2025 | B23: =SUMIFS(Détail!$E:$E,Détail!$D:$D,"LEADERS HARDWARE PLASTIC CO LIMITED",Détail!$A:$A,">="&DATE(2025,9,1),Détail!$A:$A,"<"&EDATE(DATE(2025,9,1),1)) -> -798.78
A24: Octobre 2025 | B24: =SUMIFS(Détail!$E:$E,Détail!$D:$D,"LEADERS HARDWARE PLASTIC CO LIMITED",Détail!$A:$A,">="&DATE(2025,10,1),Détail!$A:$A,"<"&EDATE(DATE(2025,10,1),1)) -> -2868.62
A25: Novembre 2025 | B25: =SUMIFS(Détail!$E:$E,Détail!$D:$D,"LEADERS HARDWARE PLASTIC CO LIMITED",Détail!$A:$A,">="&DATE(2025,11,1),Détail!$A:$A,"<"&EDATE(DATE(2025,11,1),1)) -> 0
A26: Décembre 2025 | B26: =SUMIFS(Détail!$E:$E,Détail!$D:$D,"LEADERS HARDWARE PLASTIC CO LIMITED",Détail!$A:$A,">="&DATE(2025,12,1),Détail!$A:$A,"<"&EDATE(DATE(2025,12,1),1)) -> 0
A29: Shenzhen Fortress Industry Co | C29: =SUMIF(Détail!$D:$D,"SHENZHEN FORTRESS INDUSTRY CO",Détail!$E:$E) -> -13150.78
A30: Mois | B30: Montant
A31: Janvier 2025 | B31: =SUMIFS(Détail!$E:$E,Détail!$D:$D,"SHENZHEN FORTRESS INDUSTRY CO",Détail!$A:$A,">="&DATE(2025,1,1),Détail!$A:$A,"<"&EDATE(DATE(2025,1,1),1)) -> 0
A32: Mars 2025 | B32: =SUMIFS(Détail!$E:$E,Détail!$D:$D,"SHENZHEN FORTRESS INDUSTRY CO",Détail!$A:$A,">="&DATE(2025,3,1),Détail!$A:$A,"<"&EDATE(DATE(2025,3,1),1)) -> 0
A33: Avril 2025 | B33: =SUMIFS(Détail!$E:$E,Détail!$D:$D,"SHENZHEN FORTRESS INDUSTRY CO",Détail!$A:$A,">="&DATE(2025,4,1),Détail!$A:$A,"<"&EDATE(DATE(2025,4,1),1)) -> 0
A34: Mai 2025 | B34: =SUMIFS(Détail!$E:$E,Détail!$D:$D,"SHENZHEN FORTRESS INDUSTRY CO",Détail!$A:$A,">="&DATE(2025,5,1),Détail!$A:$A,"<"&EDATE(DATE(2025,5,1),1)) -> 0
A35: Juin 2025 | B35: =SUMIFS(Détail!$E:$E,Détail!$D:$D,"SHENZHEN FORTRESS INDUSTRY CO",Détail!$A:$A,">="&DATE(2025,6,1),Détail!$A:$A,"<"&EDATE(DATE(2025,6,1),1)) -> 0
A36: Septembre 2025 | B36: =SUMIFS(Détail!$E:$E,Détail!$D:$D,"SHENZHEN FORTRESS INDUSTRY CO",Détail!$A:$A,">="&DATE(2025,9,1),Détail!$A:$A,"<"&EDATE(DATE(2025,9,1),1)) -> 0
A37: Octobre 2025 | B37: =SUMIFS(Détail!$E:$E,Détail!$D:$D,"SHENZHEN FORTRESS INDUSTRY CO",Détail!$A:$A,">="&DATE(2025,10,1),Détail!$A:$A,"<"&EDATE(DATE(2025,10,1),1)) -> -13150.78
A38: Novembre 2025 | B38: =SUMIFS(Détail!$E:$E,Détail!$D:$D,"SHENZHEN FORTRESS INDUSTRY CO",Détail!$A:$A,">="&DATE(2025,11,1),Détail!$A:$A,"<"&EDATE(DATE(2025,11,1),1)) -> 0
A39: Décembre 2025 | B39: =SUMIFS(Détail!$E:$E,Détail!$D:$D,"SHENZHEN FORTRESS INDUSTRY CO",Détail!$A:$A,">="&DATE(2025,12,1),Détail!$A:$A,"<"&EDATE(DATE(2025,12,1),1)) -> 0
A42: Luxe Perfumes Fzc | C42: =SUMIF(Détail!$D:$D,"LUXE PERFUMES FZC",Détail!$E:$E) -> -10208
A43: Mois | B43: Montant
A44: Janvier 2025 | B44: =SUMIFS(Détail!$E:$E,Détail!$D:$D,"LUXE PERFUMES FZC",Détail!$A:$A,">="&DATE(2025,1,1),Détail!$A:$A,"<"&EDATE(DATE(2025,1,1),1)) -> 0
A45: Mars 2025 | B45: =SUMIFS(Détail!$E:$E,Détail!$D:$D,"LUXE PERFUMES FZC",Détail!$A:$A,">="&DATE(2025,3,1),Détail!$A:$A,"<"&EDATE(DATE(2025,3,1),1)) -> 0
A46: Avril 2025 | B46: =SUMIFS(Détail!$E:$E,Détail!$D:$D,"LUXE PERFUMES FZC",Détail!$A:$A,">="&DATE(2025,4,1),Détail!$A:$A,"<"&EDATE(DATE(2025,4,1),1)) -> -10208
A47: Mai 2025 | B47: =SUMIFS(Détail!$E:$E,Détail!$D:$D,"LUXE PERFUMES FZC",Détail!$A:$A,">="&DATE(2025,5,1),Détail!$A:$A,"<"&EDATE(DATE(2025,5,1),1)) -> 0
...

Sheet Charges sociales détail
A1: Charges sociales & cotisations — détail par organisme (2025)
A3: Urssaf D'Ile De France | C3: =SUMIF(Détail!$D:$D,"URSSAF D'ILE DE FRANCE",Détail!$E:$E) -> -33018
A4: Mois | B4: Montant
A5: Janvier 2025 | B5: =SUMIFS(Détail!$E:$E,Détail!$D:$D,"URSSAF D'ILE DE FRANCE",Détail!$A:$A,">="&DATE(2025,1,1),Détail!$A:$A,"<"&EDATE(DATE(2025,1,1),1)) -> -1341
A6: Février 2025 | B6: =SUMIFS(Détail!$E:$E,Détail!$D:$D,"URSSAF D'ILE DE FRANCE",Détail!$A:$A,">="&DATE(2025,2,1),Détail!$A:$A,"<"&EDATE(DATE(2025,2,1),1)) -> -2405
A7: Mars 2025 | B7: =SUMIFS(Détail!$E:$E,Détail!$D:$D,"URSSAF D'ILE DE FRANCE",Détail!$A:$A,">="&DATE(2025,3,1),Détail!$A:$A,"<"&EDATE(DATE(2025,3,1),1)) -> -2860
A8: Avril 2025 | B8: =SUMIFS(Détail!$E:$E,Détail!$D:$D,"URSSAF D'ILE DE FRANCE",Détail!$A:$A,">="&DATE(2025,4,1),Détail!$A:$A,"<"&EDATE(DATE(2025,4,1),1)) -> -2839
A9: Mai 2025 | B9: =SUMIFS(Détail!$E:$E,Détail!$D:$D,"URSSAF D'ILE DE FRANCE",Détail!$A:$A,">="&DATE(2025,5,1),Détail!$A:$A,"<"&EDATE(DATE(2025,5,1),1)) -> -2887
A10: Juin 2025 | B10: =SUMIFS(Détail!$E:$E,Détail!$D:$D,"URSSAF D'ILE DE FRANCE",Détail!$A:$A,">="&DATE(2025,6,1),Détail!$A:$A,"<"&EDATE(DATE(2025,6,1),1)) -> -2927
A11: Juillet 2025 | B11: =SUMIFS(Détail!$E:$E,Détail!$D:$D,"URSSAF D'ILE DE FRANCE",Détail!$A:$A,">="&DATE(2025,7,1),Détail!$A:$A,"<"&EDATE(DATE(2025,7,1),1)) -> -2924
A12: Août 2025 | B12: =SUMIFS(Détail!$E:$E,Détail!$D:$D,"URSSAF D'ILE DE FRANCE",Détail!$A:$A,">="&DATE(2025,8,1),Détail!$A:$A,"<"&EDATE(DATE(2025,8,1),1)) -> -2930
A13: Septembre 2025 | B13: =SUMIFS(Détail!$E:$E,Détail!$D:$D,"URSSAF D'ILE DE FRANCE",Détail!$A:$A,">="&DATE(2025,9,1),Détail!$A:$A,"<"&EDATE(DATE(2025,9,1),1)) -> -3015
A14: Octobre 2025 | B14: =SUMIFS(Détail!$E:$E,Détail!$D:$D,"URSSAF D'ILE DE FRANCE",Détail!$A:$A,">="&DATE(2025,10,1),Détail!$A:$A,"<"&EDATE(DATE(2025,10,1),1)) -> -2927
A15: Novembre 2025 | B15: =SUMIFS(Détail!$E:$E,Détail!$D:$D,"URSSAF D'ILE DE FRANCE",Détail!$A:$A,">="&DATE(2025,11,1),Détail!$A:$A,"<"&EDATE(DATE(2025,11,1),1)) -> -3041
A16: Décembre 2025 | B16: =SUMIFS(Détail!$E:$E,Détail!$D:$D,"URSSAF D'ILE DE FRANCE",Détail!$A:$A,">="&DATE(2025,12,1),Détail!$A:$A,"<"&EDATE(DATE(2025,12,1),1)) -> -2922
A19: Ag2R Reunica | C19: =SUMIF(Détail!$D:$D,"AG2R REUNICA",Détail!$E:$E) -> -6882.84
A20: Mois | B20: Montant
A21: Janvier 2025 | B21: =SUMIFS(Détail!$E:$E,Détail!$D:$D,"AG2R REUNICA",Détail!$A:$A,">="&DATE(2025,1,1),Détail!$A:$A,"<"&EDATE(DATE(2025,1,1),1)) -> -268.42
A22: Février 2025 | B22: =SUMIFS(Détail!$E:$E,Détail!$D:$D,"AG2R REUNICA",Détail!$A:$A,">="&DATE(2025,2,1),Détail!$A:$A,"<"&EDATE(DATE(2025,2,1),1)) -> -503.88
A23: Mars 2025 | B23: =SUMIFS(Détail!$E:$E,Détail!$D:$D,"AG2R REUNICA",Détail!$A:$A,">="&DATE(2025,3,1),Détail!$A:$A,"<"&EDATE(DATE(2025,3,1),1)) -> -604.33
A24: Avril 2025 | B24: =SUMIFS(Détail!$E:$E,Détail!$D:$D,"AG2R REUNICA",Détail!$A:$A,">="&DATE(2025,4,1),Détail!$A:$A,"<"&EDATE(DATE(2025,4,1),1)) -> -600.22
A25: Mai 2025 | B25: =SUMIFS(Détail!$E:$E,Détail!$D:$D,"AG2R REUNICA",Détail!$A:$A,">="&DATE(2025,5,1),Détail!$A:$A,"<"&EDATE(DATE(2025,5,1),1)) -> -610.81
A26: Juin 2025 | B26: =SUMIFS(Détail!$E:$E,Détail!$D:$D,"AG2R REUNICA",Détail!$A:$A,">="&DATE(2025,6,1),Détail!$A:$A,"<"&EDATE(DATE(2025,6,1),1)) -> -611.37
A27: Juillet 2025 | B27: =SUMIFS(Détail!$E:$E,Détail!$D:$D,"AG2R REUNICA",Détail!$A:$A,">="&DATE(2025,7,1),Détail!$A:$A,"<"&EDATE(DATE(2025,7,1),1)) -> -610.75
A28: Août 2025 | B28: =SUMIFS(Détail!$E:$E,Détail!$D:$D,"AG2R REUNICA",Détail!$A:$A,">="&DATE(2025,8,1),Détail!$A:$A,"<"&EDATE(DATE(2025,8,1),1)) -> -610.68
A29: Septembre 2025 | B29: =SUMIFS(Détail!$E:$E,Détail!$D:$D,"AG2R REUNICA",Détail!$A:$A,">="&DATE(2025,9,1),Détail!$A:$A,"<"&EDATE(DATE(2025,9,1),1)) -> -631.06
A30: Octobre 2025 | B30: =SUMIFS(Détail!$E:$E,Détail!$D:$D,"AG2R REUNICA",Détail!$A:$A,">="&DATE(2025,10,1),Détail!$A:$A,"<"&EDATE(DATE(2025,10,1),1)) -> -610.48
A31: Novembre 2025 | B31: =SUMIFS(Détail!$E:$E,Détail!$D:$D,"AG2R REUNICA",Détail!$A:$A,">="&DATE(2025,11,1),Détail!$A:$A,"<"&EDATE(DATE(2025,11,1),1)) -> -610.23
A32: Décembre 2025 | B32: =SUMIFS(Détail!$E:$E,Détail!$D:$D,"AG2R REUNICA",Détail!$A:$A,">="&DATE(2025,12,1),Détail!$A:$A,"<"&EDATE(DATE(2025,12,1),1)) -> -610.61
A35: Direction Generale Des Finances Publiques (Dgfip) | C35: =SUMIF(Détail!$D:$D,"DIRECTION GENERALE DES FINANCES PUBLIQUES (DGFIP)",Détail!$E:$E) -> -4795
A36: Mois | B36: Montant
A37: Janvier 2025 | B37: =SUMIFS(Détail!$E:$E,Détail!$D:$D,"DIRECTION GENERALE DES FINANCES PUBLIQUES (DGFIP)",Détail!$A:$A,">="&DATE(2025,1,1),Détail!$A:$A,"<"&EDATE(DATE(2025,1,1),1)) -> -33
A38: Février 2025 | B38: =SUMIFS(Détail!$E:$E,Détail!$D:$D,"DIRECTION GENERALE DES FINANCES PUBLIQUES (DGFIP)",Détail!$A:$A,">="&DATE(2025,2,1),Détail!$A:$A,"<"&EDATE(DATE(2025,2,1),1)) -> -143
A39: Mars 2025 | B39: =SUMIFS(Détail!$E:$E,Détail!$D:$D,"DIRECTION GENERALE DES FINANCES PUBLIQUES (DGFIP)",Détail!$A:$A,">="&DATE(2025,3,1),Détail!$A:$A,"<"&EDATE(DATE(2025,3,1),1)) -> -191
A40: Avril 2025 | B40: =SUMIFS(Détail!$E:$E,Détail!$D:$D,"DIRECTION GENERALE DES FINANCES PUBLIQUES (DGFIP)",Détail!$A:$A,">="&DATE(2025,4,1),Détail!$A:$A,"<"&EDATE(DATE(2025,4,1),1)) -> -191
A41: Mai 2025 | B41: =SUMIFS(Détail!$E:$E,Détail!$D:$D,"DIRECTION GENERALE DES FINANCES PUBLIQUES (DGFIP)",Détail!$A:$A,">="&DATE(2025,5,1),Détail!$A:$A,"<"&EDATE(DATE(2025,5,1),1)) -> -191
A42: Juin 2025 | B42: =SUMIFS(Détail!$E:$E,Détail!$D:$D,"DIRECTION GENERALE DES FINANCES PUBLIQUES (DGFIP)",Détail!$A:$A,">="&DATE(2025,6,1),Détail!$A:$A,"<"&EDATE(DATE(2025,6,1),1)) -> -191
A43: Juillet 2025 | B43: =SUMIFS(Détail!$E:$E,Détail!$D:$D,"DIRECTION GENERALE DES FINANCES PUBLIQUES (DGFIP)",Détail!$A:$A,">="&DATE(2025,7,1),Détail!$A:$A,"<"&EDATE(DATE(2025,7,1),1)) -> -191
A44: Août 2025 | B44: =SUMIFS(Détail!$E:$E,Détail!$D:$D,"DIRECTION GENERALE DES FINANCES PUBLIQUES (DGFIP)",Détail!$A:$A,">="&DATE(2025,8,1),Détail!$A:$A,"<"&EDATE(DATE(2025,8,1),1)) -> -190
A45: Septembre 2025 | B45: =SUMIFS(Détail!$E:$E,Détail!$D:$D,"DIRECTION GENERALE DES FINANCES PUBLIQUES (DGFIP)",Détail!$A:$A,">="&DATE(2025,9,1),Détail!$A:$A,"<"&EDATE(DATE(2025,9,1),1)) -> -192
...

Sheet Voyages détail
A1: Voyages / déplacements — détail par prestataire (2025)
A3: Emirates | C3: =SUMIF(Détail!$D:$D,"EMIRATES",Détail!$E:$E) -> -10638.18
A4: Mois | B4: Montant
A5: Janvier 2025 | B5: =SUMIFS(Détail!$E:$E,Détail!$D:$D,"EMIRATES",Détail!$A:$A,">="&DATE(2025,1,1),Détail!$A:$A,"<"&EDATE(DATE(2025,1,1),1)) -> 0
A6: Février 2025 | B6: =SUMIFS(Détail!$E:$E,Détail!$D:$D,"EMIRATES",Détail!$A:$A,">="&DATE(2025,2,1),Détail!$A:$A,"<"&EDATE(DATE(2025,2,1),1)) -> 0
A7: Mars 2025 | B7: =SUMIFS(Détail!$E:$E,Détail!$D:$D,"EMIRATES",Détail!$A:$A,">="&DATE(2025,3,1),Détail!$A:$A,"<"&EDATE(DATE(2025,3,1),1)) -> 0
A8: Avril 2025 | B8: =SUMIFS(Détail!$E:$E,Détail!$D:$D,"EMIRATES",Détail!$A:$A,">="&DATE(2025,4,1),Détail!$A:$A,"<"&EDATE(DATE(2025,4,1),1)) -> -2378.04
A9: Mai 2025 | B9: =SUMIFS(Détail!$E:$E,Détail!$D:$D,"EMIRATES",Détail!$A:$A,">="&DATE(2025,5,1),Détail!$A:$A,"<"&EDATE(DATE(2025,5,1),1)) -> -856.32
A10: Juin 2025 | B10: =SUMIFS(Détail!$E:$E,Détail!$D:$D,"EMIRATES",Détail!$A:$A,">="&DATE(2025,6,1),Détail!$A:$A,"<"&EDATE(DATE(2025,6,1),1)) -> -916.64
A11: Juillet 2025 | B11: =SUMIFS(Détail!$E:$E,Détail!$D:$D,"EMIRATES",Détail!$A:$A,">="&DATE(2025,7,1),Détail!$A:$A,"<"&EDATE(DATE(2025,7,1),1)) -> -1910.9
A12: Août 2025 | B12: =SUMIFS(Détail!$E:$E,Détail!$D:$D,"EMIRATES",Détail!$A:$A,">="&DATE(2025,8,1),Détail!$A:$A,"<"&EDATE(DATE(2025,8,1),1)) -> 0
A13: Septembre 2025 | B13: =SUMIFS(Détail!$E:$E,Détail!$D:$D,"EMIRATES",Détail!$A:$A,">="&DATE(2025,9,1),Détail!$A:$A,"<"&EDATE(DATE(2025,9,1),1)) -> -3176.88
A14: Octobre 2025 | B14: =SUMIFS(Détail!$E:$E,Détail!$D:$D,"EMIRATES",Détail!$A:$A,">="&DATE(2025,10,1),Détail!$A:$A,"<"&EDATE(DATE(2025,10,1),1)) -> -1324.8
A15: Novembre 2025 | B15: =SUMIFS(Détail!$E:$E,Détail!$D:$D,"EMIRATES",Détail!$A:$A,">="&DATE(2025,11,1),Détail!$A:$A,"<"&EDATE(DATE(2025,11,1),1)) -> -74.6
A16: Décembre 2025 | B16: =SUMIFS(Détail!$E:$E,Détail!$D:$D,"EMIRATES",Détail!$A:$A,">="&DATE(2025,12,1),Détail!$A:$A,"<"&EDATE(DATE(2025,12,1),1)) -> 0
A19: Air France | C19: =SUMIF(Détail!$D:$D,"AIR FRANCE",Détail!$E:$E) -> -2218.54
A20: Mois | B20: Montant
A21: Janvier 2025 | B21: =SUMIFS(Détail!$E:$E,Détail!$D:$D,"AIR FRANCE",Détail!$A:$A,">="&DATE(2025,1,1),Détail!$A:$A,"<"&EDATE(DATE(2025,1,1),1)) -> -198.15
A22: Février 2025 | B22: =SUMIFS(Détail!$E:$E,Détail!$D:$D,"AIR FRANCE",Détail!$A:$A,">="&DATE(2025,2,1),Détail!$A:$A,"<"&EDATE(DATE(2025,2,1),1)) -> 0
A23: Mars 2025 | B23: =SUMIFS(Détail!$E:$E,Détail!$D:$D,"AIR FRANCE",Détail!$A:$A,">="&DATE(2025,3,1),Détail!$A:$A,"<"&EDATE(DATE(2025,3,1),1)) -> -350.21
A24: Avril 2025 | B24: =SUMIFS(Détail!$E:$E,Détail!$D:$D,"AIR FRANCE",Détail!$A:$A,">="&DATE(2025,4,1),Détail!$A:$A,"<"&EDATE(DATE(2025,4,1),1)) -> 0
A25: Mai 2025 | B25: =SUMIFS(Détail!$E:$E,Détail!$D:$D,"AIR FRANCE",Détail!$A:$A,">="&DATE(2025,5,1),Détail!$A:$A,"<"&EDATE(DATE(2025,5,1),1)) -> -199.6
A26: Juin 2025 | B26: =SUMIFS(Détail!$E:$E,Détail!$D:$D,"AIR FRANCE",Détail!$A:$A,">="&DATE(2025,6,1),Détail!$A:$A,"<"&EDATE(DATE(2025,6,1),1)) -> 0
A27: Juillet 2025 | B27: =SUMIFS(Détail!$E:$E,Détail!$D:$D,"AIR FRANCE",Détail!$A:$A,">="&DATE(2025,7,1),Détail!$A:$A,"<"&EDATE(DATE(2025,7,1),1)) -> 0
A28: Août 2025 | B28: =SUMIFS(Détail!$E:$E,Détail!$D:$D,"AIR FRANCE",Détail!$A:$A,">="&DATE(2025,8,1),Détail!$A:$A,"<"&EDATE(DATE(2025,8,1),1)) -> -831.75
A29: Septembre 2025 | B29: =SUMIFS(Détail!$E:$E,Détail!$D:$D,"AIR FRANCE",Détail!$A:$A,">="&DATE(2025,9,1),Détail!$A:$A,"<"&EDATE(DATE(2025,9,1),1)) -> 0
A30: Octobre 2025 | B30: =SUMIFS(Détail!$E:$E,Détail!$D:$D,"AIR FRANCE",Détail!$A:$A,">="&DATE(2025,10,1),Détail!$A:$A,"<"&EDATE(DATE(2025,10,1),1)) -> 0
A31: Novembre 2025 | B31: =SUMIFS(Détail!$E:$E,Détail!$D:$D,"AIR FRANCE",Détail!$A:$A,">="&DATE(2025,11,1),Détail!$A:$A,"<"&EDATE(DATE(2025,11,1),1)) -> -267.08
A32: Décembre 2025 | B32: =SUMIFS(Détail!$E:$E,Détail!$D:$D,"AIR FRANCE",Détail!$A:$A,">="&DATE(2025,12,1),Détail!$A:$A,"<"&EDATE(DATE(2025,12,1),1)) -> -371.75
A35: Sonder.Com | C35: =SUMIF(Détail!$D:$D,"SONDER.COM",Détail!$E:$E) -> -1586.9
A36: Mois | B36: Montant
A37: Janvier 2025 | B37: =SUMIFS(Détail!$E:$E,Détail!$D:$D,"SONDER.COM",Détail!$A:$A,">="&DATE(2025,1,1),Détail!$A:$A,"<"&EDATE(DATE(2025,1,1),1)) -> 0
A38: Février 2025 | B38: =SUMIFS(Détail!$E:$E,Détail!$D:$D,"SONDER.COM",Détail!$A:$A,">="&DATE(2025,2,1),Détail!$A:$A,"<"&EDATE(DATE(2025,2,1),1)) -> 0
A39: Mars 2025 | B39: =SUMIFS(Détail!$E:$E,Détail!$D:$D,"SONDER.COM",Détail!$A:$A,">="&DATE(2025,3,1),Détail!$A:$A,"<"&EDATE(DATE(2025,3,1),1)) -> 0
A40: Avril 2025 | B40: =SUMIFS(Détail!$E:$E,Détail!$D:$D,"SONDER.COM",Détail!$A:$A,">="&DATE(2025,4,1),Détail!$A:$A,"<"&EDATE(DATE(2025,4,1),1)) -> 0
A41: Mai 2025 | B41: =SUMIFS(Détail!$E:$E,Détail!$D:$D,"SONDER.COM",Détail!$A:$A,">="&DATE(2025,5,1),Détail!$A:$A,"<"&EDATE(DATE(2025,5,1),1)) -> 0
A42: Juin 2025 | B42: =SUMIFS(Détail!$E:$E,Détail!$D:$D,"SONDER.COM",Détail!$A:$A,">="&DATE(2025,6,1),Détail!$A:$A,"<"&EDATE(DATE(2025,6,1),1)) -> 0
A43: Juillet 2025 | B43: =SUMIFS(Détail!$E:$E,Détail!$D:$D,"SONDER.COM",Détail!$A:$A,">="&DATE(2025,7,1),Détail!$A:$A,"<"&EDATE(DATE(2025,7,1),1)) -> 0
A44: Août 2025 | B44: =SUMIFS(Détail!$E:$E,Détail!$D:$D,"SONDER.COM",Détail!$A:$A,">="&DATE(2025,8,1),Détail!$A:$A,"<"&EDATE(DATE(2025,8,1),1)) -> 0
A45: Septembre 2025 | B45: =SUMIFS(Détail!$E:$E,Détail!$D:$D,"SONDER.COM",Détail!$A:$A,">="&DATE(2025,9,1),Détail!$A:$A,"<"&EDATE(DATE(2025,9,1),1)) -> 0
...

Sheet Téléphone-Internet détail
A1: Téléphone / Internet / Logiciels — détail par prestataire (2025)
A3: Orange Sa | C3: =SUMIF(Détail!$D:$D,"ORANGE SA",Détail!$E:$E) -> -6873.65
A4: Mois | B4: Montant
A5: Janvier 2025 | B5: =SUMIFS(Détail!$E:$E,Détail!$D:$D,"ORANGE SA",Détail!$A:$A,">="&DATE(2025,1,1),Détail!$A:$A,"<"&EDATE(DATE(2025,1,1),1)) -> -443.79
A6: Février 2025 | B6: =SUMIFS(Détail!$E:$E,Détail!$D:$D,"ORANGE SA",Détail!$A:$A,">="&DATE(2025,2,1),Détail!$A:$A,"<"&EDATE(DATE(2025,2,1),1)) -> -448.53
A7: Mars 2025 | B7: =SUMIFS(Détail!$E:$E,Détail!$D:$D,"ORANGE SA",Détail!$A:$A,">="&DATE(2025,3,1),Détail!$A:$A,"<"&EDATE(DATE(2025,3,1),1)) -> -441.74
A8: Avril 2025 | B8: =SUMIFS(Détail!$E:$E,Détail!$D:$D,"ORANGE SA",Détail!$A:$A,">="&DATE(2025,4,1),Détail!$A:$A,"<"&EDATE(DATE(2025,4,1),1)) -> -531.18
A9: Mai 2025 | B9: =SUMIFS(Détail!$E:$E,Détail!$D:$D,"ORANGE SA",Détail!$A:$A,">="&DATE(2025,5,1),Détail!$A:$A,"<"&EDATE(DATE(2025,5,1),1)) -> -488.91
A10: Juin 2025 | B10: =SUMIFS(Détail!$E:$E,Détail!$D:$D,"ORANGE SA",Détail!$A:$A,">="&DATE(2025,6,1),Détail!$A:$A,"<"&EDATE(DATE(2025,6,1),1)) -> -531.8
A11: Juillet 2025 | B11: =SUMIFS(Détail!$E:$E,Détail!$D:$D,"ORANGE SA",Détail!$A:$A,">="&DATE(2025,7,1),Détail!$A:$A,"<"&EDATE(DATE(2025,7,1),1)) -> -471.5
A12: Août 2025 | B12: =SUMIFS(Détail!$E:$E,Détail!$D:$D,"ORANGE SA",Détail!$A:$A,">="&DATE(2025,8,1),Détail!$A:$A,"<"&EDATE(DATE(2025,8,1),1)) -> -474.9
A13: Septembre 2025 | B13: =SUMIFS(Détail!$E:$E,Détail!$D:$D,"ORANGE SA",Détail!$A:$A,">="&DATE(2025,9,1),Détail!$A:$A,"<"&EDATE(DATE(2025,9,1),1)) -> -1318.82
A14: Octobre 2025 | B14: =SUMIFS(Détail!$E:$E,Détail!$D:$D,"ORANGE SA",Détail!$A:$A,">="&DATE(2025,10,1),Détail!$A:$A,"<"&EDATE(DATE(2025,10,1),1)) -> -551.67
A15: Novembre 2025 | B15: =SUMIFS(Détail!$E:$E,Détail!$D:$D,"ORANGE SA",Détail!$A:$A,">="&DATE(2025,11,1),Détail!$A:$A,"<"&EDATE(DATE(2025,11,1),1)) -> -682.48
A16: Décembre 2025 | B16: =SUMIFS(Détail!$E:$E,Détail!$D:$D,"ORANGE SA",Détail!$A:$A,">="&DATE(2025,12,1),Détail!$A:$A,"<"&EDATE(DATE(2025,12,1),1)) -> -488.33
A19: Google Workspace | C19: =SUMIF(Détail!$D:$D,"GOOGLE WORKSPACE",Détail!$E:$E) -> -1676.8
A20: Mois | B20: Montant
A21: Janvier 2025 | B21: =SUMIFS(Détail!$E:$E,Détail!$D:$D,"GOOGLE WORKSPACE",Détail!$A:$A,">="&DATE(2025,1,1),Détail!$A:$A,"<"&EDATE(DATE(2025,1,1),1)) -> -215.28
A22: Février 2025 | B22: =SUMIFS(Détail!$E:$E,Détail!$D:$D,"GOOGLE WORKSPACE",Détail!$A:$A,">="&DATE(2025,2,1),Détail!$A:$A,"<"&EDATE(DATE(2025,2,1),1)) -> -107.63
A23: Mars 2025 | B23: =SUMIFS(Détail!$E:$E,Détail!$D:$D,"GOOGLE WORKSPACE",Détail!$A:$A,">="&DATE(2025,3,1),Détail!$A:$A,"<"&EDATE(DATE(2025,3,1),1)) -> -107.64
A24: Avril 2025 | B24: =SUMIFS(Détail!$E:$E,Détail!$D:$D,"GOOGLE WORKSPACE",Détail!$A:$A,">="&DATE(2025,4,1),Détail!$A:$A,"<"&EDATE(DATE(2025,4,1),1)) -> -111.85
A25: Mai 2025 | B25: =SUMIFS(Détail!$E:$E,Détail!$D:$D,"GOOGLE WORKSPACE",Détail!$A:$A,">="&DATE(2025,5,1),Détail!$A:$A,"<"&EDATE(DATE(2025,5,1),1)) -> -126.36
A26: Juin 2025 | B26: =SUMIFS(Détail!$E:$E,Détail!$D:$D,"GOOGLE WORKSPACE",Détail!$A:$A,">="&DATE(2025,6,1),Détail!$A:$A,"<"&EDATE(DATE(2025,6,1),1)) -> -133.56
A27: Juillet 2025 | B27: =SUMIFS(Détail!$E:$E,Détail!$D:$D,"GOOGLE WORKSPACE",Détail!$A:$A,">="&DATE(2025,7,1),Détail!$A:$A,"<"&EDATE(DATE(2025,7,1),1)) -> -145.48
A28: Août 2025 | B28: =SUMIFS(Détail!$E:$E,Détail!$D:$D,"GOOGLE WORKSPACE",Détail!$A:$A,">="&DATE(2025,8,1),Détail!$A:$A,"<"&EDATE(DATE(2025,8,1),1)) -> -145.8
A29: Septembre 2025 | B29: =SUMIFS(Détail!$E:$E,Détail!$D:$D,"GOOGLE WORKSPACE",Détail!$A:$A,">="&DATE(2025,9,1),Détail!$A:$A,"<"&EDATE(DATE(2025,9,1),1)) -> -145.8
A30: Octobre 2025 | B30: =SUMIFS(Détail!$E:$E,Détail!$D:$D,"GOOGLE WORKSPACE",Détail!$A:$A,">="&DATE(2025,10,1),Détail!$A:$A,"<"&EDATE(DATE(2025,10,1),1)) -> -145.8
A31: Novembre 2025 | B31: =SUMIFS(Détail!$E:$E,Détail!$D:$D,"GOOGLE WORKSPACE",Détail!$A:$A,">="&DATE(2025,11,1),Détail!$A:$A,"<"&EDATE(DATE(2025,11,1),1)) -> -145.8
A32: Décembre 2025 | B32: =SUMIFS(Détail!$E:$E,Détail!$D:$D,"GOOGLE WORKSPACE",Détail!$A:$A,">="&DATE(2025,12,1),Détail!$A:$A,"<"&EDATE(DATE(2025,12,1),1)) -> -145.8
A35: Boutique Orange | C35: =SUMIF(Détail!$D:$D,"BOUTIQUE ORANGE",Détail!$E:$E) -> -1120.96
A36: Mois | B36: Montant
A37: Janvier 2025 | B37: =SUMIFS(Détail!$E:$E,Détail!$D:$D,"BOUTIQUE ORANGE",Détail!$A:$A,">="&DATE(2025,1,1),Détail!$A:$A,"<"&EDATE(DATE(2025,1,1),1)) -> 0
A38: Février 2025 | B38: =SUMIFS(Détail!$E:$E,Détail!$D:$D,"BOUTIQUE ORANGE",Détail!$A:$A,">="&DATE(2025,2,1),Détail!$A:$A,"<"&EDATE(DATE(2025,2,1),1)) -> 0
A39: Mars 2025 | B39: =SUMIFS(Détail!$E:$E,Détail!$D:$D,"BOUTIQUE ORANGE",Détail!$A:$A,">="&DATE(2025,3,1),Détail!$A:$A,"<"&EDATE(DATE(2025,3,1),1)) -> 0
A40: Avril 2025 | B40: =SUMIFS(Détail!$E:$E,Détail!$D:$D,"BOUTIQUE ORANGE",Détail!$A:$A,">="&DATE(2025,4,1),Détail!$A:$A,"<"&EDATE(DATE(2025,4,1),1)) -> 0
A41: Mai 2025 | B41: =SUMIFS(Détail!$E:$E,Détail!$D:$D,"BOUTIQUE ORANGE",Détail!$A:$A,">="&DATE(2025,5,1),Détail!$A:$A,"<"&EDATE(DATE(2025,5,1),1)) -> 0
A42: Juin 2025 | B42: =SUMIFS(Détail!$E:$E,Détail!$D:$D,"BOUTIQUE ORANGE",Détail!$A:$A,">="&DATE(2025,6,1),Détail!$A:$A,"<"&EDATE(DATE(2025,6,1),1)) -> 0
A43: Juillet 2025 | B43: =SUMIFS(Détail!$E:$E,Détail!$D:$D,"BOUTIQUE ORANGE",Détail!$A:$A,">="&DATE(2025,7,1),Détail!$A:$A,"<"&EDATE(DATE(2025,7,1),1)) -> 0
A44: Août 2025 | B44: =SUMIFS(Détail!$E:$E,Détail!$D:$D,"BOUTIQUE ORANGE",Détail!$A:$A,">="&DATE(2025,8,1),Détail!$A:$A,"<"&EDATE(DATE(2025,8,1),1)) -> 0
A45: Septembre 2025 | B45: =SUMIFS(Détail!$E:$E,Détail!$D:$D,"BOUTIQUE ORANGE",Détail!$A:$A,">="&DATE(2025,9,1),Détail!$A:$A,"<"&EDATE(DATE(2025,9,1),1)) -> -1120.96
...

Sheet Commission vendeur détail
A1: Commission vendeur — détail (2025)
A2: Commission versée à un apporteur d'affaires (a trouvé un client).
A4: Mr Riadh Chebhouni | C4: =SUMIF(Détail!$D:$D,"MR RIADH CHEBHOUNI",Détail!$E:$E) -> -9359.1
A5: Mois | B5: Montant
A6: Septembre 2025 | B6: =SUMIFS(Détail!$E:$E,Détail!$D:$D,"MR RIADH CHEBHOUNI",Détail!$A:$A,">="&DATE(2025,9,1),Détail!$A:$A,"<"&EDATE(DATE(2025,9,1),1)) -> -9359.1

Sheet Frais pro divers détail
A1: Frais professionnels divers — détail par prestataire (2025)
A3: Messe Frankfurt Middle East Gmbh | C3: =SUMIF(Détail!$D:$D,"MESSE FRANKFURT MIDDLE EAST GMBH",Détail!$E:$E) -> -4482.37
A4: Mois | B4: Montant
A5: Janvier 2025 | B5: =SUMIFS(Détail!$E:$E,Détail!$D:$D,"MESSE FRANKFURT MIDDLE EAST GMBH",Détail!$A:$A,">="&DATE(2025,1,1),Détail!$A:$A,"<"&EDATE(DATE(2025,1,1),1)) -> 0
A6: Février 2025 | B6: =SUMIFS(Détail!$E:$E,Détail!$D:$D,"MESSE FRANKFURT MIDDLE EAST GMBH",Détail!$A:$A,">="&DATE(2025,2,1),Détail!$A:$A,"<"&EDATE(DATE(2025,2,1),1)) -> 0
A7: Mars 2025 | B7: =SUMIFS(Détail!$E:$E,Détail!$D:$D,"MESSE FRANKFURT MIDDLE EAST GMBH",Détail!$A:$A,">="&DATE(2025,3,1),Détail!$A:$A,"<"&EDATE(DATE(2025,3,1),1)) -> 0
A8: Avril 2025 | B8: =SUMIFS(Détail!$E:$E,Détail!$D:$D,"MESSE FRANKFURT MIDDLE EAST GMBH",Détail!$A:$A,">="&DATE(2025,4,1),Détail!$A:$A,"<"&EDATE(DATE(2025,4,1),1)) -> 0
A9: Mai 2025 | B9: =SUMIFS(Détail!$E:$E,Détail!$D:$D,"MESSE FRANKFURT MIDDLE EAST GMBH",Détail!$A:$A,">="&DATE(2025,5,1),Détail!$A:$A,"<"&EDATE(DATE(2025,5,1),1)) -> 0
A10: Juin 2025 | B10: =SUMIFS(Détail!$E:$E,Détail!$D:$D,"MESSE FRANKFURT MIDDLE EAST GMBH",Détail!$A:$A,">="&DATE(2025,6,1),Détail!$A:$A,"<"&EDATE(DATE(2025,6,1),1)) -> -4482.37
A11: Juillet 2025 | B11: =SUMIFS(Détail!$E:$E,Détail!$D:$D,"MESSE FRANKFURT MIDDLE EAST GMBH",Détail!$A:$A,">="&DATE(2025,7,1),Détail!$A:$A,"<"&EDATE(DATE(2025,7,1),1)) -> 0
A12: Août 2025 | B12: =SUMIFS(Détail!$E:$E,Détail!$D:$D,"MESSE FRANKFURT MIDDLE EAST GMBH",Détail!$A:$A,">="&DATE(2025,8,1),Détail!$A:$A,"<"&EDATE(DATE(2025,8,1),1)) -> 0
A13: Septembre 2025 | B13: =SUMIFS(Détail!$E:$E,Détail!$D:$D,"MESSE FRANKFURT MIDDLE EAST GMBH",Détail!$A:$A,">="&DATE(2025,9,1),Détail!$A:$A,"<"&EDATE(DATE(2025,9,1),1)) -> 0
A14: Octobre 2025 | B14: =SUMIFS(Détail!$E:$E,Détail!$D:$D,"MESSE FRANKFURT MIDDLE EAST GMBH",Détail!$A:$A,">="&DATE(2025,10,1),Détail!$A:$A,"<"&EDATE(DATE(2025,10,1),1)) -> 0
A15: Novembre 2025 | B15: =SUMIFS(Détail!$E:$E,Détail!$D:$D,"MESSE FRANKFURT MIDDLE EAST GMBH",Détail!$A:$A,">="&DATE(2025,11,1),Détail!$A:$A,"<"&EDATE(DATE(2025,11,1),1)) -> 0
A16: Décembre 2025 | B16: =SUMIFS(Détail!$E:$E,Détail!$D:$D,"MESSE FRANKFURT MIDDLE EAST GMBH",Détail!$A:$A,">="&DATE(2025,12,1),Détail!$A:$A,"<"&EDATE(DATE(2025,12,1),1)) -> 0
A19: Sas Somexing | C19: =SUMIF(Détail!$D:$D,"SAS SOMEXING",Détail!$E:$E) -> -3905
A20: Mois | B20: Montant
A21: Janvier 2025 | B21: =SUMIFS(Détail!$E:$E,Détail!$D:$D,"SAS SOMEXING",Détail!$A:$A,">="&DATE(2025,1,1),Détail!$A:$A,"<"&EDATE(DATE(2025,1,1),1)) -> 0
A22: Février 2025 | B22: =SUMIFS(Détail!$E:$E,Détail!$D:$D,"SAS SOMEXING",Détail!$A:$A,">="&DATE(2025,2,1),Détail!$A:$A,"<"&EDATE(DATE(2025,2,1),1)) -> 0
A23: Mars 2025 | B23: =SUMIFS(Détail!$E:$E,Détail!$D:$D,"SAS SOMEXING",Détail!$A:$A,">="&DATE(2025,3,1),Détail!$A:$A,"<"&EDATE(DATE(2025,3,1),1)) -> 0
A24: Avril 2025 | B24: =SUMIFS(Détail!$E:$E,Détail!$D:$D,"SAS SOMEXING",Détail!$A:$A,">="&DATE(2025,4,1),Détail!$A:$A,"<"&EDATE(DATE(2025,4,1),1)) -> 0
A25: Mai 2025 | B25: =SUMIFS(Détail!$E:$E,Détail!$D:$D,"SAS SOMEXING",Détail!$A:$A,">="&DATE(2025,5,1),Détail!$A:$A,"<"&EDATE(DATE(2025,5,1),1)) -> 0
A26: Juin 2025 | B26: =SUMIFS(Détail!$E:$E,Détail!$D:$D,"SAS SOMEXING",Détail!$A:$A,">="&DATE(2025,6,1),Détail!$A:$A,"<"&EDATE(DATE(2025,6,1),1)) -> -1952.5
A27: Juillet 2025 | B27: =SUMIFS(Détail!$E:$E,Détail!$D:$D,"SAS SOMEXING",Détail!$A:$A,">="&DATE(2025,7,1),Détail!$A:$A,"<"&EDATE(DATE(2025,7,1),1)) -> 0
A28: Août 2025 | B28: =SUMIFS(Détail!$E:$E,Détail!$D:$D,"SAS SOMEXING",Détail!$A:$A,">="&DATE(2025,8,1),Détail!$A:$A,"<"&EDATE(DATE(2025,8,1),1)) -> 0
A29: Septembre 2025 | B29: =SUMIFS(Détail!$E:$E,Détail!$D:$D,"SAS SOMEXING",Détail!$A:$A,">="&DATE(2025,9,1),Détail!$A:$A,"<"&EDATE(DATE(2025,9,1),1)) -> 0
A30: Octobre 2025 | B30: =SUMIFS(Détail!$E:$E,Détail!$D:$D,"SAS SOMEXING",Détail!$A:$A,">="&DATE(2025,10,1),Détail!$A:$A,"<"&EDATE(DATE(2025,10,1),1)) -> 0
A31: Novembre 2025 | B31: =SUMIFS(Détail!$E:$E,Détail!$D:$D,"SAS SOMEXING",Détail!$A:$A,">="&DATE(2025,11,1),Détail!$A:$A,"<"&EDATE(DATE(2025,11,1),1)) -> -1952.5
A32: Décembre 2025 | B32: =SUMIFS(Détail!$E:$E,Détail!$D:$D,"SAS SOMEXING",Détail!$A:$A,">="&DATE(2025,12,1),Détail!$A:$A,"<"&EDATE(DATE(2025,12,1),1)) -> 0
A35: Sa Liatech | C35: =SUMIF(Détail!$D:$D,"SA LIATECH",Détail!$E:$E) -> -2840
A36: Mois | B36: Montant
A37: Janvier 2025 | B37: =SUMIFS(Détail!$E:$E,Détail!$D:$D,"SA LIATECH",Détail!$A:$A,">="&DATE(2025,1,1),Détail!$A:$A,"<"&EDATE(DATE(2025,1,1),1)) -> 0
A38: Février 2025 | B38: =SUMIFS(Détail!$E:$E,Détail!$D:$D,"SA LIATECH",Détail!$A:$A,">="&DATE(2025,2,1),Détail!$A:$A,"<"&EDATE(DATE(2025,2,1),1)) -> 0
A39: Mars 2025 | B39: =SUMIFS(Détail!$E:$E,Détail!$D:$D,"SA LIATECH",Détail!$A:$A,">="&DATE(2025,3,1),Détail!$A:$A,"<"&EDATE(DATE(2025,3,1),1)) -> 0
A40: Avril 2025 | B40: =SUMIFS(Détail!$E:$E,Détail!$D:$D,"SA LIATECH",Détail!$A:$A,">="&DATE(2025,4,1),Détail!$A:$A,"<"&EDATE(DATE(2025,4,1),1)) -> 0
A41: Mai 2025 | B41: =SUMIFS(Détail!$E:$E,Détail!$D:$D,"SA LIATECH",Détail!$A:$A,">="&DATE(2025,5,1),Détail!$A:$A,"<"&EDATE(DATE(2025,5,1),1)) -> 0
A42: Juin 2025 | B42: =SUMIFS(Détail!$E:$E,Détail!$D:$D,"SA LIATECH",Détail!$A:$A,">="&DATE(2025,6,1),Détail!$A:$A,"<"&EDATE(DATE(2025,6,1),1)) -> 0
A43: Juillet 2025 | B43: =SUMIFS(Détail!$E:$E,Détail!$D:$D,"SA LIATECH",Détail!$A:$A,">="&DATE(2025,7,1),Détail!$A:$A,"<"&EDATE(DATE(2025,7,1),1)) -> 0
A44: Août 2025 | B44: =SUMIFS(Détail!$E:$E,Détail!$D:$D,"SA LIATECH",Détail!$A:$A,">="&DATE(2025,8,1),Détail!$A:$A,"<"&EDATE(DATE(2025,8,1),1)) -> 0
A45: Septembre 2025 | B45: =SUMIFS(Détail!$E:$E,Détail!$D:$D,"SA LIATECH",Détail!$A:$A,">="&DATE(2025,9,1),Détail!$A:$A,"<"&EDATE(DATE(2025,9,1),1)) -> -2840
...

Sheet Électricité Gaz détail
A1: Électricité / Gaz — détail mensuel (2025)
A3: Totalenergies Electricite Et Gaz France | C3: =SUMIF(Détail!$D:$D,"TOTALENERGIES ELECTRICITE ET GAZ FRANCE",Détail!$E:$E) -> -8727.96
A4: Mois | B4: Montant
A5: Janvier 2025 | B5: =SUMIFS(Détail!$E:$E,Détail!$D:$D,"TOTALENERGIES ELECTRICITE ET GAZ FRANCE",Détail!$A:$A,">="&DATE(2025,1,1),Détail!$A:$A,"<"&EDATE(DATE(2025,1,1),1)) -> -2033.74
A6: Février 2025 | B6: =SUMIFS(Détail!$E:$E,Détail!$D:$D,"TOTALENERGIES ELECTRICITE ET GAZ FRANCE",Détail!$A:$A,">="&DATE(2025,2,1),Détail!$A:$A,"<"&EDATE(DATE(2025,2,1),1)) -> -179.27
A7: Mars 2025 | B7: =SUMIFS(Détail!$E:$E,Détail!$D:$D,"TOTALENERGIES ELECTRICITE ET GAZ FRANCE",Détail!$A:$A,">="&DATE(2025,3,1),Détail!$A:$A,"<"&EDATE(DATE(2025,3,1),1)) -> -1983.15
A8: Avril 2025 | B8: =SUMIFS(Détail!$E:$E,Détail!$D:$D,"TOTALENERGIES ELECTRICITE ET GAZ FRANCE",Détail!$A:$A,">="&DATE(2025,4,1),Détail!$A:$A,"<"&EDATE(DATE(2025,4,1),1)) -> -187.16
A9: Mai 2025 | B9: =SUMIFS(Détail!$E:$E,Détail!$D:$D,"TOTALENERGIES ELECTRICITE ET GAZ FRANCE",Détail!$A:$A,">="&DATE(2025,5,1),Détail!$A:$A,"<"&EDATE(DATE(2025,5,1),1)) -> -707.99
A10: Juin 2025 | B10: =SUMIFS(Détail!$E:$E,Détail!$D:$D,"TOTALENERGIES ELECTRICITE ET GAZ FRANCE",Détail!$A:$A,">="&DATE(2025,6,1),Détail!$A:$A,"<"&EDATE(DATE(2025,6,1),1)) -> -403.51
A11: Juillet 2025 | B11: =SUMIFS(Détail!$E:$E,Détail!$D:$D,"TOTALENERGIES ELECTRICITE ET GAZ FRANCE",Détail!$A:$A,">="&DATE(2025,7,1),Détail!$A:$A,"<"&EDATE(DATE(2025,7,1),1)) -> -415.36
A12: Septembre 2025 | B12: =SUMIFS(Détail!$E:$E,Détail!$D:$D,"TOTALENERGIES ELECTRICITE ET GAZ FRANCE",Détail!$A:$A,">="&DATE(2025,9,1),Détail!$A:$A,"<"&EDATE(DATE(2025,9,1),1)) -> -213.49
A13: Octobre 2025 | B13: =SUMIFS(Détail!$E:$E,Détail!$D:$D,"TOTALENERGIES ELECTRICITE ET GAZ FRANCE",Détail!$A:$A,">="&DATE(2025,10,1),Détail!$A:$A,"<"&EDATE(DATE(2025,10,1),1)) -> -651.02
